2025-08-01 19:18:38 - demo.development - ERROR - logging_integration_demo.py:34 - demo_logging_setup - 这是错误日志
2025-08-01 19:19:07 - demo.development - ERROR - logging_integration_demo.py:34 - demo_logging_setup - 这是错误日志
2025-08-01 19:19:07 - rag_system.errors - ERROR - logging_config.py:256 - log_error_with_context - 错误记录: [DOCUMENT_NOT_FOUND] 文档未找到: doc_456
2025-08-01 19:19:08 - rag_system.monitoring - ERROR - logging_integration_demo.py:236 - demo_monitoring_integration - 服务不健康: embedding_service
2025-08-01 19:19:55 - demo.development - ERROR - logging_integration_demo.py:34 - demo_logging_setup - 这是错误日志
2025-08-01 19:19:55 - rag_system.errors - ERROR - logging_config.py:256 - log_error_with_context - 错误记录: [DOCUMENT_NOT_FOUND] 文档未找到: doc_456
2025-08-01 19:19:55 - rag_system.monitoring - ERROR - logging_integration_demo.py:236 - demo_monitoring_integration - 服务不健康: embedding_service
2025-08-01 19:19:55 - rag_system.monitoring - CRITICAL - logging_integration_demo.py:276 - demo_monitoring_integration - 严重告警: 错误率过高
2025-08-04 15:12:36 - __main__ - ERROR - test_logging_fix.py:60 - test_logging - 这是一个ERROR级别的日志
2025-08-04 15:16:47 - rag_system.document_processing.splitters - ERROR - splitters.py:181 - split - 固定大小分割失败: 1 validation error for TextChunk
document_id
  Value error, 无效的文档ID格式 [type=value_error, input_value='test_doc', input_type=str]
    For further information visit https://errors.pydantic.dev/2.11/v/value_error
2025-08-04 15:16:47 - rag_system.document_processing.splitters - ERROR - splitters.py:682 - split - 递归分割失败: [UNKNOWN_ERROR] 固定大小分割失败: 1 validation error for TextChunk
document_id
  Value error, 无效的文档ID格式 [type=value_error, input_value='test_doc', input_type=str]
    For further information visit https://errors.pydantic.dev/2.11/v/value_error
2025-08-04 15:16:47 - rag_system.services.document_processor - ERROR - document_processor.py:214 - process_document - 文档处理失败: test_document.txt, 错误: [UNKNOWN_ERROR] 递归分割失败: [UNKNOWN_ERROR] 固定大小分割失败: 1 validation error for TextChunk
document_id
  Value error, 无效的文档ID格式 [type=value_error, input_value='test_doc', input_type=str]
    For further information visit https://errors.pydantic.dev/2.11/v/value_error
2025-08-04 15:48:12 - rag_system.embeddings.siliconflow_embedding - ERROR - siliconflow_embedding.py:130 - embed_texts - 批量文本向量化失败: [siliconflow:BAAI/bge-large-zh-v1.5] API请求失败: 413 - {"code":20042,"message":"input batch size 34 \u003e maximum allowed batch size 32","data":null}
2025-08-04 15:48:12 - rag_system.services.embedding_service - ERROR - embedding_service.py:109 - vectorize_texts - 批量向量化失败: [UNKNOWN_ERROR] 批量文本向量化失败: [siliconflow:BAAI/bge-large-zh-v1.5] API请求失败: 413 - {"code":20042,"message":"input batch size 34 \u003e maximum allowed batch size 32","data":null}
2025-08-04 15:48:12 - rag_system.services.embedding_service - ERROR - embedding_service.py:171 - vectorize_chunks - 文本块向量化失败: [UNKNOWN_ERROR] 批量向量化失败: [UNKNOWN_ERROR] 批量文本向量化失败: [siliconflow:BAAI/bge-large-zh-v1.5] API请求失败: 413 - {"code":20042,"message":"input batch size 34 \u003e maximum allowed batch size 32","data":null}
2025-08-04 15:48:12 - rag_system.services.document_processor - ERROR - document_processor.py:174 - vectorize_chunks - 向量化失败: 错误: [UNKNOWN_ERROR] 文本块向量化失败: [UNKNOWN_ERROR] 批量向量化失败: [UNKNOWN_ERROR] 批量文本向量化失败: [siliconflow:BAAI/bge-large-zh-v1.5] API请求失败: 413 - {"code":20042,"message":"input batch size 34 \u003e maximum allowed batch size 32","data":null}
2025-08-04 15:48:12 - rag_system.services.document_processor - ERROR - document_processor.py:214 - process_document - 文档处理失败: documents\250ab60f-a952-4bf9-8b6a-a9b69a71e400.docx, 错误: [UNKNOWN_ERROR] 向量化失败: [UNKNOWN_ERROR] 文本块向量化失败: [UNKNOWN_ERROR] 批量向量化失败: [UNKNOWN_ERROR] 批量文本向量化失败: [siliconflow:BAAI/bge-large-zh-v1.5] API请求失败: 413 - {"code":20042,"message":"input batch size 34 \u003e maximum allowed batch size 32","data":null}
2025-08-04 15:48:12 - rag_system.services.document_service - ERROR - document_service.py:224 - _process_document_async - 文档处理失败: 2025年互联网问题.docx, 错误: [UNKNOWN_ERROR] 向量化失败: [UNKNOWN_ERROR] 文本块向量化失败: [UNKNOWN_ERROR] 批量向量化失败: [UNKNOWN_ERROR] 批量文本向量化失败: [siliconflow:BAAI/bge-large-zh-v1.5] API请求失败: 413 - {"code":20042,"message":"input batch size 34 \u003e maximum allowed batch size 32","data":null}
2025-08-04 18:17:24 - rag_system.vector_store.chroma_store - ERROR - chroma_store.py:85 - initialize - Chroma向量数据库初始化失败: Could not connect to tenant default_tenant. Are you sure it exists?
2025-08-04 18:17:24 - rag_system.services.vector_service - ERROR - vector_service.py:42 - initialize - 向量存储服务初始化失败: [VECTOR_STORE_OPERATION_ERROR] Chroma初始化失败: Could not connect to tenant default_tenant. Are you sure it exists?
2025-08-04 18:17:24 - rag_system.services.document_service - ERROR - document_service.py:88 - initialize - 文档管理服务初始化失败: [VECTOR_STORE_OPERATION_ERROR] 向量存储服务初始化失败: [VECTOR_STORE_OPERATION_ERROR] Chroma初始化失败: Could not connect to tenant default_tenant. Are you sure it exists?
2025-08-04 19:01:10 - rag_system.embeddings.siliconflow_embedding - ERROR - siliconflow_embedding.py:130 - embed_texts - 批量文本向量化失败: [siliconflow:BAAI/bge-large-zh-v1.5] API请求失败: 413 - {"code":20042,"message":"input batch size 34 \u003e maximum allowed batch size 32","data":null}
2025-08-04 19:01:10 - rag_system.services.embedding_service - ERROR - embedding_service.py:109 - vectorize_texts - 批量向量化失败: [UNKNOWN_ERROR] 批量文本向量化失败: [siliconflow:BAAI/bge-large-zh-v1.5] API请求失败: 413 - {"code":20042,"message":"input batch size 34 \u003e maximum allowed batch size 32","data":null}
2025-08-04 19:01:10 - rag_system.services.embedding_service - ERROR - embedding_service.py:171 - vectorize_chunks - 文本块向量化失败: [UNKNOWN_ERROR] 批量向量化失败: [UNKNOWN_ERROR] 批量文本向量化失败: [siliconflow:BAAI/bge-large-zh-v1.5] API请求失败: 413 - {"code":20042,"message":"input batch size 34 \u003e maximum allowed batch size 32","data":null}
2025-08-04 19:01:10 - rag_system.services.document_processor - ERROR - document_processor.py:174 - vectorize_chunks - 向量化失败: 错误: [UNKNOWN_ERROR] 文本块向量化失败: [UNKNOWN_ERROR] 批量向量化失败: [UNKNOWN_ERROR] 批量文本向量化失败: [siliconflow:BAAI/bge-large-zh-v1.5] API请求失败: 413 - {"code":20042,"message":"input batch size 34 \u003e maximum allowed batch size 32","data":null}
2025-08-04 19:01:10 - rag_system.services.document_processor - ERROR - document_processor.py:214 - process_document - 文档处理失败: documents\56b1590f-ef74-4444-b371-7b55d893e6a5.docx, 错误: [UNKNOWN_ERROR] 向量化失败: [UNKNOWN_ERROR] 文本块向量化失败: [UNKNOWN_ERROR] 批量向量化失败: [UNKNOWN_ERROR] 批量文本向量化失败: [siliconflow:BAAI/bge-large-zh-v1.5] API请求失败: 413 - {"code":20042,"message":"input batch size 34 \u003e maximum allowed batch size 32","data":null}
2025-08-04 19:01:10 - rag_system.services.document_service - ERROR - document_service.py:224 - _process_document_async - 文档处理失败: 2025年互联网问题.docx, 错误: [UNKNOWN_ERROR] 向量化失败: [UNKNOWN_ERROR] 文本块向量化失败: [UNKNOWN_ERROR] 批量向量化失败: [UNKNOWN_ERROR] 批量文本向量化失败: [siliconflow:BAAI/bge-large-zh-v1.5] API请求失败: 413 - {"code":20042,"message":"input batch size 34 \u003e maximum allowed batch size 32","data":null}
2025-08-04 19:41:06 - rag_system.embeddings.siliconflow_embedding - ERROR - siliconflow_embedding.py:130 - embed_texts - 批量文本向量化失败: [siliconflow:BAAI/bge-large-zh-v1.5] API请求失败: 413 - {"code":20042,"message":"input batch size 34 \u003e maximum allowed batch size 32","data":null}
2025-08-04 19:41:06 - rag_system.services.embedding_service - ERROR - embedding_service.py:109 - vectorize_texts - 批量向量化失败: [UNKNOWN_ERROR] 批量文本向量化失败: [siliconflow:BAAI/bge-large-zh-v1.5] API请求失败: 413 - {"code":20042,"message":"input batch size 34 \u003e maximum allowed batch size 32","data":null}
2025-08-04 19:41:06 - rag_system.services.embedding_service - ERROR - embedding_service.py:171 - vectorize_chunks - 文本块向量化失败: [UNKNOWN_ERROR] 批量向量化失败: [UNKNOWN_ERROR] 批量文本向量化失败: [siliconflow:BAAI/bge-large-zh-v1.5] API请求失败: 413 - {"code":20042,"message":"input batch size 34 \u003e maximum allowed batch size 32","data":null}
2025-08-04 19:41:06 - rag_system.services.document_processor - ERROR - document_processor.py:174 - vectorize_chunks - 向量化失败: 错误: [UNKNOWN_ERROR] 文本块向量化失败: [UNKNOWN_ERROR] 批量向量化失败: [UNKNOWN_ERROR] 批量文本向量化失败: [siliconflow:BAAI/bge-large-zh-v1.5] API请求失败: 413 - {"code":20042,"message":"input batch size 34 \u003e maximum allowed batch size 32","data":null}
2025-08-04 19:41:06 - rag_system.services.document_processor - ERROR - document_processor.py:214 - process_document - 文档处理失败: documents\6e89727c-970a-4f8f-b7df-59dcd057b704.docx, 错误: [UNKNOWN_ERROR] 向量化失败: [UNKNOWN_ERROR] 文本块向量化失败: [UNKNOWN_ERROR] 批量向量化失败: [UNKNOWN_ERROR] 批量文本向量化失败: [siliconflow:BAAI/bge-large-zh-v1.5] API请求失败: 413 - {"code":20042,"message":"input batch size 34 \u003e maximum allowed batch size 32","data":null}
2025-08-04 19:41:06 - rag_system.services.document_service - ERROR - document_service.py:224 - _process_document_async - 文档处理失败: 2025年互联网问题.docx, 错误: [UNKNOWN_ERROR] 向量化失败: [UNKNOWN_ERROR] 文本块向量化失败: [UNKNOWN_ERROR] 批量向量化失败: [UNKNOWN_ERROR] 批量文本向量化失败: [siliconflow:BAAI/bge-large-zh-v1.5] API请求失败: 413 - {"code":20042,"message":"input batch size 34 \u003e maximum allowed batch size 32","data":null}
2025-08-04 19:46:46 - rag_system.services.document_processor - ERROR - document_processor.py:214 - process_document - 文档处理失败: documents\46265e04-aa3f-43df-97af-a579e0ce2abb.txt, 错误: [UNKNOWN_ERROR] 文本分割后没有生成任何块
2025-08-04 19:46:46 - rag_system.services.document_service - ERROR - document_service.py:224 - _process_document_async - 文档处理失败: very_large_test_document.txt, 错误: [UNKNOWN_ERROR] 文本分割后没有生成任何块
2025-08-04 19:52:30 - rag_system.embeddings.siliconflow_embedding - ERROR - siliconflow_embedding.py:130 - embed_texts - 批量文本向量化失败: [siliconflow:BAAI/bge-large-zh-v1.5] API请求失败: 413 - {"code":20042,"message":"input batch size 34 \u003e maximum allowed batch size 32","data":null}
2025-08-04 19:52:30 - rag_system.services.embedding_service - ERROR - embedding_service.py:109 - vectorize_texts - 批量向量化失败: [UNKNOWN_ERROR] 批量文本向量化失败: [siliconflow:BAAI/bge-large-zh-v1.5] API请求失败: 413 - {"code":20042,"message":"input batch size 34 \u003e maximum allowed batch size 32","data":null}
2025-08-04 19:52:30 - rag_system.services.embedding_service - ERROR - embedding_service.py:171 - vectorize_chunks - 文本块向量化失败: [UNKNOWN_ERROR] 批量向量化失败: [UNKNOWN_ERROR] 批量文本向量化失败: [siliconflow:BAAI/bge-large-zh-v1.5] API请求失败: 413 - {"code":20042,"message":"input batch size 34 \u003e maximum allowed batch size 32","data":null}
2025-08-04 19:52:30 - rag_system.services.document_processor - ERROR - document_processor.py:174 - vectorize_chunks - 向量化失败: 错误: [UNKNOWN_ERROR] 文本块向量化失败: [UNKNOWN_ERROR] 批量向量化失败: [UNKNOWN_ERROR] 批量文本向量化失败: [siliconflow:BAAI/bge-large-zh-v1.5] API请求失败: 413 - {"code":20042,"message":"input batch size 34 \u003e maximum allowed batch size 32","data":null}
2025-08-04 19:52:30 - rag_system.services.document_processor - ERROR - document_processor.py:214 - process_document - 文档处理失败: documents\2d0d5cf8-1eae-4bcc-aa8e-aa57a6ccc26e.docx, 错误: [UNKNOWN_ERROR] 向量化失败: [UNKNOWN_ERROR] 文本块向量化失败: [UNKNOWN_ERROR] 批量向量化失败: [UNKNOWN_ERROR] 批量文本向量化失败: [siliconflow:BAAI/bge-large-zh-v1.5] API请求失败: 413 - {"code":20042,"message":"input batch size 34 \u003e maximum allowed batch size 32","data":null}
2025-08-04 19:52:30 - rag_system.services.document_service - ERROR - document_service.py:224 - _process_document_async - 文档处理失败: 2025年互联网问题.docx, 错误: [UNKNOWN_ERROR] 向量化失败: [UNKNOWN_ERROR] 文本块向量化失败: [UNKNOWN_ERROR] 批量向量化失败: [UNKNOWN_ERROR] 批量文本向量化失败: [siliconflow:BAAI/bge-large-zh-v1.5] API请求失败: 413 - {"code":20042,"message":"input batch size 34 \u003e maximum allowed batch size 32","data":null}
2025-08-04 19:55:03 - rag_system.services.document_processor - ERROR - document_processor.py:214 - process_document - 文档处理失败: documents\b58e9d73-485f-4568-b0d2-1a793d9951cc.txt, 错误: [UNKNOWN_ERROR] 文本分割后没有生成任何块
2025-08-04 19:55:03 - rag_system.services.document_service - ERROR - document_service.py:224 - _process_document_async - 文档处理失败: very_large_test_document.txt, 错误: [UNKNOWN_ERROR] 文本分割后没有生成任何块
2025-08-04 20:07:30 - rag_system.services.document_processor - ERROR - document_processor.py:214 - process_document - 文档处理失败: documents\9f3f0663-51e5-438b-967b-65bd6abaf21d.txt, 错误: [UNKNOWN_ERROR] 文本分割后没有生成任何块
2025-08-04 20:07:30 - rag_system.services.document_service - ERROR - document_service.py:224 - _process_document_async - 文档处理失败: very_large_test_document.txt, 错误: [UNKNOWN_ERROR] 文本分割后没有生成任何块
2025-08-04 20:08:51 - rag_system.services.document_processor - ERROR - document_processor.py:214 - process_document - 文档处理失败: documents\2d05e137-8f19-4afd-8770-028a7f037a9e.txt, 错误: [UNKNOWN_ERROR] 文本分割后没有生成任何块
2025-08-04 20:08:51 - rag_system.services.document_service - ERROR - document_service.py:224 - _process_document_async - 文档处理失败: very_large_test_document.txt, 错误: [UNKNOWN_ERROR] 文本分割后没有生成任何块
2025-08-04 20:12:00 - rag_system.services.document_processor - ERROR - document_processor.py:214 - process_document - 文档处理失败: documents\35d84d91-b08a-46c7-855b-591e3db56fe0.txt, 错误: [UNKNOWN_ERROR] 文本分割后没有生成任何块
2025-08-04 20:12:00 - rag_system.services.document_service - ERROR - document_service.py:224 - _process_document_async - 文档处理失败: very_large_test_document.txt, 错误: [UNKNOWN_ERROR] 文本分割后没有生成任何块
2025-08-04 20:13:47 - rag_system.embeddings.siliconflow_embedding - ERROR - siliconflow_embedding.py:130 - embed_texts - 批量文本向量化失败: [siliconflow:BAAI/bge-large-zh-v1.5] API请求失败: 413 - {"code":20042,"message":"input batch size 34 \u003e maximum allowed batch size 32","data":null}
2025-08-04 20:13:47 - rag_system.services.embedding_service - ERROR - embedding_service.py:109 - vectorize_texts - 批量向量化失败: [UNKNOWN_ERROR] 批量文本向量化失败: [siliconflow:BAAI/bge-large-zh-v1.5] API请求失败: 413 - {"code":20042,"message":"input batch size 34 \u003e maximum allowed batch size 32","data":null}
2025-08-04 20:13:47 - rag_system.services.embedding_service - ERROR - embedding_service.py:171 - vectorize_chunks - 文本块向量化失败: [UNKNOWN_ERROR] 批量向量化失败: [UNKNOWN_ERROR] 批量文本向量化失败: [siliconflow:BAAI/bge-large-zh-v1.5] API请求失败: 413 - {"code":20042,"message":"input batch size 34 \u003e maximum allowed batch size 32","data":null}
2025-08-04 20:13:47 - rag_system.services.document_processor - ERROR - document_processor.py:174 - vectorize_chunks - 向量化失败: 错误: [UNKNOWN_ERROR] 文本块向量化失败: [UNKNOWN_ERROR] 批量向量化失败: [UNKNOWN_ERROR] 批量文本向量化失败: [siliconflow:BAAI/bge-large-zh-v1.5] API请求失败: 413 - {"code":20042,"message":"input batch size 34 \u003e maximum allowed batch size 32","data":null}
2025-08-04 20:13:47 - rag_system.services.document_processor - ERROR - document_processor.py:214 - process_document - 文档处理失败: documents\45a38c76-9e8c-4e4a-808a-88a1f827bd4a.docx, 错误: [UNKNOWN_ERROR] 向量化失败: [UNKNOWN_ERROR] 文本块向量化失败: [UNKNOWN_ERROR] 批量向量化失败: [UNKNOWN_ERROR] 批量文本向量化失败: [siliconflow:BAAI/bge-large-zh-v1.5] API请求失败: 413 - {"code":20042,"message":"input batch size 34 \u003e maximum allowed batch size 32","data":null}
2025-08-04 20:13:47 - rag_system.services.document_service - ERROR - document_service.py:224 - _process_document_async - 文档处理失败: 2025年互联网问题.docx, 错误: [UNKNOWN_ERROR] 向量化失败: [UNKNOWN_ERROR] 文本块向量化失败: [UNKNOWN_ERROR] 批量向量化失败: [UNKNOWN_ERROR] 批量文本向量化失败: [siliconflow:BAAI/bge-large-zh-v1.5] API请求失败: 413 - {"code":20042,"message":"input batch size 34 \u003e maximum allowed batch size 32","data":null}
2025-08-04 20:17:07 - rag_system.services.document_processor - ERROR - document_processor.py:214 - process_document - 文档处理失败: documents\a54b0879-5343-4afe-b9b0-ee9802fafe92.txt, 错误: [UNKNOWN_ERROR] 文本分割后没有生成任何块
2025-08-04 20:17:07 - rag_system.services.document_service - ERROR - document_service.py:226 - _process_document_async - 文档处理失败: very_large_test_document.txt, 错误: [UNKNOWN_ERROR] 文本分割后没有生成任何块
2025-08-04 20:31:55 - rag_system.embeddings.siliconflow_embedding - ERROR - siliconflow_embedding.py:130 - embed_texts - 批量文本向量化失败: [siliconflow:BAAI/bge-large-zh-v1.5] API请求失败: 413 - {"code":20042,"message":"input batch size 100 \u003e maximum allowed batch size 32","data":null}
2025-08-04 20:31:55 - rag_system.services.embedding_service - ERROR - embedding_service.py:109 - vectorize_texts - 批量向量化失败: [UNKNOWN_ERROR] 批量文本向量化失败: [siliconflow:BAAI/bge-large-zh-v1.5] API请求失败: 413 - {"code":20042,"message":"input batch size 100 \u003e maximum allowed batch size 32","data":null}
2025-08-04 20:31:55 - rag_system.services.embedding_service - ERROR - embedding_service.py:171 - vectorize_chunks - 文本块向量化失败: [UNKNOWN_ERROR] 批量向量化失败: [UNKNOWN_ERROR] 批量文本向量化失败: [siliconflow:BAAI/bge-large-zh-v1.5] API请求失败: 413 - {"code":20042,"message":"input batch size 100 \u003e maximum allowed batch size 32","data":null}
2025-08-04 20:31:55 - rag_system.services.document_processor - ERROR - document_processor.py:176 - vectorize_chunks - 向量化失败: 错误: [UNKNOWN_ERROR] 文本块向量化失败: [UNKNOWN_ERROR] 批量向量化失败: [UNKNOWN_ERROR] 批量文本向量化失败: [siliconflow:BAAI/bge-large-zh-v1.5] API请求失败: 413 - {"code":20042,"message":"input batch size 100 \u003e maximum allowed batch size 32","data":null}
2025-08-04 20:31:55 - rag_system.services.document_processor - ERROR - document_processor.py:216 - process_document - 文档处理失败: documents\40d52f01-d0b0-42dc-811a-bea446e5ede9.txt, 错误: [UNKNOWN_ERROR] 向量化失败: [UNKNOWN_ERROR] 文本块向量化失败: [UNKNOWN_ERROR] 批量向量化失败: [UNKNOWN_ERROR] 批量文本向量化失败: [siliconflow:BAAI/bge-large-zh-v1.5] API请求失败: 413 - {"code":20042,"message":"input batch size 100 \u003e maximum allowed batch size 32","data":null}
2025-08-04 20:31:55 - rag_system.services.document_service - ERROR - document_service.py:226 - _process_document_async - 文档处理失败: very_large_test_document.txt, 错误: [UNKNOWN_ERROR] 向量化失败: [UNKNOWN_ERROR] 文本块向量化失败: [UNKNOWN_ERROR] 批量向量化失败: [UNKNOWN_ERROR] 批量文本向量化失败: [siliconflow:BAAI/bge-large-zh-v1.5] API请求失败: 413 - {"code":20042,"message":"input batch size 100 \u003e maximum allowed batch size 32","data":null}
2025-08-05 10:26:32 - rag_system.vector_store.chroma_store - ERROR - chroma_store.py:85 - initialize - Chroma向量数据库初始化失败: Could not connect to tenant default_tenant. Are you sure it exists?
2025-08-05 10:26:32 - rag_system.services.vector_service - ERROR - vector_service.py:42 - initialize - 向量存储服务初始化失败: [VECTOR_STORE_OPERATION_ERROR] Chroma初始化失败: Could not connect to tenant default_tenant. Are you sure it exists?
2025-08-05 10:26:32 - rag_system.services.document_service - ERROR - document_service.py:91 - initialize - 文档管理服务初始化失败: [VECTOR_STORE_OPERATION_ERROR] 向量存储服务初始化失败: [VECTOR_STORE_OPERATION_ERROR] Chroma初始化失败: Could not connect to tenant default_tenant. Are you sure it exists?
2025-08-05 10:37:35 - rag_system.vector_store.chroma_store - ERROR - chroma_store.py:85 - initialize - Chroma向量数据库初始化失败: Could not connect to tenant default_tenant. Are you sure it exists?
2025-08-05 10:37:35 - rag_system.services.vector_service - ERROR - vector_service.py:42 - initialize - 向量存储服务初始化失败: [VECTOR_STORE_OPERATION_ERROR] Chroma初始化失败: Could not connect to tenant default_tenant. Are you sure it exists?
2025-08-05 10:37:35 - rag_system.services.document_service - ERROR - document_service.py:91 - initialize - 文档管理服务初始化失败: [VECTOR_STORE_OPERATION_ERROR] 向量存储服务初始化失败: [VECTOR_STORE_OPERATION_ERROR] Chroma初始化失败: Could not connect to tenant default_tenant. Are you sure it exists?
2025-08-06 18:26:02 - rag_system.vector_store.chroma_store - ERROR - chroma_store.py:85 - initialize - Chroma向量数据库初始化失败: Could not connect to tenant default_tenant. Are you sure it exists?
2025-08-06 18:26:02 - rag_system.services.vector_service - ERROR - vector_service.py:42 - initialize - 向量存储服务初始化失败: [VECTOR_STORE_OPERATION_ERROR] Chroma初始化失败: Could not connect to tenant default_tenant. Are you sure it exists?
2025-08-06 18:26:02 - rag_system.services.document_service - ERROR - document_service.py:91 - initialize - 文档管理服务初始化失败: [VECTOR_STORE_OPERATION_ERROR] 向量存储服务初始化失败: [VECTOR_STORE_OPERATION_ERROR] Chroma初始化失败: Could not connect to tenant default_tenant. Are you sure it exists?
2025-08-06 18:46:12 - rag_system.vector_store.chroma_store - ERROR - chroma_store.py:85 - initialize - Chroma向量数据库初始化失败: Could not connect to tenant default_tenant. Are you sure it exists?
2025-08-06 18:46:12 - rag_system.services.vector_service - ERROR - vector_service.py:42 - initialize - 向量存储服务初始化失败: [VECTOR_STORE_OPERATION_ERROR] Chroma初始化失败: Could not connect to tenant default_tenant. Are you sure it exists?
2025-08-06 18:46:12 - rag_system.services.document_service - ERROR - document_service.py:91 - initialize - 文档管理服务初始化失败: [VECTOR_STORE_OPERATION_ERROR] 向量存储服务初始化失败: [VECTOR_STORE_OPERATION_ERROR] Chroma初始化失败: Could not connect to tenant default_tenant. Are you sure it exists?
2025-08-06 18:47:19 - rag_system.vector_store.chroma_store - ERROR - chroma_store.py:85 - initialize - Chroma向量数据库初始化失败: Could not connect to tenant default_tenant. Are you sure it exists?
2025-08-06 18:47:19 - rag_system.services.vector_service - ERROR - vector_service.py:42 - initialize - 向量存储服务初始化失败: [VECTOR_STORE_OPERATION_ERROR] Chroma初始化失败: Could not connect to tenant default_tenant. Are you sure it exists?
2025-08-06 18:47:19 - rag_system.services.document_service - ERROR - document_service.py:91 - initialize - 文档管理服务初始化失败: [VECTOR_STORE_OPERATION_ERROR] 向量存储服务初始化失败: [VECTOR_STORE_OPERATION_ERROR] Chroma初始化失败: Could not connect to tenant default_tenant. Are you sure it exists?
2025-08-06 20:26:09 - rag_system.vector_store.chroma_store - ERROR - chroma_store.py:85 - initialize - Chroma向量数据库初始化失败: Could not connect to tenant default_tenant. Are you sure it exists?
2025-08-06 20:26:09 - rag_system.services.vector_service - ERROR - vector_service.py:42 - initialize - 向量存储服务初始化失败: [VECTOR_STORE_OPERATION_ERROR] Chroma初始化失败: Could not connect to tenant default_tenant. Are you sure it exists?
2025-08-06 20:26:09 - rag_system.services.document_service - ERROR - document_service.py:91 - initialize - 文档管理服务初始化失败: [VECTOR_STORE_OPERATION_ERROR] 向量存储服务初始化失败: [VECTOR_STORE_OPERATION_ERROR] Chroma初始化失败: Could not connect to tenant default_tenant. Are you sure it exists?
2025-08-06 20:44:04 - rag_system.vector_store.chroma_store - ERROR - chroma_store.py:85 - initialize - Chroma向量数据库初始化失败: Could not connect to tenant default_tenant. Are you sure it exists?
2025-08-06 20:44:04 - rag_system.services.vector_service - ERROR - vector_service.py:42 - initialize - 向量存储服务初始化失败: [VECTOR_STORE_OPERATION_ERROR] Chroma初始化失败: Could not connect to tenant default_tenant. Are you sure it exists?
2025-08-06 20:44:04 - rag_system.services.document_service - ERROR - document_service.py:91 - initialize - 文档管理服务初始化失败: [VECTOR_STORE_OPERATION_ERROR] 向量存储服务初始化失败: [VECTOR_STORE_OPERATION_ERROR] Chroma初始化失败: Could not connect to tenant default_tenant. Are you sure it exists?
2025-08-07 14:56:02 - rag_system.vector_store.chroma_store - ERROR - chroma_store.py:85 - initialize - Chroma向量数据库初始化失败: Could not connect to tenant default_tenant. Are you sure it exists?
2025-08-07 14:56:02 - rag_system.services.vector_service - ERROR - vector_service.py:42 - initialize - 向量存储服务初始化失败: [VECTOR_STORE_OPERATION_ERROR] Chroma初始化失败: Could not connect to tenant default_tenant. Are you sure it exists?
2025-08-07 14:56:02 - rag_system.services.document_service - ERROR - document_service.py:91 - initialize - 文档管理服务初始化失败: [VECTOR_STORE_OPERATION_ERROR] 向量存储服务初始化失败: [VECTOR_STORE_OPERATION_ERROR] Chroma初始化失败: Could not connect to tenant default_tenant. Are you sure it exists?
2025-08-07 15:31:42 - rag_system.vector_store.chroma_store - ERROR - chroma_store.py:85 - initialize - Chroma向量数据库初始化失败: Could not connect to tenant default_tenant. Are you sure it exists?
2025-08-07 15:31:42 - rag_system.services.vector_service - ERROR - vector_service.py:42 - initialize - 向量存储服务初始化失败: [VECTOR_STORE_OPERATION_ERROR] Chroma初始化失败: Could not connect to tenant default_tenant. Are you sure it exists?
2025-08-07 15:31:42 - rag_system.services.document_service - ERROR - document_service.py:91 - initialize - 文档管理服务初始化失败: [VECTOR_STORE_OPERATION_ERROR] 向量存储服务初始化失败: [VECTOR_STORE_OPERATION_ERROR] Chroma初始化失败: Could not connect to tenant default_tenant. Are you sure it exists?
2025-08-07 15:32:22 - rag_system.services.reranking_service - ERROR - reranking_service.py:128 - _load_model - 模型加载失败: We couldn't connect to 'https://huggingface.co' to load this file, couldn't find it in the cached files and it looks like cross-encoder/ms-marco-MiniLM-L-6-v2 is not the path to a directory containing a file named config.json.
Checkout your internet connection or see how to run the library in offline mode at 'https://huggingface.co/docs/transformers/installation#offline-mode'.
2025-08-07 15:32:22 - rag_system.services.reranking_service - ERROR - reranking_service.py:109 - initialize - 重排序模型加载失败: We couldn't connect to 'https://huggingface.co' to load this file, couldn't find it in the cached files and it looks like cross-encoder/ms-marco-MiniLM-L-6-v2 is not the path to a directory containing a file named config.json.
Checkout your internet connection or see how to run the library in offline mode at 'https://huggingface.co/docs/transformers/installation#offline-mode'.
2025-08-07 17:11:58 - rag_system.vector_store.chroma_store - ERROR - chroma_store.py:85 - initialize - Chroma向量数据库初始化失败: Could not connect to tenant default_tenant. Are you sure it exists?
2025-08-07 17:11:58 - rag_system.services.vector_service - ERROR - vector_service.py:42 - initialize - 向量存储服务初始化失败: [VECTOR_STORE_OPERATION_ERROR] Chroma初始化失败: Could not connect to tenant default_tenant. Are you sure it exists?
2025-08-07 17:11:58 - rag_system.services.document_service - ERROR - document_service.py:91 - initialize - 文档管理服务初始化失败: [VECTOR_STORE_OPERATION_ERROR] 向量存储服务初始化失败: [VECTOR_STORE_OPERATION_ERROR] Chroma初始化失败: Could not connect to tenant default_tenant. Are you sure it exists?
2025-08-07 21:16:19 - rag_system.embeddings.siliconflow_embedding - ERROR - siliconflow_embedding.py:72 - initialize - SiliconFlow嵌入模型初始化失败: [siliconflow:siliconflow_BAAI/bge-large-zh-v1.5] SiliconFlow嵌入API连接测试失败: [siliconflow:siliconflow_BAAI/bge-large-zh-v1.5] API请求失败: 400 - {"code":20012,"message":"Model does not exist. Please check it carefully.","data":null} (错误码: 6000) (错误码: 3000)
2025-08-07 21:16:19 - rag_system.services.embedding_service - ERROR - embedding_service.py:72 - _create_embedding_instance - 嵌入模型实例创建失败: siliconflow - [UNKNOWN_ERROR] SiliconFlow嵌入模型初始化失败: [siliconflow:siliconflow_BAAI/bge-large-zh-v1.5] SiliconFlow嵌入API连接测试失败: [siliconflow:siliconflow_BAAI/bge-large-zh-v1.5] API请求失败: 400 - {"code":20012,"message":"Model does not exist. Please check it carefully.","data":null} (错误码: 6000) (错误码: 3000)
2025-08-07 21:16:19 - rag_system.services.embedding_service - ERROR - embedding_service.py:242 - initialize - 嵌入服务初始化失败: [CONFIG_VALIDATION_ERROR] 无法创建主要嵌入模型实例: siliconflow
2025-08-07 21:16:19 - rag_system.services.document_service - ERROR - document_service.py:91 - initialize - 文档管理服务初始化失败: [CONFIG_VALIDATION_ERROR] 嵌入服务初始化失败: [CONFIG_VALIDATION_ERROR] 无法创建主要嵌入模型实例: siliconflow
2025-08-07 21:16:19 - rag_system.embeddings.siliconflow_embedding - ERROR - siliconflow_embedding.py:72 - initialize - SiliconFlow嵌入模型初始化失败: [siliconflow:siliconflow_BAAI/bge-large-zh-v1.5] SiliconFlow嵌入API连接测试失败: [siliconflow:siliconflow_BAAI/bge-large-zh-v1.5] API请求失败: 400 - {"code":20012,"message":"Model does not exist. Please check it carefully.","data":null} (错误码: 6000) (错误码: 3000)
2025-08-07 21:16:19 - rag_system.services.embedding_service - ERROR - embedding_service.py:72 - _create_embedding_instance - 嵌入模型实例创建失败: siliconflow - [UNKNOWN_ERROR] SiliconFlow嵌入模型初始化失败: [siliconflow:siliconflow_BAAI/bge-large-zh-v1.5] SiliconFlow嵌入API连接测试失败: [siliconflow:siliconflow_BAAI/bge-large-zh-v1.5] API请求失败: 400 - {"code":20012,"message":"Model does not exist. Please check it carefully.","data":null} (错误码: 6000) (错误码: 3000)
2025-08-07 21:16:19 - rag_system.services.embedding_service - ERROR - embedding_service.py:242 - initialize - 嵌入服务初始化失败: [CONFIG_VALIDATION_ERROR] 无法创建主要嵌入模型实例: siliconflow
2025-08-07 21:16:19 - rag_system.services.document_service - ERROR - document_service.py:91 - initialize - 文档管理服务初始化失败: [CONFIG_VALIDATION_ERROR] 嵌入服务初始化失败: [CONFIG_VALIDATION_ERROR] 无法创建主要嵌入模型实例: siliconflow
2025-08-07 21:16:37 - rag_system.embeddings.siliconflow_embedding - ERROR - siliconflow_embedding.py:72 - initialize - SiliconFlow嵌入模型初始化失败: [siliconflow:siliconflow_BAAI/bge-large-zh-v1.5] SiliconFlow嵌入API连接测试失败: [siliconflow:siliconflow_BAAI/bge-large-zh-v1.5] API请求失败: 400 - {"code":20012,"message":"Model does not exist. Please check it carefully.","data":null} (错误码: 6000) (错误码: 3000)
2025-08-07 21:16:37 - rag_system.services.embedding_service - ERROR - embedding_service.py:72 - _create_embedding_instance - 嵌入模型实例创建失败: siliconflow - [UNKNOWN_ERROR] SiliconFlow嵌入模型初始化失败: [siliconflow:siliconflow_BAAI/bge-large-zh-v1.5] SiliconFlow嵌入API连接测试失败: [siliconflow:siliconflow_BAAI/bge-large-zh-v1.5] API请求失败: 400 - {"code":20012,"message":"Model does not exist. Please check it carefully.","data":null} (错误码: 6000) (错误码: 3000)
2025-08-07 21:16:37 - rag_system.services.embedding_service - ERROR - embedding_service.py:242 - initialize - 嵌入服务初始化失败: [CONFIG_VALIDATION_ERROR] 无法创建主要嵌入模型实例: siliconflow
2025-08-07 21:16:37 - rag_system.services.document_service - ERROR - document_service.py:91 - initialize - 文档管理服务初始化失败: [CONFIG_VALIDATION_ERROR] 嵌入服务初始化失败: [CONFIG_VALIDATION_ERROR] 无法创建主要嵌入模型实例: siliconflow
2025-08-07 21:16:37 - rag_system.embeddings.siliconflow_embedding - ERROR - siliconflow_embedding.py:72 - initialize - SiliconFlow嵌入模型初始化失败: [siliconflow:siliconflow_BAAI/bge-large-zh-v1.5] SiliconFlow嵌入API连接测试失败: [siliconflow:siliconflow_BAAI/bge-large-zh-v1.5] API请求失败: 400 - {"code":20012,"message":"Model does not exist. Please check it carefully.","data":null} (错误码: 6000) (错误码: 3000)
2025-08-07 21:16:37 - rag_system.services.embedding_service - ERROR - embedding_service.py:72 - _create_embedding_instance - 嵌入模型实例创建失败: siliconflow - [UNKNOWN_ERROR] SiliconFlow嵌入模型初始化失败: [siliconflow:siliconflow_BAAI/bge-large-zh-v1.5] SiliconFlow嵌入API连接测试失败: [siliconflow:siliconflow_BAAI/bge-large-zh-v1.5] API请求失败: 400 - {"code":20012,"message":"Model does not exist. Please check it carefully.","data":null} (错误码: 6000) (错误码: 3000)
2025-08-07 21:16:37 - rag_system.services.embedding_service - ERROR - embedding_service.py:242 - initialize - 嵌入服务初始化失败: [CONFIG_VALIDATION_ERROR] 无法创建主要嵌入模型实例: siliconflow
2025-08-07 21:16:37 - rag_system.services.document_service - ERROR - document_service.py:91 - initialize - 文档管理服务初始化失败: [CONFIG_VALIDATION_ERROR] 嵌入服务初始化失败: [CONFIG_VALIDATION_ERROR] 无法创建主要嵌入模型实例: siliconflow
2025-08-07 21:17:34 - rag_system.embeddings.siliconflow_embedding - ERROR - siliconflow_embedding.py:72 - initialize - SiliconFlow嵌入模型初始化失败: [siliconflow:siliconflow_BAAI/bge-large-zh-v1.5] SiliconFlow嵌入API连接测试失败: [siliconflow:siliconflow_BAAI/bge-large-zh-v1.5] API请求失败: 400 - {"code":20012,"message":"Model does not exist. Please check it carefully.","data":null} (错误码: 6000) (错误码: 3000)
2025-08-07 21:17:34 - rag_system.services.embedding_service - ERROR - embedding_service.py:72 - _create_embedding_instance - 嵌入模型实例创建失败: siliconflow - [UNKNOWN_ERROR] SiliconFlow嵌入模型初始化失败: [siliconflow:siliconflow_BAAI/bge-large-zh-v1.5] SiliconFlow嵌入API连接测试失败: [siliconflow:siliconflow_BAAI/bge-large-zh-v1.5] API请求失败: 400 - {"code":20012,"message":"Model does not exist. Please check it carefully.","data":null} (错误码: 6000) (错误码: 3000)
2025-08-07 21:17:34 - rag_system.services.embedding_service - ERROR - embedding_service.py:242 - initialize - 嵌入服务初始化失败: [CONFIG_VALIDATION_ERROR] 无法创建主要嵌入模型实例: siliconflow
2025-08-07 21:17:34 - rag_system.services.document_service - ERROR - document_service.py:91 - initialize - 文档管理服务初始化失败: [CONFIG_VALIDATION_ERROR] 嵌入服务初始化失败: [CONFIG_VALIDATION_ERROR] 无法创建主要嵌入模型实例: siliconflow
2025-08-07 21:17:34 - rag_system.embeddings.siliconflow_embedding - ERROR - siliconflow_embedding.py:72 - initialize - SiliconFlow嵌入模型初始化失败: [siliconflow:siliconflow_BAAI/bge-large-zh-v1.5] SiliconFlow嵌入API连接测试失败: [siliconflow:siliconflow_BAAI/bge-large-zh-v1.5] API请求失败: 400 - {"code":20012,"message":"Model does not exist. Please check it carefully.","data":null} (错误码: 6000) (错误码: 3000)
2025-08-07 21:17:34 - rag_system.services.embedding_service - ERROR - embedding_service.py:72 - _create_embedding_instance - 嵌入模型实例创建失败: siliconflow - [UNKNOWN_ERROR] SiliconFlow嵌入模型初始化失败: [siliconflow:siliconflow_BAAI/bge-large-zh-v1.5] SiliconFlow嵌入API连接测试失败: [siliconflow:siliconflow_BAAI/bge-large-zh-v1.5] API请求失败: 400 - {"code":20012,"message":"Model does not exist. Please check it carefully.","data":null} (错误码: 6000) (错误码: 3000)
2025-08-07 21:17:34 - rag_system.services.embedding_service - ERROR - embedding_service.py:242 - initialize - 嵌入服务初始化失败: [CONFIG_VALIDATION_ERROR] 无法创建主要嵌入模型实例: siliconflow
2025-08-07 21:17:34 - rag_system.services.document_service - ERROR - document_service.py:91 - initialize - 文档管理服务初始化失败: [CONFIG_VALIDATION_ERROR] 嵌入服务初始化失败: [CONFIG_VALIDATION_ERROR] 无法创建主要嵌入模型实例: siliconflow
2025-08-07 21:25:56 - rag_system.embeddings.siliconflow_embedding - ERROR - siliconflow_embedding.py:72 - initialize - SiliconFlow嵌入模型初始化失败: [siliconflow:siliconflow_BAAI/bge-large-zh-v1.5] SiliconFlow嵌入API连接测试失败: [siliconflow:siliconflow_BAAI/bge-large-zh-v1.5] API请求失败: 400 - {"code":20012,"message":"Model does not exist. Please check it carefully.","data":null} (错误码: 6000) (错误码: 3000)
2025-08-07 21:25:56 - rag_system.services.embedding_service - ERROR - embedding_service.py:72 - _create_embedding_instance - 嵌入模型实例创建失败: siliconflow - [UNKNOWN_ERROR] SiliconFlow嵌入模型初始化失败: [siliconflow:siliconflow_BAAI/bge-large-zh-v1.5] SiliconFlow嵌入API连接测试失败: [siliconflow:siliconflow_BAAI/bge-large-zh-v1.5] API请求失败: 400 - {"code":20012,"message":"Model does not exist. Please check it carefully.","data":null} (错误码: 6000) (错误码: 3000)
2025-08-07 21:25:56 - rag_system.services.embedding_service - ERROR - embedding_service.py:242 - initialize - 嵌入服务初始化失败: [CONFIG_VALIDATION_ERROR] 无法创建主要嵌入模型实例: siliconflow
2025-08-07 21:25:56 - rag_system.services.document_service - ERROR - document_service.py:91 - initialize - 文档管理服务初始化失败: [CONFIG_VALIDATION_ERROR] 嵌入服务初始化失败: [CONFIG_VALIDATION_ERROR] 无法创建主要嵌入模型实例: siliconflow
2025-08-07 21:25:56 - rag_system.embeddings.siliconflow_embedding - ERROR - siliconflow_embedding.py:72 - initialize - SiliconFlow嵌入模型初始化失败: [siliconflow:siliconflow_BAAI/bge-large-zh-v1.5] SiliconFlow嵌入API连接测试失败: [siliconflow:siliconflow_BAAI/bge-large-zh-v1.5] API请求失败: 400 - {"code":20012,"message":"Model does not exist. Please check it carefully.","data":null} (错误码: 6000) (错误码: 3000)
2025-08-07 21:25:56 - rag_system.services.embedding_service - ERROR - embedding_service.py:72 - _create_embedding_instance - 嵌入模型实例创建失败: siliconflow - [UNKNOWN_ERROR] SiliconFlow嵌入模型初始化失败: [siliconflow:siliconflow_BAAI/bge-large-zh-v1.5] SiliconFlow嵌入API连接测试失败: [siliconflow:siliconflow_BAAI/bge-large-zh-v1.5] API请求失败: 400 - {"code":20012,"message":"Model does not exist. Please check it carefully.","data":null} (错误码: 6000) (错误码: 3000)
2025-08-07 21:25:56 - rag_system.services.embedding_service - ERROR - embedding_service.py:242 - initialize - 嵌入服务初始化失败: [CONFIG_VALIDATION_ERROR] 无法创建主要嵌入模型实例: siliconflow
2025-08-07 21:25:56 - rag_system.services.document_service - ERROR - document_service.py:91 - initialize - 文档管理服务初始化失败: [CONFIG_VALIDATION_ERROR] 嵌入服务初始化失败: [CONFIG_VALIDATION_ERROR] 无法创建主要嵌入模型实例: siliconflow
2025-08-07 21:27:23 - rag_system.embeddings.siliconflow_embedding - ERROR - siliconflow_embedding.py:72 - initialize - SiliconFlow嵌入模型初始化失败: [siliconflow:siliconflow_BAAI/bge-large-zh-v1.5] SiliconFlow嵌入API连接测试失败: [siliconflow:siliconflow_BAAI/bge-large-zh-v1.5] API请求失败: 400 - {"code":20012,"message":"Model does not exist. Please check it carefully.","data":null} (错误码: 6000) (错误码: 3000)
2025-08-07 21:27:23 - rag_system.services.embedding_service - ERROR - embedding_service.py:72 - _create_embedding_instance - 嵌入模型实例创建失败: siliconflow - [UNKNOWN_ERROR] SiliconFlow嵌入模型初始化失败: [siliconflow:siliconflow_BAAI/bge-large-zh-v1.5] SiliconFlow嵌入API连接测试失败: [siliconflow:siliconflow_BAAI/bge-large-zh-v1.5] API请求失败: 400 - {"code":20012,"message":"Model does not exist. Please check it carefully.","data":null} (错误码: 6000) (错误码: 3000)
2025-08-07 21:27:23 - rag_system.services.embedding_service - ERROR - embedding_service.py:242 - initialize - 嵌入服务初始化失败: [CONFIG_VALIDATION_ERROR] 无法创建主要嵌入模型实例: siliconflow
2025-08-07 21:27:23 - rag_system.services.document_service - ERROR - document_service.py:91 - initialize - 文档管理服务初始化失败: [CONFIG_VALIDATION_ERROR] 嵌入服务初始化失败: [CONFIG_VALIDATION_ERROR] 无法创建主要嵌入模型实例: siliconflow
2025-08-07 21:27:23 - rag_system.embeddings.siliconflow_embedding - ERROR - siliconflow_embedding.py:72 - initialize - SiliconFlow嵌入模型初始化失败: [siliconflow:siliconflow_BAAI/bge-large-zh-v1.5] SiliconFlow嵌入API连接测试失败: [siliconflow:siliconflow_BAAI/bge-large-zh-v1.5] API请求失败: 400 - {"code":20012,"message":"Model does not exist. Please check it carefully.","data":null} (错误码: 6000) (错误码: 3000)
2025-08-07 21:27:23 - rag_system.services.embedding_service - ERROR - embedding_service.py:72 - _create_embedding_instance - 嵌入模型实例创建失败: siliconflow - [UNKNOWN_ERROR] SiliconFlow嵌入模型初始化失败: [siliconflow:siliconflow_BAAI/bge-large-zh-v1.5] SiliconFlow嵌入API连接测试失败: [siliconflow:siliconflow_BAAI/bge-large-zh-v1.5] API请求失败: 400 - {"code":20012,"message":"Model does not exist. Please check it carefully.","data":null} (错误码: 6000) (错误码: 3000)
2025-08-07 21:27:23 - rag_system.services.embedding_service - ERROR - embedding_service.py:242 - initialize - 嵌入服务初始化失败: [CONFIG_VALIDATION_ERROR] 无法创建主要嵌入模型实例: siliconflow
2025-08-07 21:27:23 - rag_system.services.document_service - ERROR - document_service.py:91 - initialize - 文档管理服务初始化失败: [CONFIG_VALIDATION_ERROR] 嵌入服务初始化失败: [CONFIG_VALIDATION_ERROR] 无法创建主要嵌入模型实例: siliconflow
2025-08-07 21:28:30 - rag_system.embeddings.siliconflow_embedding - ERROR - siliconflow_embedding.py:72 - initialize - SiliconFlow嵌入模型初始化失败: [siliconflow:siliconflow_BAAI/bge-large-zh-v1.5] SiliconFlow嵌入API连接测试失败: [siliconflow:siliconflow_BAAI/bge-large-zh-v1.5] API请求失败: 400 - {"code":20012,"message":"Model does not exist. Please check it carefully.","data":null} (错误码: 6000) (错误码: 3000)
2025-08-07 21:28:30 - rag_system.services.embedding_service - ERROR - embedding_service.py:72 - _create_embedding_instance - 嵌入模型实例创建失败: siliconflow - [UNKNOWN_ERROR] SiliconFlow嵌入模型初始化失败: [siliconflow:siliconflow_BAAI/bge-large-zh-v1.5] SiliconFlow嵌入API连接测试失败: [siliconflow:siliconflow_BAAI/bge-large-zh-v1.5] API请求失败: 400 - {"code":20012,"message":"Model does not exist. Please check it carefully.","data":null} (错误码: 6000) (错误码: 3000)
2025-08-07 21:28:30 - rag_system.services.embedding_service - ERROR - embedding_service.py:242 - initialize - 嵌入服务初始化失败: [CONFIG_VALIDATION_ERROR] 无法创建主要嵌入模型实例: siliconflow
2025-08-07 21:28:30 - rag_system.services.document_service - ERROR - document_service.py:91 - initialize - 文档管理服务初始化失败: [CONFIG_VALIDATION_ERROR] 嵌入服务初始化失败: [CONFIG_VALIDATION_ERROR] 无法创建主要嵌入模型实例: siliconflow
2025-08-07 21:28:30 - rag_system.embeddings.siliconflow_embedding - ERROR - siliconflow_embedding.py:72 - initialize - SiliconFlow嵌入模型初始化失败: [siliconflow:siliconflow_BAAI/bge-large-zh-v1.5] SiliconFlow嵌入API连接测试失败: [siliconflow:siliconflow_BAAI/bge-large-zh-v1.5] API请求失败: 400 - {"code":20012,"message":"Model does not exist. Please check it carefully.","data":null} (错误码: 6000) (错误码: 3000)
2025-08-07 21:28:30 - rag_system.services.embedding_service - ERROR - embedding_service.py:72 - _create_embedding_instance - 嵌入模型实例创建失败: siliconflow - [UNKNOWN_ERROR] SiliconFlow嵌入模型初始化失败: [siliconflow:siliconflow_BAAI/bge-large-zh-v1.5] SiliconFlow嵌入API连接测试失败: [siliconflow:siliconflow_BAAI/bge-large-zh-v1.5] API请求失败: 400 - {"code":20012,"message":"Model does not exist. Please check it carefully.","data":null} (错误码: 6000) (错误码: 3000)
2025-08-07 21:28:30 - rag_system.services.embedding_service - ERROR - embedding_service.py:242 - initialize - 嵌入服务初始化失败: [CONFIG_VALIDATION_ERROR] 无法创建主要嵌入模型实例: siliconflow
2025-08-07 21:28:30 - rag_system.services.document_service - ERROR - document_service.py:91 - initialize - 文档管理服务初始化失败: [CONFIG_VALIDATION_ERROR] 嵌入服务初始化失败: [CONFIG_VALIDATION_ERROR] 无法创建主要嵌入模型实例: siliconflow
2025-08-07 21:31:08 - rag_system.embeddings.siliconflow_embedding - ERROR - siliconflow_embedding.py:72 - initialize - SiliconFlow嵌入模型初始化失败: [siliconflow:siliconflow_BAAI/bge-large-zh-v1.5] SiliconFlow嵌入API连接测试失败: [siliconflow:siliconflow_BAAI/bge-large-zh-v1.5] API请求失败: 400 - {"code":20012,"message":"Model does not exist. Please check it carefully.","data":null} (错误码: 6000) (错误码: 3000)
2025-08-07 21:31:08 - rag_system.services.embedding_service - ERROR - embedding_service.py:72 - _create_embedding_instance - 嵌入模型实例创建失败: siliconflow - [UNKNOWN_ERROR] SiliconFlow嵌入模型初始化失败: [siliconflow:siliconflow_BAAI/bge-large-zh-v1.5] SiliconFlow嵌入API连接测试失败: [siliconflow:siliconflow_BAAI/bge-large-zh-v1.5] API请求失败: 400 - {"code":20012,"message":"Model does not exist. Please check it carefully.","data":null} (错误码: 6000) (错误码: 3000)
2025-08-07 21:31:08 - rag_system.services.embedding_service - ERROR - embedding_service.py:242 - initialize - 嵌入服务初始化失败: [CONFIG_VALIDATION_ERROR] 无法创建主要嵌入模型实例: siliconflow
2025-08-07 21:31:08 - rag_system.services.document_service - ERROR - document_service.py:91 - initialize - 文档管理服务初始化失败: [CONFIG_VALIDATION_ERROR] 嵌入服务初始化失败: [CONFIG_VALIDATION_ERROR] 无法创建主要嵌入模型实例: siliconflow
2025-08-07 21:31:09 - rag_system.embeddings.siliconflow_embedding - ERROR - siliconflow_embedding.py:72 - initialize - SiliconFlow嵌入模型初始化失败: [siliconflow:siliconflow_BAAI/bge-large-zh-v1.5] SiliconFlow嵌入API连接测试失败: [siliconflow:siliconflow_BAAI/bge-large-zh-v1.5] API请求失败: 400 - {"code":20012,"message":"Model does not exist. Please check it carefully.","data":null} (错误码: 6000) (错误码: 3000)
2025-08-07 21:31:09 - rag_system.services.embedding_service - ERROR - embedding_service.py:72 - _create_embedding_instance - 嵌入模型实例创建失败: siliconflow - [UNKNOWN_ERROR] SiliconFlow嵌入模型初始化失败: [siliconflow:siliconflow_BAAI/bge-large-zh-v1.5] SiliconFlow嵌入API连接测试失败: [siliconflow:siliconflow_BAAI/bge-large-zh-v1.5] API请求失败: 400 - {"code":20012,"message":"Model does not exist. Please check it carefully.","data":null} (错误码: 6000) (错误码: 3000)
2025-08-07 21:31:09 - rag_system.services.embedding_service - ERROR - embedding_service.py:242 - initialize - 嵌入服务初始化失败: [CONFIG_VALIDATION_ERROR] 无法创建主要嵌入模型实例: siliconflow
2025-08-07 21:31:09 - rag_system.services.document_service - ERROR - document_service.py:91 - initialize - 文档管理服务初始化失败: [CONFIG_VALIDATION_ERROR] 嵌入服务初始化失败: [CONFIG_VALIDATION_ERROR] 无法创建主要嵌入模型实例: siliconflow
2025-08-07 21:32:52 - rag_system.embeddings.siliconflow_embedding - ERROR - siliconflow_embedding.py:72 - initialize - SiliconFlow嵌入模型初始化失败: [siliconflow:siliconflow_BAAI/bge-large-zh-v1.5] SiliconFlow嵌入API连接测试失败: [siliconflow:siliconflow_BAAI/bge-large-zh-v1.5] API请求失败: 400 - {"code":20012,"message":"Model does not exist. Please check it carefully.","data":null} (错误码: 6000) (错误码: 3000)
2025-08-07 21:32:52 - rag_system.services.embedding_service - ERROR - embedding_service.py:72 - _create_embedding_instance - 嵌入模型实例创建失败: siliconflow - [UNKNOWN_ERROR] SiliconFlow嵌入模型初始化失败: [siliconflow:siliconflow_BAAI/bge-large-zh-v1.5] SiliconFlow嵌入API连接测试失败: [siliconflow:siliconflow_BAAI/bge-large-zh-v1.5] API请求失败: 400 - {"code":20012,"message":"Model does not exist. Please check it carefully.","data":null} (错误码: 6000) (错误码: 3000)
2025-08-07 21:32:52 - rag_system.services.embedding_service - ERROR - embedding_service.py:242 - initialize - 嵌入服务初始化失败: [CONFIG_VALIDATION_ERROR] 无法创建主要嵌入模型实例: siliconflow
2025-08-07 21:32:52 - rag_system.services.document_service - ERROR - document_service.py:91 - initialize - 文档管理服务初始化失败: [CONFIG_VALIDATION_ERROR] 嵌入服务初始化失败: [CONFIG_VALIDATION_ERROR] 无法创建主要嵌入模型实例: siliconflow
2025-08-07 21:32:52 - rag_system.embeddings.siliconflow_embedding - ERROR - siliconflow_embedding.py:72 - initialize - SiliconFlow嵌入模型初始化失败: [siliconflow:siliconflow_BAAI/bge-large-zh-v1.5] SiliconFlow嵌入API连接测试失败: [siliconflow:siliconflow_BAAI/bge-large-zh-v1.5] API请求失败: 400 - {"code":20012,"message":"Model does not exist. Please check it carefully.","data":null} (错误码: 6000) (错误码: 3000)
2025-08-07 21:32:52 - rag_system.services.embedding_service - ERROR - embedding_service.py:72 - _create_embedding_instance - 嵌入模型实例创建失败: siliconflow - [UNKNOWN_ERROR] SiliconFlow嵌入模型初始化失败: [siliconflow:siliconflow_BAAI/bge-large-zh-v1.5] SiliconFlow嵌入API连接测试失败: [siliconflow:siliconflow_BAAI/bge-large-zh-v1.5] API请求失败: 400 - {"code":20012,"message":"Model does not exist. Please check it carefully.","data":null} (错误码: 6000) (错误码: 3000)
2025-08-07 21:32:52 - rag_system.services.embedding_service - ERROR - embedding_service.py:242 - initialize - 嵌入服务初始化失败: [CONFIG_VALIDATION_ERROR] 无法创建主要嵌入模型实例: siliconflow
2025-08-07 21:32:52 - rag_system.services.document_service - ERROR - document_service.py:91 - initialize - 文档管理服务初始化失败: [CONFIG_VALIDATION_ERROR] 嵌入服务初始化失败: [CONFIG_VALIDATION_ERROR] 无法创建主要嵌入模型实例: siliconflow
2025-08-07 21:34:20 - rag_system.embeddings.siliconflow_embedding - ERROR - siliconflow_embedding.py:72 - initialize - SiliconFlow嵌入模型初始化失败: [siliconflow:siliconflow_BAAI/bge-large-zh-v1.5] SiliconFlow嵌入API连接测试失败: [siliconflow:siliconflow_BAAI/bge-large-zh-v1.5] API请求失败: 400 - {"code":20012,"message":"Model does not exist. Please check it carefully.","data":null} (错误码: 6000) (错误码: 3000)
2025-08-07 21:34:20 - rag_system.services.embedding_service - ERROR - embedding_service.py:72 - _create_embedding_instance - 嵌入模型实例创建失败: siliconflow - [UNKNOWN_ERROR] SiliconFlow嵌入模型初始化失败: [siliconflow:siliconflow_BAAI/bge-large-zh-v1.5] SiliconFlow嵌入API连接测试失败: [siliconflow:siliconflow_BAAI/bge-large-zh-v1.5] API请求失败: 400 - {"code":20012,"message":"Model does not exist. Please check it carefully.","data":null} (错误码: 6000) (错误码: 3000)
2025-08-07 21:34:20 - rag_system.services.embedding_service - ERROR - embedding_service.py:242 - initialize - 嵌入服务初始化失败: [CONFIG_VALIDATION_ERROR] 无法创建主要嵌入模型实例: siliconflow
2025-08-07 21:34:20 - rag_system.services.document_service - ERROR - document_service.py:91 - initialize - 文档管理服务初始化失败: [CONFIG_VALIDATION_ERROR] 嵌入服务初始化失败: [CONFIG_VALIDATION_ERROR] 无法创建主要嵌入模型实例: siliconflow
2025-08-07 21:34:20 - rag_system.embeddings.siliconflow_embedding - ERROR - siliconflow_embedding.py:72 - initialize - SiliconFlow嵌入模型初始化失败: [siliconflow:siliconflow_BAAI/bge-large-zh-v1.5] SiliconFlow嵌入API连接测试失败: [siliconflow:siliconflow_BAAI/bge-large-zh-v1.5] API请求失败: 400 - {"code":20012,"message":"Model does not exist. Please check it carefully.","data":null} (错误码: 6000) (错误码: 3000)
2025-08-07 21:34:20 - rag_system.services.embedding_service - ERROR - embedding_service.py:72 - _create_embedding_instance - 嵌入模型实例创建失败: siliconflow - [UNKNOWN_ERROR] SiliconFlow嵌入模型初始化失败: [siliconflow:siliconflow_BAAI/bge-large-zh-v1.5] SiliconFlow嵌入API连接测试失败: [siliconflow:siliconflow_BAAI/bge-large-zh-v1.5] API请求失败: 400 - {"code":20012,"message":"Model does not exist. Please check it carefully.","data":null} (错误码: 6000) (错误码: 3000)
2025-08-07 21:34:20 - rag_system.services.embedding_service - ERROR - embedding_service.py:242 - initialize - 嵌入服务初始化失败: [CONFIG_VALIDATION_ERROR] 无法创建主要嵌入模型实例: siliconflow
2025-08-07 21:34:20 - rag_system.services.document_service - ERROR - document_service.py:91 - initialize - 文档管理服务初始化失败: [CONFIG_VALIDATION_ERROR] 嵌入服务初始化失败: [CONFIG_VALIDATION_ERROR] 无法创建主要嵌入模型实例: siliconflow
2025-08-07 21:42:14 - rag_system.embeddings.siliconflow_embedding - ERROR - siliconflow_embedding.py:72 - initialize - SiliconFlow嵌入模型初始化失败: [siliconflow:siliconflow_BAAI/bge-large-zh-v1.5] SiliconFlow嵌入API连接测试失败: [siliconflow:siliconflow_BAAI/bge-large-zh-v1.5] API请求失败: 400 - {"code":20012,"message":"Model does not exist. Please check it carefully.","data":null} (错误码: 6000) (错误码: 3000)
2025-08-07 21:42:14 - rag_system.services.embedding_service - ERROR - embedding_service.py:72 - _create_embedding_instance - 嵌入模型实例创建失败: siliconflow - [UNKNOWN_ERROR] SiliconFlow嵌入模型初始化失败: [siliconflow:siliconflow_BAAI/bge-large-zh-v1.5] SiliconFlow嵌入API连接测试失败: [siliconflow:siliconflow_BAAI/bge-large-zh-v1.5] API请求失败: 400 - {"code":20012,"message":"Model does not exist. Please check it carefully.","data":null} (错误码: 6000) (错误码: 3000)
2025-08-07 21:42:14 - rag_system.services.embedding_service - ERROR - embedding_service.py:242 - initialize - 嵌入服务初始化失败: [CONFIG_VALIDATION_ERROR] 无法创建主要嵌入模型实例: siliconflow
2025-08-07 21:42:14 - rag_system.services.document_service - ERROR - document_service.py:91 - initialize - 文档管理服务初始化失败: [CONFIG_VALIDATION_ERROR] 嵌入服务初始化失败: [CONFIG_VALIDATION_ERROR] 无法创建主要嵌入模型实例: siliconflow
2025-08-07 21:42:36 - rag_system.embeddings.siliconflow_embedding - ERROR - siliconflow_embedding.py:72 - initialize - SiliconFlow嵌入模型初始化失败: [siliconflow:siliconflow_BAAI/bge-large-zh-v1.5] SiliconFlow嵌入API连接测试失败: [siliconflow:siliconflow_BAAI/bge-large-zh-v1.5] API请求失败: 400 - {"code":20012,"message":"Model does not exist. Please check it carefully.","data":null} (错误码: 6000) (错误码: 3000)
2025-08-07 21:42:36 - rag_system.services.embedding_service - ERROR - embedding_service.py:72 - _create_embedding_instance - 嵌入模型实例创建失败: siliconflow - [UNKNOWN_ERROR] SiliconFlow嵌入模型初始化失败: [siliconflow:siliconflow_BAAI/bge-large-zh-v1.5] SiliconFlow嵌入API连接测试失败: [siliconflow:siliconflow_BAAI/bge-large-zh-v1.5] API请求失败: 400 - {"code":20012,"message":"Model does not exist. Please check it carefully.","data":null} (错误码: 6000) (错误码: 3000)
2025-08-07 21:42:36 - rag_system.services.embedding_service - ERROR - embedding_service.py:242 - initialize - 嵌入服务初始化失败: [CONFIG_VALIDATION_ERROR] 无法创建主要嵌入模型实例: siliconflow
2025-08-07 21:42:36 - rag_system.services.document_service - ERROR - document_service.py:91 - initialize - 文档管理服务初始化失败: [CONFIG_VALIDATION_ERROR] 嵌入服务初始化失败: [CONFIG_VALIDATION_ERROR] 无法创建主要嵌入模型实例: siliconflow
2025-08-07 21:42:52 - rag_system.embeddings.siliconflow_embedding - ERROR - siliconflow_embedding.py:72 - initialize - SiliconFlow嵌入模型初始化失败: [siliconflow:siliconflow_BAAI/bge-large-zh-v1.5] SiliconFlow嵌入API连接测试失败: [siliconflow:siliconflow_BAAI/bge-large-zh-v1.5] API请求失败: 400 - {"code":20012,"message":"Model does not exist. Please check it carefully.","data":null} (错误码: 6000) (错误码: 3000)
2025-08-07 21:42:52 - rag_system.services.embedding_service - ERROR - embedding_service.py:72 - _create_embedding_instance - 嵌入模型实例创建失败: siliconflow - [UNKNOWN_ERROR] SiliconFlow嵌入模型初始化失败: [siliconflow:siliconflow_BAAI/bge-large-zh-v1.5] SiliconFlow嵌入API连接测试失败: [siliconflow:siliconflow_BAAI/bge-large-zh-v1.5] API请求失败: 400 - {"code":20012,"message":"Model does not exist. Please check it carefully.","data":null} (错误码: 6000) (错误码: 3000)
2025-08-07 21:42:52 - rag_system.services.embedding_service - ERROR - embedding_service.py:242 - initialize - 嵌入服务初始化失败: [CONFIG_VALIDATION_ERROR] 无法创建主要嵌入模型实例: siliconflow
2025-08-07 21:42:52 - rag_system.services.document_service - ERROR - document_service.py:91 - initialize - 文档管理服务初始化失败: [CONFIG_VALIDATION_ERROR] 嵌入服务初始化失败: [CONFIG_VALIDATION_ERROR] 无法创建主要嵌入模型实例: siliconflow
2025-08-07 21:42:52 - rag_system.embeddings.siliconflow_embedding - ERROR - siliconflow_embedding.py:72 - initialize - SiliconFlow嵌入模型初始化失败: [siliconflow:siliconflow_BAAI/bge-large-zh-v1.5] SiliconFlow嵌入API连接测试失败: [siliconflow:siliconflow_BAAI/bge-large-zh-v1.5] API请求失败: 400 - {"code":20012,"message":"Model does not exist. Please check it carefully.","data":null} (错误码: 6000) (错误码: 3000)
2025-08-07 21:42:52 - rag_system.services.embedding_service - ERROR - embedding_service.py:72 - _create_embedding_instance - 嵌入模型实例创建失败: siliconflow - [UNKNOWN_ERROR] SiliconFlow嵌入模型初始化失败: [siliconflow:siliconflow_BAAI/bge-large-zh-v1.5] SiliconFlow嵌入API连接测试失败: [siliconflow:siliconflow_BAAI/bge-large-zh-v1.5] API请求失败: 400 - {"code":20012,"message":"Model does not exist. Please check it carefully.","data":null} (错误码: 6000) (错误码: 3000)
2025-08-07 21:42:52 - rag_system.services.embedding_service - ERROR - embedding_service.py:242 - initialize - 嵌入服务初始化失败: [CONFIG_VALIDATION_ERROR] 无法创建主要嵌入模型实例: siliconflow
2025-08-07 21:42:52 - rag_system.services.document_service - ERROR - document_service.py:91 - initialize - 文档管理服务初始化失败: [CONFIG_VALIDATION_ERROR] 嵌入服务初始化失败: [CONFIG_VALIDATION_ERROR] 无法创建主要嵌入模型实例: siliconflow
2025-08-07 21:43:01 - rag_system.embeddings.siliconflow_embedding - ERROR - siliconflow_embedding.py:72 - initialize - SiliconFlow嵌入模型初始化失败: [siliconflow:siliconflow_BAAI/bge-large-zh-v1.5] SiliconFlow嵌入API连接测试失败: [siliconflow:siliconflow_BAAI/bge-large-zh-v1.5] API请求失败: 400 - {"code":20012,"message":"Model does not exist. Please check it carefully.","data":null} (错误码: 6000) (错误码: 3000)
2025-08-07 21:43:01 - rag_system.services.embedding_service - ERROR - embedding_service.py:72 - _create_embedding_instance - 嵌入模型实例创建失败: siliconflow - [UNKNOWN_ERROR] SiliconFlow嵌入模型初始化失败: [siliconflow:siliconflow_BAAI/bge-large-zh-v1.5] SiliconFlow嵌入API连接测试失败: [siliconflow:siliconflow_BAAI/bge-large-zh-v1.5] API请求失败: 400 - {"code":20012,"message":"Model does not exist. Please check it carefully.","data":null} (错误码: 6000) (错误码: 3000)
2025-08-07 21:43:01 - rag_system.services.embedding_service - ERROR - embedding_service.py:242 - initialize - 嵌入服务初始化失败: [CONFIG_VALIDATION_ERROR] 无法创建主要嵌入模型实例: siliconflow
2025-08-07 21:43:01 - rag_system.services.document_service - ERROR - document_service.py:91 - initialize - 文档管理服务初始化失败: [CONFIG_VALIDATION_ERROR] 嵌入服务初始化失败: [CONFIG_VALIDATION_ERROR] 无法创建主要嵌入模型实例: siliconflow
2025-08-07 21:43:01 - rag_system.embeddings.siliconflow_embedding - ERROR - siliconflow_embedding.py:72 - initialize - SiliconFlow嵌入模型初始化失败: [siliconflow:siliconflow_BAAI/bge-large-zh-v1.5] SiliconFlow嵌入API连接测试失败: [siliconflow:siliconflow_BAAI/bge-large-zh-v1.5] API请求失败: 400 - {"code":20012,"message":"Model does not exist. Please check it carefully.","data":null} (错误码: 6000) (错误码: 3000)
2025-08-07 21:43:01 - rag_system.services.embedding_service - ERROR - embedding_service.py:72 - _create_embedding_instance - 嵌入模型实例创建失败: siliconflow - [UNKNOWN_ERROR] SiliconFlow嵌入模型初始化失败: [siliconflow:siliconflow_BAAI/bge-large-zh-v1.5] SiliconFlow嵌入API连接测试失败: [siliconflow:siliconflow_BAAI/bge-large-zh-v1.5] API请求失败: 400 - {"code":20012,"message":"Model does not exist. Please check it carefully.","data":null} (错误码: 6000) (错误码: 3000)
2025-08-07 21:43:01 - rag_system.services.embedding_service - ERROR - embedding_service.py:242 - initialize - 嵌入服务初始化失败: [CONFIG_VALIDATION_ERROR] 无法创建主要嵌入模型实例: siliconflow
2025-08-07 21:43:01 - rag_system.services.document_service - ERROR - document_service.py:91 - initialize - 文档管理服务初始化失败: [CONFIG_VALIDATION_ERROR] 嵌入服务初始化失败: [CONFIG_VALIDATION_ERROR] 无法创建主要嵌入模型实例: siliconflow
2025-08-07 21:43:20 - rag_system.embeddings.siliconflow_embedding - ERROR - siliconflow_embedding.py:72 - initialize - SiliconFlow嵌入模型初始化失败: [siliconflow:siliconflow_BAAI/bge-large-zh-v1.5] SiliconFlow嵌入API连接测试失败: [siliconflow:siliconflow_BAAI/bge-large-zh-v1.5] API请求失败: 400 - {"code":20012,"message":"Model does not exist. Please check it carefully.","data":null} (错误码: 6000) (错误码: 3000)
2025-08-07 21:43:20 - rag_system.services.embedding_service - ERROR - embedding_service.py:72 - _create_embedding_instance - 嵌入模型实例创建失败: siliconflow - [UNKNOWN_ERROR] SiliconFlow嵌入模型初始化失败: [siliconflow:siliconflow_BAAI/bge-large-zh-v1.5] SiliconFlow嵌入API连接测试失败: [siliconflow:siliconflow_BAAI/bge-large-zh-v1.5] API请求失败: 400 - {"code":20012,"message":"Model does not exist. Please check it carefully.","data":null} (错误码: 6000) (错误码: 3000)
2025-08-07 21:43:20 - rag_system.services.embedding_service - ERROR - embedding_service.py:242 - initialize - 嵌入服务初始化失败: [CONFIG_VALIDATION_ERROR] 无法创建主要嵌入模型实例: siliconflow
2025-08-07 21:43:20 - rag_system.services.document_service - ERROR - document_service.py:91 - initialize - 文档管理服务初始化失败: [CONFIG_VALIDATION_ERROR] 嵌入服务初始化失败: [CONFIG_VALIDATION_ERROR] 无法创建主要嵌入模型实例: siliconflow
2025-08-07 21:43:39 - rag_system.embeddings.siliconflow_embedding - ERROR - siliconflow_embedding.py:72 - initialize - SiliconFlow嵌入模型初始化失败: [siliconflow:siliconflow_BAAI/bge-large-zh-v1.5] SiliconFlow嵌入API连接测试失败: [siliconflow:siliconflow_BAAI/bge-large-zh-v1.5] API请求失败: 400 - {"code":20012,"message":"Model does not exist. Please check it carefully.","data":null} (错误码: 6000) (错误码: 3000)
2025-08-07 21:43:39 - rag_system.services.embedding_service - ERROR - embedding_service.py:72 - _create_embedding_instance - 嵌入模型实例创建失败: siliconflow - [UNKNOWN_ERROR] SiliconFlow嵌入模型初始化失败: [siliconflow:siliconflow_BAAI/bge-large-zh-v1.5] SiliconFlow嵌入API连接测试失败: [siliconflow:siliconflow_BAAI/bge-large-zh-v1.5] API请求失败: 400 - {"code":20012,"message":"Model does not exist. Please check it carefully.","data":null} (错误码: 6000) (错误码: 3000)
2025-08-07 21:43:39 - rag_system.services.embedding_service - ERROR - embedding_service.py:242 - initialize - 嵌入服务初始化失败: [CONFIG_VALIDATION_ERROR] 无法创建主要嵌入模型实例: siliconflow
2025-08-07 21:43:39 - rag_system.services.document_service - ERROR - document_service.py:91 - initialize - 文档管理服务初始化失败: [CONFIG_VALIDATION_ERROR] 嵌入服务初始化失败: [CONFIG_VALIDATION_ERROR] 无法创建主要嵌入模型实例: siliconflow
2025-08-08 08:34:13 - rag_system.vector_store.chroma_store - ERROR - chroma_store.py:85 - initialize - Chroma向量数据库初始化失败: Could not connect to tenant default_tenant. Are you sure it exists?
2025-08-08 08:34:13 - rag_system.services.vector_service - ERROR - vector_service.py:42 - initialize - 向量存储服务初始化失败: [VECTOR_STORE_OPERATION_ERROR] Chroma初始化失败: Could not connect to tenant default_tenant. Are you sure it exists?
2025-08-08 08:34:13 - rag_system.services.document_service - ERROR - document_service.py:91 - initialize - 文档管理服务初始化失败: [VECTOR_STORE_OPERATION_ERROR] 向量存储服务初始化失败: [VECTOR_STORE_OPERATION_ERROR] Chroma初始化失败: Could not connect to tenant default_tenant. Are you sure it exists?
2025-08-08 08:36:04 - rag_system.services.reranking_service - ERROR - reranking_service.py:128 - _load_model - 模型加载失败: We couldn't connect to 'https://huggingface.co' to load this file, couldn't find it in the cached files and it looks like cross-encoder/ms-marco-MiniLM-L-6-v2 is not the path to a directory containing a file named config.json.
Checkout your internet connection or see how to run the library in offline mode at 'https://huggingface.co/docs/transformers/installation#offline-mode'.
2025-08-08 08:36:04 - rag_system.services.reranking_service - ERROR - reranking_service.py:109 - initialize - 重排序模型加载失败: We couldn't connect to 'https://huggingface.co' to load this file, couldn't find it in the cached files and it looks like cross-encoder/ms-marco-MiniLM-L-6-v2 is not the path to a directory containing a file named config.json.
Checkout your internet connection or see how to run the library in offline mode at 'https://huggingface.co/docs/transformers/installation#offline-mode'.
2025-08-08 11:54:22 - rag_system.vector_store.chroma_store - ERROR - chroma_store.py:85 - initialize - Chroma向量数据库初始化失败: Could not connect to tenant default_tenant. Are you sure it exists?
2025-08-08 11:54:22 - rag_system.services.vector_service - ERROR - vector_service.py:42 - initialize - 向量存储服务初始化失败: [VECTOR_STORE_OPERATION_ERROR] Chroma初始化失败: Could not connect to tenant default_tenant. Are you sure it exists?
2025-08-08 11:54:22 - rag_system.services.document_service - ERROR - document_service.py:91 - initialize - 文档管理服务初始化失败: [VECTOR_STORE_OPERATION_ERROR] 向量存储服务初始化失败: [VECTOR_STORE_OPERATION_ERROR] Chroma初始化失败: Could not connect to tenant default_tenant. Are you sure it exists?
2025-08-08 11:54:57 - rag_system.vector_store.chroma_store - ERROR - chroma_store.py:85 - initialize - Chroma向量数据库初始化失败: Could not connect to tenant default_tenant. Are you sure it exists?
2025-08-08 11:54:57 - rag_system.services.vector_service - ERROR - vector_service.py:42 - initialize - 向量存储服务初始化失败: [VECTOR_STORE_OPERATION_ERROR] Chroma初始化失败: Could not connect to tenant default_tenant. Are you sure it exists?
2025-08-08 11:54:57 - rag_system.services.document_service - ERROR - document_service.py:91 - initialize - 文档管理服务初始化失败: [VECTOR_STORE_OPERATION_ERROR] 向量存储服务初始化失败: [VECTOR_STORE_OPERATION_ERROR] Chroma初始化失败: Could not connect to tenant default_tenant. Are you sure it exists?
2025-08-08 12:46:54 - rag_system.services.reranking_service - ERROR - reranking_service.py:128 - _load_model - 模型加载失败: We couldn't connect to 'https://huggingface.co' to load this file, couldn't find it in the cached files and it looks like cross-encoder/ms-marco-MiniLM-L-6-v2 is not the path to a directory containing a file named config.json.
Checkout your internet connection or see how to run the library in offline mode at 'https://huggingface.co/docs/transformers/installation#offline-mode'.
2025-08-08 12:46:54 - rag_system.services.reranking_service - ERROR - reranking_service.py:109 - initialize - 重排序模型加载失败: We couldn't connect to 'https://huggingface.co' to load this file, couldn't find it in the cached files and it looks like cross-encoder/ms-marco-MiniLM-L-6-v2 is not the path to a directory containing a file named config.json.
Checkout your internet connection or see how to run the library in offline mode at 'https://huggingface.co/docs/transformers/installation#offline-mode'.
2025-08-08 13:36:17 - rag_system.vector_store.chroma_store - ERROR - chroma_store.py:85 - initialize - Chroma向量数据库初始化失败: Could not connect to tenant default_tenant. Are you sure it exists?
2025-08-08 13:36:17 - rag_system.services.vector_service - ERROR - vector_service.py:42 - initialize - 向量存储服务初始化失败: [VECTOR_STORE_OPERATION_ERROR] Chroma初始化失败: Could not connect to tenant default_tenant. Are you sure it exists?
2025-08-08 13:36:17 - rag_system.services.document_service - ERROR - document_service.py:91 - initialize - 文档管理服务初始化失败: [VECTOR_STORE_OPERATION_ERROR] 向量存储服务初始化失败: [VECTOR_STORE_OPERATION_ERROR] Chroma初始化失败: Could not connect to tenant default_tenant. Are you sure it exists?
2025-08-08 13:47:53 - rag_system.reranking.local_reranking - ERROR - local_reranking.py:77 - _load_model - 本地模型加载失败: We couldn't connect to 'https://huggingface.co' to load this file, couldn't find it in the cached files and it looks like cross-encoder/ms-marco-MiniLM-L-6-v2 is not the path to a directory containing a file named config.json.
Checkout your internet connection or see how to run the library in offline mode at 'https://huggingface.co/docs/transformers/installation#offline-mode'.
2025-08-08 13:47:53 - rag_system.reranking.local_reranking - ERROR - local_reranking.py:48 - initialize - 本地重排序模型加载失败: We couldn't connect to 'https://huggingface.co' to load this file, couldn't find it in the cached files and it looks like cross-encoder/ms-marco-MiniLM-L-6-v2 is not the path to a directory containing a file named config.json.
Checkout your internet connection or see how to run the library in offline mode at 'https://huggingface.co/docs/transformers/installation#offline-mode'.
2025-08-08 13:47:53 - rag_system.services.reranking_service - ERROR - reranking_service.py:193 - _create_reranking_instance - 重排序模型实例创建失败: local - 本地重排序模型加载失败: We couldn't connect to 'https://huggingface.co' to load this file, couldn't find it in the cached files and it looks like cross-encoder/ms-marco-MiniLM-L-6-v2 is not the path to a directory containing a file named config.json.
Checkout your internet connection or see how to run the library in offline mode at 'https://huggingface.co/docs/transformers/installation#offline-mode'.
2025-08-08 13:47:53 - rag_system.services.reranking_service - ERROR - reranking_service.py:181 - initialize - 重排序服务初始化失败: [CONFIG_VALIDATION_ERROR] 无法创建主要重排序模型实例: local
2025-08-08 13:47:53 - rag_system.services.enhanced_retrieval_service - ERROR - enhanced_retrieval_service.py:103 - initialize - 增强检索服务初始化失败: [CONFIG_VALIDATION_ERROR] 重排序服务初始化失败: [CONFIG_VALIDATION_ERROR] 无法创建主要重排序模型实例: local
2025-08-08 13:47:53 - rag_system.services.qa_service - ERROR - qa_service.py:185 - initialize - 问答服务初始化失败: [UNKNOWN_ERROR] 增强检索服务初始化失败: [CONFIG_VALIDATION_ERROR] 重排序服务初始化失败: [CONFIG_VALIDATION_ERROR] 无法创建主要重排序模型实例: local
2025-08-08 13:49:36 - rag_system.reranking.local_reranking - ERROR - local_reranking.py:77 - _load_model - 本地模型加载失败: We couldn't connect to 'https://huggingface.co' to load this file, couldn't find it in the cached files and it looks like cross-encoder/ms-marco-MiniLM-L-6-v2 is not the path to a directory containing a file named config.json.
Checkout your internet connection or see how to run the library in offline mode at 'https://huggingface.co/docs/transformers/installation#offline-mode'.
2025-08-08 13:49:36 - rag_system.reranking.local_reranking - ERROR - local_reranking.py:48 - initialize - 本地重排序模型加载失败: We couldn't connect to 'https://huggingface.co' to load this file, couldn't find it in the cached files and it looks like cross-encoder/ms-marco-MiniLM-L-6-v2 is not the path to a directory containing a file named config.json.
Checkout your internet connection or see how to run the library in offline mode at 'https://huggingface.co/docs/transformers/installation#offline-mode'.
2025-08-08 13:49:36 - rag_system.services.reranking_service - ERROR - reranking_service.py:193 - _create_reranking_instance - 重排序模型实例创建失败: local - 本地重排序模型加载失败: We couldn't connect to 'https://huggingface.co' to load this file, couldn't find it in the cached files and it looks like cross-encoder/ms-marco-MiniLM-L-6-v2 is not the path to a directory containing a file named config.json.
Checkout your internet connection or see how to run the library in offline mode at 'https://huggingface.co/docs/transformers/installation#offline-mode'.
2025-08-08 13:49:36 - rag_system.services.reranking_service - ERROR - reranking_service.py:181 - initialize - 重排序服务初始化失败: [CONFIG_VALIDATION_ERROR] 无法创建主要重排序模型实例: local
2025-08-08 13:49:36 - rag_system.services.enhanced_retrieval_service - ERROR - enhanced_retrieval_service.py:103 - initialize - 增强检索服务初始化失败: [CONFIG_VALIDATION_ERROR] 重排序服务初始化失败: [CONFIG_VALIDATION_ERROR] 无法创建主要重排序模型实例: local
2025-08-08 13:49:36 - rag_system.services.qa_service - ERROR - qa_service.py:185 - initialize - 问答服务初始化失败: [UNKNOWN_ERROR] 增强检索服务初始化失败: [CONFIG_VALIDATION_ERROR] 重排序服务初始化失败: [CONFIG_VALIDATION_ERROR] 无法创建主要重排序模型实例: local
2025-08-08 14:01:06 - rag_system.vector_store.chroma_store - ERROR - chroma_store.py:85 - initialize - Chroma向量数据库初始化失败: Could not connect to tenant default_tenant. Are you sure it exists?
2025-08-08 14:01:06 - rag_system.services.vector_service - ERROR - vector_service.py:42 - initialize - 向量存储服务初始化失败: [VECTOR_STORE_OPERATION_ERROR] Chroma初始化失败: Could not connect to tenant default_tenant. Are you sure it exists?
2025-08-08 14:01:06 - rag_system.services.document_service - ERROR - document_service.py:91 - initialize - 文档管理服务初始化失败: [VECTOR_STORE_OPERATION_ERROR] 向量存储服务初始化失败: [VECTOR_STORE_OPERATION_ERROR] Chroma初始化失败: Could not connect to tenant default_tenant. Are you sure it exists?
2025-08-08 14:26:01 - rag_system.vector_store.chroma_store - ERROR - chroma_store.py:85 - initialize - Chroma向量数据库初始化失败: Could not connect to tenant default_tenant. Are you sure it exists?
2025-08-08 14:26:01 - rag_system.services.vector_service - ERROR - vector_service.py:42 - initialize - 向量存储服务初始化失败: [VECTOR_STORE_OPERATION_ERROR] Chroma初始化失败: Could not connect to tenant default_tenant. Are you sure it exists?
2025-08-08 14:26:01 - rag_system.services.document_service - ERROR - document_service.py:91 - initialize - 文档管理服务初始化失败: [VECTOR_STORE_OPERATION_ERROR] 向量存储服务初始化失败: [VECTOR_STORE_OPERATION_ERROR] Chroma初始化失败: Could not connect to tenant default_tenant. Are you sure it exists?
2025-08-08 14:37:47 - rag_system.vector_store.chroma_store - ERROR - chroma_store.py:85 - initialize - Chroma向量数据库初始化失败: Could not connect to tenant default_tenant. Are you sure it exists?
2025-08-08 14:37:47 - rag_system.services.vector_service - ERROR - vector_service.py:42 - initialize - 向量存储服务初始化失败: [VECTOR_STORE_OPERATION_ERROR] Chroma初始化失败: Could not connect to tenant default_tenant. Are you sure it exists?
2025-08-08 14:37:47 - rag_system.services.document_service - ERROR - document_service.py:91 - initialize - 文档管理服务初始化失败: [VECTOR_STORE_OPERATION_ERROR] 向量存储服务初始化失败: [VECTOR_STORE_OPERATION_ERROR] Chroma初始化失败: Could not connect to tenant default_tenant. Are you sure it exists?
2025-08-08 14:37:47 - rag_system.vector_store.chroma_store - ERROR - chroma_store.py:85 - initialize - Chroma向量数据库初始化失败: Could not connect to tenant default_tenant. Are you sure it exists?
2025-08-08 14:37:47 - rag_system.services.vector_service - ERROR - vector_service.py:42 - initialize - 向量存储服务初始化失败: [VECTOR_STORE_OPERATION_ERROR] Chroma初始化失败: Could not connect to tenant default_tenant. Are you sure it exists?
2025-08-08 14:37:47 - rag_system.services.document_service - ERROR - document_service.py:91 - initialize - 文档管理服务初始化失败: [VECTOR_STORE_OPERATION_ERROR] 向量存储服务初始化失败: [VECTOR_STORE_OPERATION_ERROR] Chroma初始化失败: Could not connect to tenant default_tenant. Are you sure it exists?
2025-08-08 14:41:04 - rag_system.vector_store.chroma_store - ERROR - chroma_store.py:85 - initialize - Chroma向量数据库初始化失败: Could not connect to tenant default_tenant. Are you sure it exists?
2025-08-08 14:41:04 - rag_system.services.vector_service - ERROR - vector_service.py:42 - initialize - 向量存储服务初始化失败: [VECTOR_STORE_OPERATION_ERROR] Chroma初始化失败: Could not connect to tenant default_tenant. Are you sure it exists?
2025-08-08 14:41:04 - rag_system.services.document_service - ERROR - document_service.py:91 - initialize - 文档管理服务初始化失败: [VECTOR_STORE_OPERATION_ERROR] 向量存储服务初始化失败: [VECTOR_STORE_OPERATION_ERROR] Chroma初始化失败: Could not connect to tenant default_tenant. Are you sure it exists?
2025-08-08 14:47:40 - rag_system.services.model_manager - ERROR - model_manager.py:410 - _load_embedding_model - 加载embedding模型失败: default_embedding, 错误: 1 validation error for EmbeddingConfig
  Value error, 提供商 openai 需要API密钥 [type=value_error, input_value={'provider': 'openai', 'm...s': 8192, 'timeout': 30}, input_type=dict]
    For further information visit https://errors.pydantic.dev/2.11/v/value_error
2025-08-08 14:47:40 - rag_system.services.model_manager - ERROR - model_manager.py:375 - load_model - 模型加载失败: default_embedding
2025-08-08 14:47:43 - rag_system.services.model_manager - ERROR - model_manager.py:410 - _load_embedding_model - 加载embedding模型失败: default_embedding, 错误: 1 validation error for EmbeddingConfig
  Value error, 提供商 openai 需要API密钥 [type=value_error, input_value={'provider': 'openai', 'm...s': 8192, 'timeout': 30}, input_type=dict]
    For further information visit https://errors.pydantic.dev/2.11/v/value_error
2025-08-08 14:47:43 - rag_system.services.model_manager - ERROR - model_manager.py:375 - load_model - 模型加载失败: default_embedding
2025-08-08 14:47:47 - rag_system.services.reranking_service - ERROR - reranking_service.py:161 - _load_model - 模型加载失败: We couldn't connect to 'https://huggingface.co' to load this file, couldn't find it in the cached files and it looks like cross-encoder/ms-marco-MiniLM-L-6-v2 is not the path to a directory containing a file named config.json.
Checkout your internet connection or see how to run the library in offline mode at 'https://huggingface.co/docs/transformers/installation#offline-mode'.
2025-08-08 14:47:47 - rag_system.services.reranking_service - ERROR - reranking_service.py:125 - initialize - 重排序模型加载失败: We couldn't connect to 'https://huggingface.co' to load this file, couldn't find it in the cached files and it looks like cross-encoder/ms-marco-MiniLM-L-6-v2 is not the path to a directory containing a file named config.json.
Checkout your internet connection or see how to run the library in offline mode at 'https://huggingface.co/docs/transformers/installation#offline-mode'.
2025-08-08 14:48:41 - rag_system.services.model_manager - ERROR - model_manager.py:410 - _load_embedding_model - 加载embedding模型失败: default_embedding, 错误: 1 validation error for EmbeddingConfig
  Value error, 提供商 openai 需要API密钥 [type=value_error, input_value={'provider': 'openai', 'm...s': 8192, 'timeout': 30}, input_type=dict]
    For further information visit https://errors.pydantic.dev/2.11/v/value_error
2025-08-08 14:48:41 - rag_system.services.model_manager - ERROR - model_manager.py:375 - load_model - 模型加载失败: default_embedding
2025-08-08 14:48:44 - rag_system.services.reranking_service - ERROR - reranking_service.py:161 - _load_model - 模型加载失败: We couldn't connect to 'https://huggingface.co' to load this file, couldn't find it in the cached files and it looks like cross-encoder/ms-marco-MiniLM-L-6-v2 is not the path to a directory containing a file named config.json.
Checkout your internet connection or see how to run the library in offline mode at 'https://huggingface.co/docs/transformers/installation#offline-mode'.
2025-08-08 14:48:44 - rag_system.services.reranking_service - ERROR - reranking_service.py:125 - initialize - 重排序模型加载失败: We couldn't connect to 'https://huggingface.co' to load this file, couldn't find it in the cached files and it looks like cross-encoder/ms-marco-MiniLM-L-6-v2 is not the path to a directory containing a file named config.json.
Checkout your internet connection or see how to run the library in offline mode at 'https://huggingface.co/docs/transformers/installation#offline-mode'.
2025-08-08 14:51:44 - rag_system.services.model_manager - ERROR - model_manager.py:410 - _load_embedding_model - 加载embedding模型失败: default_embedding, 错误: 1 validation error for EmbeddingConfig
  Value error, 提供商 openai 需要API密钥 [type=value_error, input_value={'provider': 'openai', 'm...s': 8192, 'timeout': 30}, input_type=dict]
    For further information visit https://errors.pydantic.dev/2.11/v/value_error
2025-08-08 14:51:44 - rag_system.services.model_manager - ERROR - model_manager.py:375 - load_model - 模型加载失败: default_embedding
2025-08-08 14:51:48 - rag_system.services.reranking_service - ERROR - reranking_service.py:161 - _load_model - 模型加载失败: We couldn't connect to 'https://huggingface.co' to load this file, couldn't find it in the cached files and it looks like cross-encoder/ms-marco-MiniLM-L-6-v2 is not the path to a directory containing a file named config.json.
Checkout your internet connection or see how to run the library in offline mode at 'https://huggingface.co/docs/transformers/installation#offline-mode'.
2025-08-08 14:51:48 - rag_system.services.reranking_service - ERROR - reranking_service.py:125 - initialize - 重排序模型加载失败: We couldn't connect to 'https://huggingface.co' to load this file, couldn't find it in the cached files and it looks like cross-encoder/ms-marco-MiniLM-L-6-v2 is not the path to a directory containing a file named config.json.
Checkout your internet connection or see how to run the library in offline mode at 'https://huggingface.co/docs/transformers/installation#offline-mode'.
2025-08-08 14:51:51 - rag_system.services.model_manager - ERROR - model_manager.py:410 - _load_embedding_model - 加载embedding模型失败: default_embedding, 错误: 1 validation error for EmbeddingConfig
  Value error, 提供商 openai 需要API密钥 [type=value_error, input_value={'provider': 'openai', 'm...s': 8192, 'timeout': 30}, input_type=dict]
    For further information visit https://errors.pydantic.dev/2.11/v/value_error
2025-08-08 14:51:51 - rag_system.services.model_manager - ERROR - model_manager.py:375 - load_model - 模型加载失败: default_embedding
2025-08-08 14:51:55 - rag_system.services.reranking_service - ERROR - reranking_service.py:161 - _load_model - 模型加载失败: We couldn't connect to 'https://huggingface.co' to load this file, couldn't find it in the cached files and it looks like cross-encoder/ms-marco-MiniLM-L-6-v2 is not the path to a directory containing a file named config.json.
Checkout your internet connection or see how to run the library in offline mode at 'https://huggingface.co/docs/transformers/installation#offline-mode'.
2025-08-08 14:51:55 - rag_system.services.reranking_service - ERROR - reranking_service.py:125 - initialize - 重排序模型加载失败: We couldn't connect to 'https://huggingface.co' to load this file, couldn't find it in the cached files and it looks like cross-encoder/ms-marco-MiniLM-L-6-v2 is not the path to a directory containing a file named config.json.
Checkout your internet connection or see how to run the library in offline mode at 'https://huggingface.co/docs/transformers/installation#offline-mode'.
2025-08-08 14:52:44 - rag_system.services.model_manager - ERROR - model_manager.py:410 - _load_embedding_model - 加载embedding模型失败: default_embedding, 错误: 1 validation error for EmbeddingConfig
  Value error, 提供商 openai 需要API密钥 [type=value_error, input_value={'provider': 'openai', 'm...s': 8192, 'timeout': 30}, input_type=dict]
    For further information visit https://errors.pydantic.dev/2.11/v/value_error
2025-08-08 14:52:44 - rag_system.services.model_manager - ERROR - model_manager.py:375 - load_model - 模型加载失败: default_embedding
2025-08-08 14:52:47 - rag_system.services.model_manager - ERROR - model_manager.py:410 - _load_embedding_model - 加载embedding模型失败: default_embedding, 错误: 1 validation error for EmbeddingConfig
  Value error, 提供商 openai 需要API密钥 [type=value_error, input_value={'provider': 'openai', 'm...s': 8192, 'timeout': 30}, input_type=dict]
    For further information visit https://errors.pydantic.dev/2.11/v/value_error
2025-08-08 14:52:47 - rag_system.services.model_manager - ERROR - model_manager.py:375 - load_model - 模型加载失败: default_embedding
2025-08-08 14:56:43 - rag_system.services.model_manager - ERROR - model_manager.py:410 - _load_embedding_model - 加载embedding模型失败: default_embedding, 错误: 1 validation error for EmbeddingConfig
  Value error, 提供商 openai 需要API密钥 [type=value_error, input_value={'provider': 'openai', 'm...s': 8192, 'timeout': 30}, input_type=dict]
    For further information visit https://errors.pydantic.dev/2.11/v/value_error
2025-08-08 14:56:43 - rag_system.services.model_manager - ERROR - model_manager.py:375 - load_model - 模型加载失败: default_embedding
2025-08-08 14:56:46 - rag_system.services.model_manager - ERROR - model_manager.py:410 - _load_embedding_model - 加载embedding模型失败: default_embedding, 错误: 1 validation error for EmbeddingConfig
  Value error, 提供商 openai 需要API密钥 [type=value_error, input_value={'provider': 'openai', 'm...s': 8192, 'timeout': 30}, input_type=dict]
    For further information visit https://errors.pydantic.dev/2.11/v/value_error
2025-08-08 14:56:46 - rag_system.services.model_manager - ERROR - model_manager.py:375 - load_model - 模型加载失败: default_embedding
2025-08-08 14:56:46 - rag_system.services.reranking_service - ERROR - reranking_service.py:161 - _load_model - 模型加载失败: We couldn't connect to 'https://huggingface.co' to load this file, couldn't find it in the cached files and it looks like cross-encoder/ms-marco-MiniLM-L-6-v2 is not the path to a directory containing a file named config.json.
Checkout your internet connection or see how to run the library in offline mode at 'https://huggingface.co/docs/transformers/installation#offline-mode'.
2025-08-08 14:56:46 - rag_system.services.reranking_service - ERROR - reranking_service.py:125 - initialize - 重排序模型加载失败: We couldn't connect to 'https://huggingface.co' to load this file, couldn't find it in the cached files and it looks like cross-encoder/ms-marco-MiniLM-L-6-v2 is not the path to a directory containing a file named config.json.
Checkout your internet connection or see how to run the library in offline mode at 'https://huggingface.co/docs/transformers/installation#offline-mode'.
2025-08-08 14:56:46 - rag_system.services.model_manager - ERROR - model_manager.py:410 - _load_embedding_model - 加载embedding模型失败: siliconflow_BAAI_bge_large_zh_v1_5, 错误: 2 validation errors for EmbeddingConfig
chunk_size
  Extra inputs are not permitted [type=extra_forbidden, input_value=100, input_type=int]
    For further information visit https://errors.pydantic.dev/2.11/v/extra_forbidden
chunk_overlap
  Extra inputs are not permitted [type=extra_forbidden, input_value=5, input_type=int]
    For further information visit https://errors.pydantic.dev/2.11/v/extra_forbidden
2025-08-08 14:56:46 - rag_system.services.model_manager - ERROR - model_manager.py:375 - load_model - 模型加载失败: siliconflow_BAAI_bge_large_zh_v1_5
2025-08-08 14:56:46 - rag_system.services.reranking_service - ERROR - reranking_service.py:161 - _load_model - 模型加载失败: We couldn't connect to 'https://huggingface.co' to load this file, couldn't find it in the cached files and it looks like cross-encoder/ms-marco-MiniLM-L-6-v2 is not the path to a directory containing a file named config.json.
Checkout your internet connection or see how to run the library in offline mode at 'https://huggingface.co/docs/transformers/installation#offline-mode'.
2025-08-08 14:56:46 - rag_system.services.reranking_service - ERROR - reranking_service.py:125 - initialize - 重排序模型加载失败: We couldn't connect to 'https://huggingface.co' to load this file, couldn't find it in the cached files and it looks like cross-encoder/ms-marco-MiniLM-L-6-v2 is not the path to a directory containing a file named config.json.
Checkout your internet connection or see how to run the library in offline mode at 'https://huggingface.co/docs/transformers/installation#offline-mode'.
2025-08-08 14:56:46 - rag_system.services.model_manager - ERROR - model_manager.py:410 - _load_embedding_model - 加载embedding模型失败: siliconflow_BAAI_bge_large_zh_v1_5, 错误: 2 validation errors for EmbeddingConfig
chunk_size
  Extra inputs are not permitted [type=extra_forbidden, input_value=100, input_type=int]
    For further information visit https://errors.pydantic.dev/2.11/v/extra_forbidden
chunk_overlap
  Extra inputs are not permitted [type=extra_forbidden, input_value=5, input_type=int]
    For further information visit https://errors.pydantic.dev/2.11/v/extra_forbidden
2025-08-08 14:56:46 - rag_system.services.model_manager - ERROR - model_manager.py:375 - load_model - 模型加载失败: siliconflow_BAAI_bge_large_zh_v1_5
2025-08-08 15:01:02 - rag_system.vector_store.chroma_store - ERROR - chroma_store.py:85 - initialize - Chroma向量数据库初始化失败: Could not connect to tenant default_tenant. Are you sure it exists?
2025-08-08 15:01:02 - rag_system.services.vector_service - ERROR - vector_service.py:42 - initialize - 向量存储服务初始化失败: [VECTOR_STORE_OPERATION_ERROR] Chroma初始化失败: Could not connect to tenant default_tenant. Are you sure it exists?
2025-08-08 15:01:02 - rag_system.services.document_service - ERROR - document_service.py:91 - initialize - 文档管理服务初始化失败: [VECTOR_STORE_OPERATION_ERROR] 向量存储服务初始化失败: [VECTOR_STORE_OPERATION_ERROR] Chroma初始化失败: Could not connect to tenant default_tenant. Are you sure it exists?
2025-08-08 15:01:11 - rag_system.services.model_manager - ERROR - model_manager.py:410 - _load_embedding_model - 加载embedding模型失败: default_embedding, 错误: 1 validation error for EmbeddingConfig
  Value error, 提供商 openai 需要API密钥 [type=value_error, input_value={'provider': 'openai', 'm...s': 8192, 'timeout': 30}, input_type=dict]
    For further information visit https://errors.pydantic.dev/2.11/v/value_error
2025-08-08 15:01:11 - rag_system.services.model_manager - ERROR - model_manager.py:375 - load_model - 模型加载失败: default_embedding
2025-08-08 15:01:15 - rag_system.services.reranking_service - ERROR - reranking_service.py:161 - _load_model - 模型加载失败: We couldn't connect to 'https://huggingface.co' to load this file, couldn't find it in the cached files and it looks like cross-encoder/ms-marco-MiniLM-L-6-v2 is not the path to a directory containing a file named config.json.
Checkout your internet connection or see how to run the library in offline mode at 'https://huggingface.co/docs/transformers/installation#offline-mode'.
2025-08-08 15:01:15 - rag_system.services.reranking_service - ERROR - reranking_service.py:125 - initialize - 重排序模型加载失败: We couldn't connect to 'https://huggingface.co' to load this file, couldn't find it in the cached files and it looks like cross-encoder/ms-marco-MiniLM-L-6-v2 is not the path to a directory containing a file named config.json.
Checkout your internet connection or see how to run the library in offline mode at 'https://huggingface.co/docs/transformers/installation#offline-mode'.
2025-08-08 15:01:15 - rag_system.services.model_manager - ERROR - model_manager.py:410 - _load_embedding_model - 加载embedding模型失败: siliconflow_BAAI_bge_large_zh_v1_5, 错误: 2 validation errors for EmbeddingConfig
chunk_size
  Extra inputs are not permitted [type=extra_forbidden, input_value=1000, input_type=int]
    For further information visit https://errors.pydantic.dev/2.11/v/extra_forbidden
chunk_overlap
  Extra inputs are not permitted [type=extra_forbidden, input_value=50, input_type=int]
    For further information visit https://errors.pydantic.dev/2.11/v/extra_forbidden
2025-08-08 15:01:15 - rag_system.services.model_manager - ERROR - model_manager.py:375 - load_model - 模型加载失败: siliconflow_BAAI_bge_large_zh_v1_5
2025-08-08 15:01:24 - rag_system.services.model_manager - ERROR - model_manager.py:410 - _load_embedding_model - 加载embedding模型失败: default_embedding, 错误: 1 validation error for EmbeddingConfig
  Value error, 提供商 openai 需要API密钥 [type=value_error, input_value={'provider': 'openai', 'm...s': 8192, 'timeout': 30}, input_type=dict]
    For further information visit https://errors.pydantic.dev/2.11/v/value_error
2025-08-08 15:01:24 - rag_system.services.model_manager - ERROR - model_manager.py:375 - load_model - 模型加载失败: default_embedding
2025-08-08 15:01:27 - rag_system.services.reranking_service - ERROR - reranking_service.py:161 - _load_model - 模型加载失败: We couldn't connect to 'https://huggingface.co' to load this file, couldn't find it in the cached files and it looks like cross-encoder/ms-marco-MiniLM-L-6-v2 is not the path to a directory containing a file named config.json.
Checkout your internet connection or see how to run the library in offline mode at 'https://huggingface.co/docs/transformers/installation#offline-mode'.
2025-08-08 15:01:27 - rag_system.services.reranking_service - ERROR - reranking_service.py:125 - initialize - 重排序模型加载失败: We couldn't connect to 'https://huggingface.co' to load this file, couldn't find it in the cached files and it looks like cross-encoder/ms-marco-MiniLM-L-6-v2 is not the path to a directory containing a file named config.json.
Checkout your internet connection or see how to run the library in offline mode at 'https://huggingface.co/docs/transformers/installation#offline-mode'.
2025-08-08 15:01:27 - rag_system.services.model_manager - ERROR - model_manager.py:410 - _load_embedding_model - 加载embedding模型失败: test_embedding_persistence, 错误: rag_system.embeddings.base.EmbeddingConfig() got multiple values for keyword argument 'provider'
2025-08-08 15:01:27 - rag_system.services.model_manager - ERROR - model_manager.py:375 - load_model - 模型加载失败: test_embedding_persistence
2025-08-08 15:01:32 - rag_system.services.model_manager - ERROR - model_manager.py:410 - _load_embedding_model - 加载embedding模型失败: default_embedding, 错误: 1 validation error for EmbeddingConfig
  Value error, 提供商 openai 需要API密钥 [type=value_error, input_value={'provider': 'openai', 'm...s': 8192, 'timeout': 30}, input_type=dict]
    For further information visit https://errors.pydantic.dev/2.11/v/value_error
2025-08-08 15:01:32 - rag_system.services.model_manager - ERROR - model_manager.py:375 - load_model - 模型加载失败: default_embedding
2025-08-08 15:01:32 - rag_system.services.reranking_service - ERROR - reranking_service.py:161 - _load_model - 模型加载失败: We couldn't connect to 'https://huggingface.co' to load this file, couldn't find it in the cached files and it looks like cross-encoder/ms-marco-MiniLM-L-6-v2 is not the path to a directory containing a file named config.json.
Checkout your internet connection or see how to run the library in offline mode at 'https://huggingface.co/docs/transformers/installation#offline-mode'.
2025-08-08 15:01:32 - rag_system.services.reranking_service - ERROR - reranking_service.py:125 - initialize - 重排序模型加载失败: We couldn't connect to 'https://huggingface.co' to load this file, couldn't find it in the cached files and it looks like cross-encoder/ms-marco-MiniLM-L-6-v2 is not the path to a directory containing a file named config.json.
Checkout your internet connection or see how to run the library in offline mode at 'https://huggingface.co/docs/transformers/installation#offline-mode'.
2025-08-08 15:01:49 - rag_system.vector_store.chroma_store - ERROR - chroma_store.py:85 - initialize - Chroma向量数据库初始化失败: Could not connect to tenant default_tenant. Are you sure it exists?
2025-08-08 15:01:49 - rag_system.services.vector_service - ERROR - vector_service.py:42 - initialize - 向量存储服务初始化失败: [VECTOR_STORE_OPERATION_ERROR] Chroma初始化失败: Could not connect to tenant default_tenant. Are you sure it exists?
2025-08-08 15:01:49 - rag_system.services.document_service - ERROR - document_service.py:91 - initialize - 文档管理服务初始化失败: [VECTOR_STORE_OPERATION_ERROR] 向量存储服务初始化失败: [VECTOR_STORE_OPERATION_ERROR] Chroma初始化失败: Could not connect to tenant default_tenant. Are you sure it exists?
2025-08-08 15:02:34 - rag_system.services.model_manager - ERROR - model_manager.py:410 - _load_embedding_model - 加载embedding模型失败: default_embedding, 错误: 1 validation error for EmbeddingConfig
  Value error, 提供商 openai 需要API密钥 [type=value_error, input_value={'provider': 'openai', 'm...s': 8192, 'timeout': 30}, input_type=dict]
    For further information visit https://errors.pydantic.dev/2.11/v/value_error
2025-08-08 15:02:34 - rag_system.services.model_manager - ERROR - model_manager.py:375 - load_model - 模型加载失败: default_embedding
2025-08-08 15:02:34 - rag_system.services.reranking_service - ERROR - reranking_service.py:161 - _load_model - 模型加载失败: We couldn't connect to 'https://huggingface.co' to load this file, couldn't find it in the cached files and it looks like cross-encoder/ms-marco-MiniLM-L-6-v2 is not the path to a directory containing a file named config.json.
Checkout your internet connection or see how to run the library in offline mode at 'https://huggingface.co/docs/transformers/installation#offline-mode'.
2025-08-08 15:02:34 - rag_system.services.reranking_service - ERROR - reranking_service.py:125 - initialize - 重排序模型加载失败: We couldn't connect to 'https://huggingface.co' to load this file, couldn't find it in the cached files and it looks like cross-encoder/ms-marco-MiniLM-L-6-v2 is not the path to a directory containing a file named config.json.
Checkout your internet connection or see how to run the library in offline mode at 'https://huggingface.co/docs/transformers/installation#offline-mode'.
2025-08-08 15:02:34 - rag_system.services.model_manager - ERROR - model_manager.py:410 - _load_embedding_model - 加载embedding模型失败: siliconflow_BAAI_bge_large_zh_v1_5, 错误: 2 validation errors for EmbeddingConfig
chunk_size
  Extra inputs are not permitted [type=extra_forbidden, input_value=100, input_type=int]
    For further information visit https://errors.pydantic.dev/2.11/v/extra_forbidden
chunk_overlap
  Extra inputs are not permitted [type=extra_forbidden, input_value=5, input_type=int]
    For further information visit https://errors.pydantic.dev/2.11/v/extra_forbidden
2025-08-08 15:02:34 - rag_system.services.model_manager - ERROR - model_manager.py:375 - load_model - 模型加载失败: siliconflow_BAAI_bge_large_zh_v1_5
2025-08-08 15:05:17 - rag_system.services.model_manager - ERROR - model_manager.py:410 - _load_embedding_model - 加载embedding模型失败: default_embedding, 错误: 1 validation error for EmbeddingConfig
  Value error, 提供商 openai 需要API密钥 [type=value_error, input_value={'provider': 'openai', 'm...s': 8192, 'timeout': 30}, input_type=dict]
    For further information visit https://errors.pydantic.dev/2.11/v/value_error
2025-08-08 15:05:17 - rag_system.services.model_manager - ERROR - model_manager.py:375 - load_model - 模型加载失败: default_embedding
2025-08-08 15:05:17 - rag_system.services.reranking_service - ERROR - reranking_service.py:161 - _load_model - 模型加载失败: We couldn't connect to 'https://huggingface.co' to load this file, couldn't find it in the cached files and it looks like cross-encoder/ms-marco-MiniLM-L-6-v2 is not the path to a directory containing a file named config.json.
Checkout your internet connection or see how to run the library in offline mode at 'https://huggingface.co/docs/transformers/installation#offline-mode'.
2025-08-08 15:05:17 - rag_system.services.reranking_service - ERROR - reranking_service.py:125 - initialize - 重排序模型加载失败: We couldn't connect to 'https://huggingface.co' to load this file, couldn't find it in the cached files and it looks like cross-encoder/ms-marco-MiniLM-L-6-v2 is not the path to a directory containing a file named config.json.
Checkout your internet connection or see how to run the library in offline mode at 'https://huggingface.co/docs/transformers/installation#offline-mode'.
2025-08-08 15:05:48 - rag_system.services.model_manager - ERROR - model_manager.py:410 - _load_embedding_model - 加载embedding模型失败: default_embedding, 错误: 1 validation error for EmbeddingConfig
  Value error, 提供商 openai 需要API密钥 [type=value_error, input_value={'provider': 'openai', 'm...s': 8192, 'timeout': 30}, input_type=dict]
    For further information visit https://errors.pydantic.dev/2.11/v/value_error
2025-08-08 15:05:48 - rag_system.services.model_manager - ERROR - model_manager.py:375 - load_model - 模型加载失败: default_embedding
2025-08-08 15:05:48 - rag_system.services.reranking_service - ERROR - reranking_service.py:161 - _load_model - 模型加载失败: We couldn't connect to 'https://huggingface.co' to load this file, couldn't find it in the cached files and it looks like cross-encoder/ms-marco-MiniLM-L-6-v2 is not the path to a directory containing a file named config.json.
Checkout your internet connection or see how to run the library in offline mode at 'https://huggingface.co/docs/transformers/installation#offline-mode'.
2025-08-08 15:05:48 - rag_system.services.reranking_service - ERROR - reranking_service.py:125 - initialize - 重排序模型加载失败: We couldn't connect to 'https://huggingface.co' to load this file, couldn't find it in the cached files and it looks like cross-encoder/ms-marco-MiniLM-L-6-v2 is not the path to a directory containing a file named config.json.
Checkout your internet connection or see how to run the library in offline mode at 'https://huggingface.co/docs/transformers/installation#offline-mode'.
2025-08-08 15:06:18 - asyncio - ERROR - base_events.py:1833 - default_exception_handler - Unclosed client session
client_session: <aiohttp.client.ClientSession object at 0x0000021582AE38F0>
2025-08-08 15:06:18 - asyncio - ERROR - base_events.py:1833 - default_exception_handler - Unclosed client session
client_session: <aiohttp.client.ClientSession object at 0x000002158349BA40>
2025-08-08 15:06:18 - asyncio - ERROR - base_events.py:1833 - default_exception_handler - Unclosed client session
client_session: <aiohttp.client.ClientSession object at 0x000002158345D910>
2025-08-08 15:12:13 - rag_system.vector_store.chroma_store - ERROR - chroma_store.py:85 - initialize - Chroma向量数据库初始化失败: Could not connect to tenant default_tenant. Are you sure it exists?
2025-08-08 15:12:13 - rag_system.services.vector_service - ERROR - vector_service.py:42 - initialize - 向量存储服务初始化失败: [VECTOR_STORE_OPERATION_ERROR] Chroma初始化失败: Could not connect to tenant default_tenant. Are you sure it exists?
2025-08-08 15:12:13 - rag_system.services.document_service - ERROR - document_service.py:91 - initialize - 文档管理服务初始化失败: [VECTOR_STORE_OPERATION_ERROR] 向量存储服务初始化失败: [VECTOR_STORE_OPERATION_ERROR] Chroma初始化失败: Could not connect to tenant default_tenant. Are you sure it exists?
2025-08-08 15:12:41 - rag_system.services.model_manager - ERROR - model_manager.py:410 - _load_embedding_model - 加载embedding模型失败: default_embedding, 错误: 1 validation error for EmbeddingConfig
  Value error, 提供商 openai 需要API密钥 [type=value_error, input_value={'provider': 'openai', 'm...s': 8192, 'timeout': 30}, input_type=dict]
    For further information visit https://errors.pydantic.dev/2.11/v/value_error
2025-08-08 15:12:41 - rag_system.services.model_manager - ERROR - model_manager.py:375 - load_model - 模型加载失败: default_embedding
2025-08-08 15:12:44 - rag_system.services.reranking_service - ERROR - reranking_service.py:161 - _load_model - 模型加载失败: We couldn't connect to 'https://huggingface.co' to load this file, couldn't find it in the cached files and it looks like cross-encoder/ms-marco-MiniLM-L-6-v2 is not the path to a directory containing a file named config.json.
Checkout your internet connection or see how to run the library in offline mode at 'https://huggingface.co/docs/transformers/installation#offline-mode'.
2025-08-08 15:12:44 - rag_system.services.reranking_service - ERROR - reranking_service.py:125 - initialize - 重排序模型加载失败: We couldn't connect to 'https://huggingface.co' to load this file, couldn't find it in the cached files and it looks like cross-encoder/ms-marco-MiniLM-L-6-v2 is not the path to a directory containing a file named config.json.
Checkout your internet connection or see how to run the library in offline mode at 'https://huggingface.co/docs/transformers/installation#offline-mode'.
2025-08-08 15:12:44 - rag_system.services.model_manager - ERROR - model_manager.py:410 - _load_embedding_model - 加载embedding模型失败: siliconflow_BAAI_bge_large_zh_v1_5, 错误: 2 validation errors for EmbeddingConfig
chunk_size
  Extra inputs are not permitted [type=extra_forbidden, input_value=1000, input_type=int]
    For further information visit https://errors.pydantic.dev/2.11/v/extra_forbidden
chunk_overlap
  Extra inputs are not permitted [type=extra_forbidden, input_value=50, input_type=int]
    For further information visit https://errors.pydantic.dev/2.11/v/extra_forbidden
2025-08-08 15:12:44 - rag_system.services.model_manager - ERROR - model_manager.py:375 - load_model - 模型加载失败: siliconflow_BAAI_bge_large_zh_v1_5
2025-08-08 15:12:51 - rag_system.vector_store.chroma_store - ERROR - chroma_store.py:85 - initialize - Chroma向量数据库初始化失败: Could not connect to tenant default_tenant. Are you sure it exists?
2025-08-08 15:12:51 - rag_system.services.vector_service - ERROR - vector_service.py:42 - initialize - 向量存储服务初始化失败: [VECTOR_STORE_OPERATION_ERROR] Chroma初始化失败: Could not connect to tenant default_tenant. Are you sure it exists?
2025-08-08 15:12:51 - rag_system.services.document_service - ERROR - document_service.py:91 - initialize - 文档管理服务初始化失败: [VECTOR_STORE_OPERATION_ERROR] 向量存储服务初始化失败: [VECTOR_STORE_OPERATION_ERROR] Chroma初始化失败: Could not connect to tenant default_tenant. Are you sure it exists?
2025-08-08 15:16:28 - rag_system.vector_store.chroma_store - ERROR - chroma_store.py:85 - initialize - Chroma向量数据库初始化失败: Could not connect to tenant default_tenant. Are you sure it exists?
2025-08-08 15:16:28 - rag_system.services.vector_service - ERROR - vector_service.py:42 - initialize - 向量存储服务初始化失败: [VECTOR_STORE_OPERATION_ERROR] Chroma初始化失败: Could not connect to tenant default_tenant. Are you sure it exists?
2025-08-08 15:16:28 - rag_system.services.document_service - ERROR - document_service.py:91 - initialize - 文档管理服务初始化失败: [VECTOR_STORE_OPERATION_ERROR] 向量存储服务初始化失败: [VECTOR_STORE_OPERATION_ERROR] Chroma初始化失败: Could not connect to tenant default_tenant. Are you sure it exists?
2025-08-08 15:16:39 - rag_system.services.model_manager - ERROR - model_manager.py:410 - _load_embedding_model - 加载embedding模型失败: default_embedding, 错误: 1 validation error for EmbeddingConfig
  Value error, 提供商 openai 需要API密钥 [type=value_error, input_value={'provider': 'openai', 'm...s': 8192, 'timeout': 30}, input_type=dict]
    For further information visit https://errors.pydantic.dev/2.11/v/value_error
2025-08-08 15:16:39 - rag_system.services.model_manager - ERROR - model_manager.py:375 - load_model - 模型加载失败: default_embedding
2025-08-08 15:16:41 - rag_system.services.reranking_service - ERROR - reranking_service.py:161 - _load_model - 模型加载失败: We couldn't connect to 'https://huggingface.co' to load this file, couldn't find it in the cached files and it looks like cross-encoder/ms-marco-MiniLM-L-6-v2 is not the path to a directory containing a file named config.json.
Checkout your internet connection or see how to run the library in offline mode at 'https://huggingface.co/docs/transformers/installation#offline-mode'.
2025-08-08 15:16:41 - rag_system.services.reranking_service - ERROR - reranking_service.py:125 - initialize - 重排序模型加载失败: We couldn't connect to 'https://huggingface.co' to load this file, couldn't find it in the cached files and it looks like cross-encoder/ms-marco-MiniLM-L-6-v2 is not the path to a directory containing a file named config.json.
Checkout your internet connection or see how to run the library in offline mode at 'https://huggingface.co/docs/transformers/installation#offline-mode'.
2025-08-08 15:16:41 - rag_system.services.model_manager - ERROR - model_manager.py:410 - _load_embedding_model - 加载embedding模型失败: siliconflow_BAAI_bge_large_zh_v1_5, 错误: 3 validation errors for EmbeddingConfig
dimensions
  Input should be less than or equal to 10000 [type=less_than_equal, input_value=10240, input_type=int]
    For further information visit https://errors.pydantic.dev/2.11/v/less_than_equal
chunk_size
  Extra inputs are not permitted [type=extra_forbidden, input_value=10000, input_type=int]
    For further information visit https://errors.pydantic.dev/2.11/v/extra_forbidden
chunk_overlap
  Extra inputs are not permitted [type=extra_forbidden, input_value=500, input_type=int]
    For further information visit https://errors.pydantic.dev/2.11/v/extra_forbidden
2025-08-08 15:16:41 - rag_system.services.model_manager - ERROR - model_manager.py:375 - load_model - 模型加载失败: siliconflow_BAAI_bge_large_zh_v1_5
2025-08-08 15:17:06 - rag_system.services.model_manager - ERROR - model_manager.py:410 - _load_embedding_model - 加载embedding模型失败: default_embedding, 错误: 1 validation error for EmbeddingConfig
  Value error, 提供商 openai 需要API密钥 [type=value_error, input_value={'provider': 'openai', 'm...s': 8192, 'timeout': 30}, input_type=dict]
    For further information visit https://errors.pydantic.dev/2.11/v/value_error
2025-08-08 15:17:06 - rag_system.services.model_manager - ERROR - model_manager.py:375 - load_model - 模型加载失败: default_embedding
2025-08-08 15:17:06 - rag_system.services.reranking_service - ERROR - reranking_service.py:161 - _load_model - 模型加载失败: We couldn't connect to 'https://huggingface.co' to load this file, couldn't find it in the cached files and it looks like cross-encoder/ms-marco-MiniLM-L-6-v2 is not the path to a directory containing a file named config.json.
Checkout your internet connection or see how to run the library in offline mode at 'https://huggingface.co/docs/transformers/installation#offline-mode'.
2025-08-08 15:17:06 - rag_system.services.reranking_service - ERROR - reranking_service.py:125 - initialize - 重排序模型加载失败: We couldn't connect to 'https://huggingface.co' to load this file, couldn't find it in the cached files and it looks like cross-encoder/ms-marco-MiniLM-L-6-v2 is not the path to a directory containing a file named config.json.
Checkout your internet connection or see how to run the library in offline mode at 'https://huggingface.co/docs/transformers/installation#offline-mode'.
2025-08-08 15:17:06 - rag_system.services.model_manager - ERROR - model_manager.py:410 - _load_embedding_model - 加载embedding模型失败: siliconflow_BAAI_bge_large_zh_v1_5, 错误: 2 validation errors for EmbeddingConfig
chunk_size
  Extra inputs are not permitted [type=extra_forbidden, input_value=1000, input_type=int]
    For further information visit https://errors.pydantic.dev/2.11/v/extra_forbidden
chunk_overlap
  Extra inputs are not permitted [type=extra_forbidden, input_value=50, input_type=int]
    For further information visit https://errors.pydantic.dev/2.11/v/extra_forbidden
2025-08-08 15:17:06 - rag_system.services.model_manager - ERROR - model_manager.py:375 - load_model - 模型加载失败: siliconflow_BAAI_bge_large_zh_v1_5
2025-08-08 15:17:33 - rag_system.services.model_manager - ERROR - model_manager.py:410 - _load_embedding_model - 加载embedding模型失败: default_embedding, 错误: 1 validation error for EmbeddingConfig
  Value error, 提供商 openai 需要API密钥 [type=value_error, input_value={'provider': 'openai', 'm...s': 8192, 'timeout': 30}, input_type=dict]
    For further information visit https://errors.pydantic.dev/2.11/v/value_error
2025-08-08 15:17:33 - rag_system.services.model_manager - ERROR - model_manager.py:375 - load_model - 模型加载失败: default_embedding
2025-08-08 15:17:34 - rag_system.services.reranking_service - ERROR - reranking_service.py:161 - _load_model - 模型加载失败: We couldn't connect to 'https://huggingface.co' to load this file, couldn't find it in the cached files and it looks like cross-encoder/ms-marco-MiniLM-L-6-v2 is not the path to a directory containing a file named config.json.
Checkout your internet connection or see how to run the library in offline mode at 'https://huggingface.co/docs/transformers/installation#offline-mode'.
2025-08-08 15:17:34 - rag_system.services.reranking_service - ERROR - reranking_service.py:125 - initialize - 重排序模型加载失败: We couldn't connect to 'https://huggingface.co' to load this file, couldn't find it in the cached files and it looks like cross-encoder/ms-marco-MiniLM-L-6-v2 is not the path to a directory containing a file named config.json.
Checkout your internet connection or see how to run the library in offline mode at 'https://huggingface.co/docs/transformers/installation#offline-mode'.
2025-08-08 15:23:51 - asyncio - ERROR - base_events.py:1833 - default_exception_handler - Unclosed client session
client_session: <aiohttp.client.ClientSession object at 0x000001F14C588E60>
2025-08-08 15:23:57 - rag_system.vector_store.chroma_store - ERROR - chroma_store.py:85 - initialize - Chroma向量数据库初始化失败: Could not connect to tenant default_tenant. Are you sure it exists?
2025-08-08 15:23:57 - rag_system.services.vector_service - ERROR - vector_service.py:42 - initialize - 向量存储服务初始化失败: [VECTOR_STORE_OPERATION_ERROR] Chroma初始化失败: Could not connect to tenant default_tenant. Are you sure it exists?
2025-08-08 15:23:57 - rag_system.services.document_service - ERROR - document_service.py:91 - initialize - 文档管理服务初始化失败: [VECTOR_STORE_OPERATION_ERROR] 向量存储服务初始化失败: [VECTOR_STORE_OPERATION_ERROR] Chroma初始化失败: Could not connect to tenant default_tenant. Are you sure it exists?
2025-08-08 15:24:29 - rag_system.services.model_manager - ERROR - model_manager.py:410 - _load_embedding_model - 加载embedding模型失败: default_embedding, 错误: 1 validation error for EmbeddingConfig
  Value error, 提供商 openai 需要API密钥 [type=value_error, input_value={'provider': 'openai', 'm...s': 8192, 'timeout': 30}, input_type=dict]
    For further information visit https://errors.pydantic.dev/2.11/v/value_error
2025-08-08 15:24:29 - rag_system.services.model_manager - ERROR - model_manager.py:375 - load_model - 模型加载失败: default_embedding
2025-08-08 15:24:32 - rag_system.services.reranking_service - ERROR - reranking_service.py:161 - _load_model - 模型加载失败: We couldn't connect to 'https://huggingface.co' to load this file, couldn't find it in the cached files and it looks like cross-encoder/ms-marco-MiniLM-L-6-v2 is not the path to a directory containing a file named config.json.
Checkout your internet connection or see how to run the library in offline mode at 'https://huggingface.co/docs/transformers/installation#offline-mode'.
2025-08-08 15:24:32 - rag_system.services.reranking_service - ERROR - reranking_service.py:125 - initialize - 重排序模型加载失败: We couldn't connect to 'https://huggingface.co' to load this file, couldn't find it in the cached files and it looks like cross-encoder/ms-marco-MiniLM-L-6-v2 is not the path to a directory containing a file named config.json.
Checkout your internet connection or see how to run the library in offline mode at 'https://huggingface.co/docs/transformers/installation#offline-mode'.
2025-08-08 15:27:34 - asyncio - ERROR - base_events.py:1833 - default_exception_handler - Unclosed client session
client_session: <aiohttp.client.ClientSession object at 0x00000243FE84F0B0>
2025-08-08 15:29:31 - rag_system.vector_store.chroma_store - ERROR - chroma_store.py:85 - initialize - Chroma向量数据库初始化失败: Could not connect to tenant default_tenant. Are you sure it exists?
2025-08-08 15:29:32 - rag_system.services.vector_service - ERROR - vector_service.py:42 - initialize - 向量存储服务初始化失败: [VECTOR_STORE_OPERATION_ERROR] Chroma初始化失败: Could not connect to tenant default_tenant. Are you sure it exists?
2025-08-08 15:29:32 - rag_system.services.document_service - ERROR - document_service.py:91 - initialize - 文档管理服务初始化失败: [VECTOR_STORE_OPERATION_ERROR] 向量存储服务初始化失败: [VECTOR_STORE_OPERATION_ERROR] Chroma初始化失败: Could not connect to tenant default_tenant. Are you sure it exists?
2025-08-08 15:33:18 - rag_system.services.model_manager - ERROR - model_manager.py:410 - _load_embedding_model - 加载embedding模型失败: default_embedding, 错误: 1 validation error for EmbeddingConfig
  Value error, 提供商 openai 需要API密钥 [type=value_error, input_value={'provider': 'openai', 'm...s': 8192, 'timeout': 30}, input_type=dict]
    For further information visit https://errors.pydantic.dev/2.11/v/value_error
2025-08-08 15:33:18 - rag_system.services.model_manager - ERROR - model_manager.py:375 - load_model - 模型加载失败: default_embedding
2025-08-08 15:33:21 - rag_system.services.reranking_service - ERROR - reranking_service.py:161 - _load_model - 模型加载失败: We couldn't connect to 'https://huggingface.co' to load this file, couldn't find it in the cached files and it looks like cross-encoder/ms-marco-MiniLM-L-6-v2 is not the path to a directory containing a file named config.json.
Checkout your internet connection or see how to run the library in offline mode at 'https://huggingface.co/docs/transformers/installation#offline-mode'.
2025-08-08 15:33:21 - rag_system.services.reranking_service - ERROR - reranking_service.py:125 - initialize - 重排序模型加载失败: We couldn't connect to 'https://huggingface.co' to load this file, couldn't find it in the cached files and it looks like cross-encoder/ms-marco-MiniLM-L-6-v2 is not the path to a directory containing a file named config.json.
Checkout your internet connection or see how to run the library in offline mode at 'https://huggingface.co/docs/transformers/installation#offline-mode'.
2025-08-08 15:35:37 - rag_system.vector_store.chroma_store - ERROR - chroma_store.py:85 - initialize - Chroma向量数据库初始化失败: Could not connect to tenant default_tenant. Are you sure it exists?
2025-08-08 15:35:37 - rag_system.services.vector_service - ERROR - vector_service.py:42 - initialize - 向量存储服务初始化失败: [VECTOR_STORE_OPERATION_ERROR] Chroma初始化失败: Could not connect to tenant default_tenant. Are you sure it exists?
2025-08-08 15:35:37 - rag_system.services.document_service - ERROR - document_service.py:91 - initialize - 文档管理服务初始化失败: [VECTOR_STORE_OPERATION_ERROR] 向量存储服务初始化失败: [VECTOR_STORE_OPERATION_ERROR] Chroma初始化失败: Could not connect to tenant default_tenant. Are you sure it exists?
2025-08-08 15:35:54 - rag_system.services.model_manager - ERROR - model_manager.py:410 - _load_embedding_model - 加载embedding模型失败: default_embedding, 错误: 1 validation error for EmbeddingConfig
  Value error, 提供商 openai 需要API密钥 [type=value_error, input_value={'provider': 'openai', 'm...s': 8192, 'timeout': 30}, input_type=dict]
    For further information visit https://errors.pydantic.dev/2.11/v/value_error
2025-08-08 15:35:54 - rag_system.services.model_manager - ERROR - model_manager.py:375 - load_model - 模型加载失败: default_embedding
2025-08-08 15:35:54 - rag_system.services.reranking_service - ERROR - reranking_service.py:161 - _load_model - 模型加载失败: We couldn't connect to 'https://huggingface.co' to load this file, couldn't find it in the cached files and it looks like cross-encoder/ms-marco-MiniLM-L-6-v2 is not the path to a directory containing a file named config.json.
Checkout your internet connection or see how to run the library in offline mode at 'https://huggingface.co/docs/transformers/installation#offline-mode'.
2025-08-08 15:35:54 - rag_system.services.reranking_service - ERROR - reranking_service.py:125 - initialize - 重排序模型加载失败: We couldn't connect to 'https://huggingface.co' to load this file, couldn't find it in the cached files and it looks like cross-encoder/ms-marco-MiniLM-L-6-v2 is not the path to a directory containing a file named config.json.
Checkout your internet connection or see how to run the library in offline mode at 'https://huggingface.co/docs/transformers/installation#offline-mode'.
2025-08-08 15:36:34 - rag_system.services.model_manager - ERROR - model_manager.py:410 - _load_embedding_model - 加载embedding模型失败: default_embedding, 错误: 1 validation error for EmbeddingConfig
  Value error, 提供商 openai 需要API密钥 [type=value_error, input_value={'provider': 'openai', 'm...s': 8192, 'timeout': 30}, input_type=dict]
    For further information visit https://errors.pydantic.dev/2.11/v/value_error
2025-08-08 15:36:34 - rag_system.services.model_manager - ERROR - model_manager.py:375 - load_model - 模型加载失败: default_embedding
2025-08-08 15:36:35 - rag_system.services.reranking_service - ERROR - reranking_service.py:161 - _load_model - 模型加载失败: We couldn't connect to 'https://huggingface.co' to load this file, couldn't find it in the cached files and it looks like cross-encoder/ms-marco-MiniLM-L-6-v2 is not the path to a directory containing a file named config.json.
Checkout your internet connection or see how to run the library in offline mode at 'https://huggingface.co/docs/transformers/installation#offline-mode'.
2025-08-08 15:36:35 - rag_system.services.reranking_service - ERROR - reranking_service.py:125 - initialize - 重排序模型加载失败: We couldn't connect to 'https://huggingface.co' to load this file, couldn't find it in the cached files and it looks like cross-encoder/ms-marco-MiniLM-L-6-v2 is not the path to a directory containing a file named config.json.
Checkout your internet connection or see how to run the library in offline mode at 'https://huggingface.co/docs/transformers/installation#offline-mode'.
2025-08-08 15:36:43 - rag_system.services.model_manager - ERROR - model_manager.py:410 - _load_embedding_model - 加载embedding模型失败: default_embedding, 错误: 1 validation error for EmbeddingConfig
  Value error, 提供商 openai 需要API密钥 [type=value_error, input_value={'provider': 'openai', 'm...s': 8192, 'timeout': 30}, input_type=dict]
    For further information visit https://errors.pydantic.dev/2.11/v/value_error
2025-08-08 15:36:43 - rag_system.services.model_manager - ERROR - model_manager.py:375 - load_model - 模型加载失败: default_embedding
2025-08-08 15:36:44 - rag_system.services.reranking_service - ERROR - reranking_service.py:161 - _load_model - 模型加载失败: We couldn't connect to 'https://huggingface.co' to load this file, couldn't find it in the cached files and it looks like cross-encoder/ms-marco-MiniLM-L-6-v2 is not the path to a directory containing a file named config.json.
Checkout your internet connection or see how to run the library in offline mode at 'https://huggingface.co/docs/transformers/installation#offline-mode'.
2025-08-08 15:36:44 - rag_system.services.reranking_service - ERROR - reranking_service.py:125 - initialize - 重排序模型加载失败: We couldn't connect to 'https://huggingface.co' to load this file, couldn't find it in the cached files and it looks like cross-encoder/ms-marco-MiniLM-L-6-v2 is not the path to a directory containing a file named config.json.
Checkout your internet connection or see how to run the library in offline mode at 'https://huggingface.co/docs/transformers/installation#offline-mode'.
2025-08-08 15:38:36 - rag_system.services.model_manager - ERROR - model_manager.py:410 - _load_embedding_model - 加载embedding模型失败: default_embedding, 错误: 1 validation error for EmbeddingConfig
  Value error, 提供商 openai 需要API密钥 [type=value_error, input_value={'provider': 'openai', 'm...s': 8192, 'timeout': 30}, input_type=dict]
    For further information visit https://errors.pydantic.dev/2.11/v/value_error
2025-08-08 15:38:36 - rag_system.services.model_manager - ERROR - model_manager.py:375 - load_model - 模型加载失败: default_embedding
2025-08-08 15:38:37 - rag_system.services.reranking_service - ERROR - reranking_service.py:161 - _load_model - 模型加载失败: We couldn't connect to 'https://huggingface.co' to load this file, couldn't find it in the cached files and it looks like cross-encoder/ms-marco-MiniLM-L-6-v2 is not the path to a directory containing a file named config.json.
Checkout your internet connection or see how to run the library in offline mode at 'https://huggingface.co/docs/transformers/installation#offline-mode'.
2025-08-08 15:38:37 - rag_system.services.reranking_service - ERROR - reranking_service.py:125 - initialize - 重排序模型加载失败: We couldn't connect to 'https://huggingface.co' to load this file, couldn't find it in the cached files and it looks like cross-encoder/ms-marco-MiniLM-L-6-v2 is not the path to a directory containing a file named config.json.
Checkout your internet connection or see how to run the library in offline mode at 'https://huggingface.co/docs/transformers/installation#offline-mode'.
2025-08-08 15:38:45 - rag_system.services.model_manager - ERROR - model_manager.py:410 - _load_embedding_model - 加载embedding模型失败: default_embedding, 错误: 1 validation error for EmbeddingConfig
  Value error, 提供商 openai 需要API密钥 [type=value_error, input_value={'provider': 'openai', 'm...s': 8192, 'timeout': 30}, input_type=dict]
    For further information visit https://errors.pydantic.dev/2.11/v/value_error
2025-08-08 15:38:45 - rag_system.services.model_manager - ERROR - model_manager.py:375 - load_model - 模型加载失败: default_embedding
2025-08-08 15:38:46 - rag_system.services.reranking_service - ERROR - reranking_service.py:161 - _load_model - 模型加载失败: We couldn't connect to 'https://huggingface.co' to load this file, couldn't find it in the cached files and it looks like cross-encoder/ms-marco-MiniLM-L-6-v2 is not the path to a directory containing a file named config.json.
Checkout your internet connection or see how to run the library in offline mode at 'https://huggingface.co/docs/transformers/installation#offline-mode'.
2025-08-08 15:38:46 - rag_system.services.reranking_service - ERROR - reranking_service.py:125 - initialize - 重排序模型加载失败: We couldn't connect to 'https://huggingface.co' to load this file, couldn't find it in the cached files and it looks like cross-encoder/ms-marco-MiniLM-L-6-v2 is not the path to a directory containing a file named config.json.
Checkout your internet connection or see how to run the library in offline mode at 'https://huggingface.co/docs/transformers/installation#offline-mode'.
2025-08-08 15:38:52 - rag_system.services.model_manager - ERROR - model_manager.py:410 - _load_embedding_model - 加载embedding模型失败: default_embedding, 错误: 1 validation error for EmbeddingConfig
  Value error, 提供商 openai 需要API密钥 [type=value_error, input_value={'provider': 'openai', 'm...s': 8192, 'timeout': 30}, input_type=dict]
    For further information visit https://errors.pydantic.dev/2.11/v/value_error
2025-08-08 15:38:52 - rag_system.services.model_manager - ERROR - model_manager.py:375 - load_model - 模型加载失败: default_embedding
2025-08-08 15:38:53 - rag_system.services.reranking_service - ERROR - reranking_service.py:161 - _load_model - 模型加载失败: We couldn't connect to 'https://huggingface.co' to load this file, couldn't find it in the cached files and it looks like cross-encoder/ms-marco-MiniLM-L-6-v2 is not the path to a directory containing a file named config.json.
Checkout your internet connection or see how to run the library in offline mode at 'https://huggingface.co/docs/transformers/installation#offline-mode'.
2025-08-08 15:38:53 - rag_system.services.reranking_service - ERROR - reranking_service.py:125 - initialize - 重排序模型加载失败: We couldn't connect to 'https://huggingface.co' to load this file, couldn't find it in the cached files and it looks like cross-encoder/ms-marco-MiniLM-L-6-v2 is not the path to a directory containing a file named config.json.
Checkout your internet connection or see how to run the library in offline mode at 'https://huggingface.co/docs/transformers/installation#offline-mode'.
2025-08-08 15:42:47 - rag_system.services.model_manager - ERROR - model_manager.py:410 - _load_embedding_model - 加载embedding模型失败: default_embedding, 错误: 1 validation error for EmbeddingConfig
  Value error, 提供商 openai 需要API密钥 [type=value_error, input_value={'provider': 'openai', 'm...s': 8192, 'timeout': 30}, input_type=dict]
    For further information visit https://errors.pydantic.dev/2.11/v/value_error
2025-08-08 15:42:47 - rag_system.services.model_manager - ERROR - model_manager.py:375 - load_model - 模型加载失败: default_embedding
2025-08-08 15:42:48 - rag_system.services.reranking_service - ERROR - reranking_service.py:161 - _load_model - 模型加载失败: We couldn't connect to 'https://huggingface.co' to load this file, couldn't find it in the cached files and it looks like cross-encoder/ms-marco-MiniLM-L-6-v2 is not the path to a directory containing a file named config.json.
Checkout your internet connection or see how to run the library in offline mode at 'https://huggingface.co/docs/transformers/installation#offline-mode'.
2025-08-08 15:42:48 - rag_system.services.reranking_service - ERROR - reranking_service.py:125 - initialize - 重排序模型加载失败: We couldn't connect to 'https://huggingface.co' to load this file, couldn't find it in the cached files and it looks like cross-encoder/ms-marco-MiniLM-L-6-v2 is not the path to a directory containing a file named config.json.
Checkout your internet connection or see how to run the library in offline mode at 'https://huggingface.co/docs/transformers/installation#offline-mode'.
2025-08-08 15:42:48 - asyncio - ERROR - base_events.py:1833 - default_exception_handler - Unclosed client session
client_session: <aiohttp.client.ClientSession object at 0x0000016794F4CBF0>
2025-08-08 15:42:48 - asyncio - ERROR - base_events.py:1833 - default_exception_handler - Unclosed client session
client_session: <aiohttp.client.ClientSession object at 0x00000167BA346990>
2025-08-08 15:42:48 - asyncio - ERROR - base_events.py:1833 - default_exception_handler - Unclosed client session
client_session: <aiohttp.client.ClientSession object at 0x00000167B9AFEF30>
2025-08-08 15:42:48 - asyncio - ERROR - base_events.py:1833 - default_exception_handler - Unclosed client session
client_session: <aiohttp.client.ClientSession object at 0x00000167BA5150D0>
2025-08-08 15:42:53 - rag_system.services.model_manager - ERROR - model_manager.py:410 - _load_embedding_model - 加载embedding模型失败: default_embedding, 错误: 1 validation error for EmbeddingConfig
  Value error, 提供商 openai 需要API密钥 [type=value_error, input_value={'provider': 'openai', 'm...s': 8192, 'timeout': 30}, input_type=dict]
    For further information visit https://errors.pydantic.dev/2.11/v/value_error
2025-08-08 15:42:53 - rag_system.services.model_manager - ERROR - model_manager.py:375 - load_model - 模型加载失败: default_embedding
2025-08-08 15:42:56 - rag_system.services.reranking_service - ERROR - reranking_service.py:161 - _load_model - 模型加载失败: We couldn't connect to 'https://huggingface.co' to load this file, couldn't find it in the cached files and it looks like cross-encoder/ms-marco-MiniLM-L-6-v2 is not the path to a directory containing a file named config.json.
Checkout your internet connection or see how to run the library in offline mode at 'https://huggingface.co/docs/transformers/installation#offline-mode'.
2025-08-08 15:42:56 - rag_system.services.reranking_service - ERROR - reranking_service.py:125 - initialize - 重排序模型加载失败: We couldn't connect to 'https://huggingface.co' to load this file, couldn't find it in the cached files and it looks like cross-encoder/ms-marco-MiniLM-L-6-v2 is not the path to a directory containing a file named config.json.
Checkout your internet connection or see how to run the library in offline mode at 'https://huggingface.co/docs/transformers/installation#offline-mode'.
2025-08-08 15:42:58 - rag_system.services.model_manager - ERROR - model_manager.py:410 - _load_embedding_model - 加载embedding模型失败: default_embedding, 错误: 1 validation error for EmbeddingConfig
  Value error, 提供商 openai 需要API密钥 [type=value_error, input_value={'provider': 'openai', 'm...s': 8192, 'timeout': 30}, input_type=dict]
    For further information visit https://errors.pydantic.dev/2.11/v/value_error
2025-08-08 15:42:58 - rag_system.services.model_manager - ERROR - model_manager.py:375 - load_model - 模型加载失败: default_embedding
2025-08-08 15:42:58 - rag_system.services.reranking_service - ERROR - reranking_service.py:161 - _load_model - 模型加载失败: We couldn't connect to 'https://huggingface.co' to load this file, couldn't find it in the cached files and it looks like cross-encoder/ms-marco-MiniLM-L-6-v2 is not the path to a directory containing a file named config.json.
Checkout your internet connection or see how to run the library in offline mode at 'https://huggingface.co/docs/transformers/installation#offline-mode'.
2025-08-08 15:42:58 - rag_system.services.reranking_service - ERROR - reranking_service.py:125 - initialize - 重排序模型加载失败: We couldn't connect to 'https://huggingface.co' to load this file, couldn't find it in the cached files and it looks like cross-encoder/ms-marco-MiniLM-L-6-v2 is not the path to a directory containing a file named config.json.
Checkout your internet connection or see how to run the library in offline mode at 'https://huggingface.co/docs/transformers/installation#offline-mode'.
2025-08-08 15:42:58 - rag_system.services.model_manager - ERROR - model_manager.py:603 - test_model - 测试模型失败 invalid_type/test-model: 'invalid_type' is not a valid ModelType
2025-08-08 15:46:04 - rag_system.vector_store.chroma_store - ERROR - chroma_store.py:85 - initialize - Chroma向量数据库初始化失败: Could not connect to tenant default_tenant. Are you sure it exists?
2025-08-08 15:46:04 - rag_system.services.vector_service - ERROR - vector_service.py:42 - initialize - 向量存储服务初始化失败: [VECTOR_STORE_OPERATION_ERROR] Chroma初始化失败: Could not connect to tenant default_tenant. Are you sure it exists?
2025-08-08 15:46:04 - rag_system.services.document_service - ERROR - document_service.py:91 - initialize - 文档管理服务初始化失败: [VECTOR_STORE_OPERATION_ERROR] 向量存储服务初始化失败: [VECTOR_STORE_OPERATION_ERROR] Chroma初始化失败: Could not connect to tenant default_tenant. Are you sure it exists?
2025-08-08 15:46:19 - rag_system.services.model_manager - ERROR - model_manager.py:410 - _load_embedding_model - 加载embedding模型失败: default_embedding, 错误: 1 validation error for EmbeddingConfig
  Value error, 提供商 openai 需要API密钥 [type=value_error, input_value={'provider': 'openai', 'm...s': 8192, 'timeout': 30}, input_type=dict]
    For further information visit https://errors.pydantic.dev/2.11/v/value_error
2025-08-08 15:46:19 - rag_system.services.model_manager - ERROR - model_manager.py:375 - load_model - 模型加载失败: default_embedding
2025-08-08 15:46:19 - rag_system.services.reranking_service - ERROR - reranking_service.py:161 - _load_model - 模型加载失败: We couldn't connect to 'https://huggingface.co' to load this file, couldn't find it in the cached files and it looks like cross-encoder/ms-marco-MiniLM-L-6-v2 is not the path to a directory containing a file named config.json.
Checkout your internet connection or see how to run the library in offline mode at 'https://huggingface.co/docs/transformers/installation#offline-mode'.
2025-08-08 15:46:19 - rag_system.services.reranking_service - ERROR - reranking_service.py:125 - initialize - 重排序模型加载失败: We couldn't connect to 'https://huggingface.co' to load this file, couldn't find it in the cached files and it looks like cross-encoder/ms-marco-MiniLM-L-6-v2 is not the path to a directory containing a file named config.json.
Checkout your internet connection or see how to run the library in offline mode at 'https://huggingface.co/docs/transformers/installation#offline-mode'.
2025-08-08 15:46:54 - rag_system.services.model_manager - ERROR - model_manager.py:410 - _load_embedding_model - 加载embedding模型失败: default_embedding, 错误: 1 validation error for EmbeddingConfig
  Value error, 提供商 openai 需要API密钥 [type=value_error, input_value={'provider': 'openai', 'm...s': 8192, 'timeout': 30}, input_type=dict]
    For further information visit https://errors.pydantic.dev/2.11/v/value_error
2025-08-08 15:46:54 - rag_system.services.model_manager - ERROR - model_manager.py:375 - load_model - 模型加载失败: default_embedding
2025-08-08 15:46:55 - rag_system.services.reranking_service - ERROR - reranking_service.py:161 - _load_model - 模型加载失败: We couldn't connect to 'https://huggingface.co' to load this file, couldn't find it in the cached files and it looks like cross-encoder/ms-marco-MiniLM-L-6-v2 is not the path to a directory containing a file named config.json.
Checkout your internet connection or see how to run the library in offline mode at 'https://huggingface.co/docs/transformers/installation#offline-mode'.
2025-08-08 15:46:55 - rag_system.services.reranking_service - ERROR - reranking_service.py:125 - initialize - 重排序模型加载失败: We couldn't connect to 'https://huggingface.co' to load this file, couldn't find it in the cached files and it looks like cross-encoder/ms-marco-MiniLM-L-6-v2 is not the path to a directory containing a file named config.json.
Checkout your internet connection or see how to run the library in offline mode at 'https://huggingface.co/docs/transformers/installation#offline-mode'.
2025-08-08 15:47:56 - rag_system.services.model_manager - ERROR - model_manager.py:410 - _load_embedding_model - 加载embedding模型失败: default_embedding, 错误: 1 validation error for EmbeddingConfig
  Value error, 提供商 openai 需要API密钥 [type=value_error, input_value={'provider': 'openai', 'm...s': 8192, 'timeout': 30}, input_type=dict]
    For further information visit https://errors.pydantic.dev/2.11/v/value_error
2025-08-08 15:47:56 - rag_system.services.model_manager - ERROR - model_manager.py:375 - load_model - 模型加载失败: default_embedding
2025-08-08 15:47:57 - rag_system.services.reranking_service - ERROR - reranking_service.py:161 - _load_model - 模型加载失败: We couldn't connect to 'https://huggingface.co' to load this file, couldn't find it in the cached files and it looks like cross-encoder/ms-marco-MiniLM-L-6-v2 is not the path to a directory containing a file named config.json.
Checkout your internet connection or see how to run the library in offline mode at 'https://huggingface.co/docs/transformers/installation#offline-mode'.
2025-08-08 15:47:57 - rag_system.services.reranking_service - ERROR - reranking_service.py:125 - initialize - 重排序模型加载失败: We couldn't connect to 'https://huggingface.co' to load this file, couldn't find it in the cached files and it looks like cross-encoder/ms-marco-MiniLM-L-6-v2 is not the path to a directory containing a file named config.json.
Checkout your internet connection or see how to run the library in offline mode at 'https://huggingface.co/docs/transformers/installation#offline-mode'.
2025-08-08 15:47:59 - rag_system.services.model_manager - ERROR - model_manager.py:410 - _load_embedding_model - 加载embedding模型失败: default_embedding, 错误: 1 validation error for EmbeddingConfig
  Value error, 提供商 openai 需要API密钥 [type=value_error, input_value={'provider': 'openai', 'm...s': 8192, 'timeout': 30}, input_type=dict]
    For further information visit https://errors.pydantic.dev/2.11/v/value_error
2025-08-08 15:47:59 - rag_system.services.model_manager - ERROR - model_manager.py:375 - load_model - 模型加载失败: default_embedding
2025-08-08 15:47:59 - rag_system.services.reranking_service - ERROR - reranking_service.py:161 - _load_model - 模型加载失败: We couldn't connect to 'https://huggingface.co' to load this file, couldn't find it in the cached files and it looks like cross-encoder/ms-marco-MiniLM-L-6-v2 is not the path to a directory containing a file named config.json.
Checkout your internet connection or see how to run the library in offline mode at 'https://huggingface.co/docs/transformers/installation#offline-mode'.
2025-08-08 15:47:59 - rag_system.services.reranking_service - ERROR - reranking_service.py:125 - initialize - 重排序模型加载失败: We couldn't connect to 'https://huggingface.co' to load this file, couldn't find it in the cached files and it looks like cross-encoder/ms-marco-MiniLM-L-6-v2 is not the path to a directory containing a file named config.json.
Checkout your internet connection or see how to run the library in offline mode at 'https://huggingface.co/docs/transformers/installation#offline-mode'.
2025-08-08 15:48:01 - rag_system.services.model_manager - ERROR - model_manager.py:410 - _load_embedding_model - 加载embedding模型失败: default_embedding, 错误: 1 validation error for EmbeddingConfig
  Value error, 提供商 openai 需要API密钥 [type=value_error, input_value={'provider': 'openai', 'm...s': 8192, 'timeout': 30}, input_type=dict]
    For further information visit https://errors.pydantic.dev/2.11/v/value_error
2025-08-08 15:48:01 - rag_system.services.model_manager - ERROR - model_manager.py:375 - load_model - 模型加载失败: default_embedding
2025-08-08 15:48:01 - rag_system.services.reranking_service - ERROR - reranking_service.py:161 - _load_model - 模型加载失败: We couldn't connect to 'https://huggingface.co' to load this file, couldn't find it in the cached files and it looks like cross-encoder/ms-marco-MiniLM-L-6-v2 is not the path to a directory containing a file named config.json.
Checkout your internet connection or see how to run the library in offline mode at 'https://huggingface.co/docs/transformers/installation#offline-mode'.
2025-08-08 15:48:01 - rag_system.services.reranking_service - ERROR - reranking_service.py:125 - initialize - 重排序模型加载失败: We couldn't connect to 'https://huggingface.co' to load this file, couldn't find it in the cached files and it looks like cross-encoder/ms-marco-MiniLM-L-6-v2 is not the path to a directory containing a file named config.json.
Checkout your internet connection or see how to run the library in offline mode at 'https://huggingface.co/docs/transformers/installation#offline-mode'.
2025-08-08 15:48:01 - rag_system.services.model_manager - ERROR - model_manager.py:410 - _load_embedding_model - 加载embedding模型失败: default_embedding, 错误: 1 validation error for EmbeddingConfig
  Value error, 提供商 openai 需要API密钥 [type=value_error, input_value={'provider': 'openai', 'm...s': 8192, 'timeout': 30}, input_type=dict]
    For further information visit https://errors.pydantic.dev/2.11/v/value_error
2025-08-08 15:48:01 - rag_system.services.model_manager - ERROR - model_manager.py:375 - load_model - 模型加载失败: default_embedding
2025-08-08 15:48:02 - rag_system.services.reranking_service - ERROR - reranking_service.py:161 - _load_model - 模型加载失败: We couldn't connect to 'https://huggingface.co' to load this file, couldn't find it in the cached files and it looks like cross-encoder/ms-marco-MiniLM-L-6-v2 is not the path to a directory containing a file named config.json.
Checkout your internet connection or see how to run the library in offline mode at 'https://huggingface.co/docs/transformers/installation#offline-mode'.
2025-08-08 15:48:02 - rag_system.services.reranking_service - ERROR - reranking_service.py:125 - initialize - 重排序模型加载失败: We couldn't connect to 'https://huggingface.co' to load this file, couldn't find it in the cached files and it looks like cross-encoder/ms-marco-MiniLM-L-6-v2 is not the path to a directory containing a file named config.json.
Checkout your internet connection or see how to run the library in offline mode at 'https://huggingface.co/docs/transformers/installation#offline-mode'.
2025-08-08 15:48:02 - rag_system.services.model_manager - ERROR - model_manager.py:410 - _load_embedding_model - 加载embedding模型失败: default_embedding, 错误: 1 validation error for EmbeddingConfig
  Value error, 提供商 openai 需要API密钥 [type=value_error, input_value={'provider': 'openai', 'm...s': 8192, 'timeout': 30}, input_type=dict]
    For further information visit https://errors.pydantic.dev/2.11/v/value_error
2025-08-08 15:48:02 - rag_system.services.model_manager - ERROR - model_manager.py:375 - load_model - 模型加载失败: default_embedding
2025-08-08 15:48:02 - rag_system.services.reranking_service - ERROR - reranking_service.py:161 - _load_model - 模型加载失败: We couldn't connect to 'https://huggingface.co' to load this file, couldn't find it in the cached files and it looks like cross-encoder/ms-marco-MiniLM-L-6-v2 is not the path to a directory containing a file named config.json.
Checkout your internet connection or see how to run the library in offline mode at 'https://huggingface.co/docs/transformers/installation#offline-mode'.
2025-08-08 15:48:02 - rag_system.services.reranking_service - ERROR - reranking_service.py:125 - initialize - 重排序模型加载失败: We couldn't connect to 'https://huggingface.co' to load this file, couldn't find it in the cached files and it looks like cross-encoder/ms-marco-MiniLM-L-6-v2 is not the path to a directory containing a file named config.json.
Checkout your internet connection or see how to run the library in offline mode at 'https://huggingface.co/docs/transformers/installation#offline-mode'.
2025-08-08 15:48:02 - rag_system.services.model_manager - ERROR - model_manager.py:603 - test_model - 测试模型失败 invalid/test-model: 'invalid' is not a valid ModelType
2025-08-08 15:51:40 - rag_system.services.model_manager - ERROR - model_manager.py:410 - _load_embedding_model - 加载embedding模型失败: default_embedding, 错误: 1 validation error for EmbeddingConfig
  Value error, 提供商 openai 需要API密钥 [type=value_error, input_value={'provider': 'openai', 'm...s': 8192, 'timeout': 30}, input_type=dict]
    For further information visit https://errors.pydantic.dev/2.11/v/value_error
2025-08-08 15:51:40 - rag_system.services.model_manager - ERROR - model_manager.py:375 - load_model - 模型加载失败: default_embedding
2025-08-08 15:51:41 - rag_system.services.reranking_service - ERROR - reranking_service.py:161 - _load_model - 模型加载失败: We couldn't connect to 'https://huggingface.co' to load this file, couldn't find it in the cached files and it looks like cross-encoder/ms-marco-MiniLM-L-6-v2 is not the path to a directory containing a file named config.json.
Checkout your internet connection or see how to run the library in offline mode at 'https://huggingface.co/docs/transformers/installation#offline-mode'.
2025-08-08 15:51:41 - rag_system.services.reranking_service - ERROR - reranking_service.py:125 - initialize - 重排序模型加载失败: We couldn't connect to 'https://huggingface.co' to load this file, couldn't find it in the cached files and it looks like cross-encoder/ms-marco-MiniLM-L-6-v2 is not the path to a directory containing a file named config.json.
Checkout your internet connection or see how to run the library in offline mode at 'https://huggingface.co/docs/transformers/installation#offline-mode'.
2025-08-08 15:54:20 - rag_system.services.reranking_service - ERROR - reranking_service.py:161 - _load_model - 模型加载失败: We couldn't connect to 'https://huggingface.co' to load this file, couldn't find it in the cached files and it looks like cross-encoder/ms-marco-MiniLM-L-6-v2 is not the path to a directory containing a file named config.json.
Checkout your internet connection or see how to run the library in offline mode at 'https://huggingface.co/docs/transformers/installation#offline-mode'.
2025-08-08 15:54:20 - rag_system.services.reranking_service - ERROR - reranking_service.py:125 - initialize - 重排序模型加载失败: We couldn't connect to 'https://huggingface.co' to load this file, couldn't find it in the cached files and it looks like cross-encoder/ms-marco-MiniLM-L-6-v2 is not the path to a directory containing a file named config.json.
Checkout your internet connection or see how to run the library in offline mode at 'https://huggingface.co/docs/transformers/installation#offline-mode'.
2025-08-09 09:15:45 - rag_system.services.model_manager - ERROR - model_manager.py:410 - _load_embedding_model - 加载embedding模型失败: default_embedding, 错误: 1 validation error for EmbeddingConfig
  Value error, 提供商 openai 需要API密钥 [type=value_error, input_value={'provider': 'openai', 'm...s': 8192, 'timeout': 30}, input_type=dict]
    For further information visit https://errors.pydantic.dev/2.11/v/value_error
2025-08-09 09:15:45 - rag_system.services.model_manager - ERROR - model_manager.py:375 - load_model - 模型加载失败: default_embedding
2025-08-09 09:15:49 - rag_system.services.reranking_service - ERROR - reranking_service.py:161 - _load_model - 模型加载失败: We couldn't connect to 'https://huggingface.co' to load this file, couldn't find it in the cached files and it looks like cross-encoder/ms-marco-MiniLM-L-6-v2 is not the path to a directory containing a file named config.json.
Checkout your internet connection or see how to run the library in offline mode at 'https://huggingface.co/docs/transformers/installation#offline-mode'.
2025-08-09 09:15:49 - rag_system.services.reranking_service - ERROR - reranking_service.py:125 - initialize - 重排序模型加载失败: We couldn't connect to 'https://huggingface.co' to load this file, couldn't find it in the cached files and it looks like cross-encoder/ms-marco-MiniLM-L-6-v2 is not the path to a directory containing a file named config.json.
Checkout your internet connection or see how to run the library in offline mode at 'https://huggingface.co/docs/transformers/installation#offline-mode'.
2025-08-09 09:15:49 - rag_system.services.model_manager - ERROR - model_manager.py:410 - _load_embedding_model - 加载embedding模型失败: test_embedding_debug, 错误: rag_system.embeddings.base.EmbeddingConfig() got multiple values for keyword argument 'provider'
2025-08-09 09:15:49 - rag_system.services.model_manager - ERROR - model_manager.py:375 - load_model - 模型加载失败: test_embedding_debug
2025-08-09 09:15:51 - rag_system.services.model_manager - ERROR - model_manager.py:410 - _load_embedding_model - 加载embedding模型失败: default_embedding, 错误: 1 validation error for EmbeddingConfig
  Value error, 提供商 openai 需要API密钥 [type=value_error, input_value={'provider': 'openai', 'm...s': 8192, 'timeout': 30}, input_type=dict]
    For further information visit https://errors.pydantic.dev/2.11/v/value_error
2025-08-09 09:15:51 - rag_system.services.model_manager - ERROR - model_manager.py:375 - load_model - 模型加载失败: default_embedding
2025-08-09 09:15:52 - rag_system.services.reranking_service - ERROR - reranking_service.py:161 - _load_model - 模型加载失败: We couldn't connect to 'https://huggingface.co' to load this file, couldn't find it in the cached files and it looks like cross-encoder/ms-marco-MiniLM-L-6-v2 is not the path to a directory containing a file named config.json.
Checkout your internet connection or see how to run the library in offline mode at 'https://huggingface.co/docs/transformers/installation#offline-mode'.
2025-08-09 09:15:52 - rag_system.services.reranking_service - ERROR - reranking_service.py:125 - initialize - 重排序模型加载失败: We couldn't connect to 'https://huggingface.co' to load this file, couldn't find it in the cached files and it looks like cross-encoder/ms-marco-MiniLM-L-6-v2 is not the path to a directory containing a file named config.json.
Checkout your internet connection or see how to run the library in offline mode at 'https://huggingface.co/docs/transformers/installation#offline-mode'.
2025-08-09 09:15:54 - rag_system.services.model_manager - ERROR - model_manager.py:410 - _load_embedding_model - 加载embedding模型失败: default_embedding, 错误: 1 validation error for EmbeddingConfig
  Value error, 提供商 openai 需要API密钥 [type=value_error, input_value={'provider': 'openai', 'm...s': 8192, 'timeout': 30}, input_type=dict]
    For further information visit https://errors.pydantic.dev/2.11/v/value_error
2025-08-09 09:15:54 - rag_system.services.model_manager - ERROR - model_manager.py:375 - load_model - 模型加载失败: default_embedding
2025-08-09 09:15:55 - rag_system.services.reranking_service - ERROR - reranking_service.py:161 - _load_model - 模型加载失败: We couldn't connect to 'https://huggingface.co' to load this file, couldn't find it in the cached files and it looks like cross-encoder/ms-marco-MiniLM-L-6-v2 is not the path to a directory containing a file named config.json.
Checkout your internet connection or see how to run the library in offline mode at 'https://huggingface.co/docs/transformers/installation#offline-mode'.
2025-08-09 09:15:55 - rag_system.services.reranking_service - ERROR - reranking_service.py:125 - initialize - 重排序模型加载失败: We couldn't connect to 'https://huggingface.co' to load this file, couldn't find it in the cached files and it looks like cross-encoder/ms-marco-MiniLM-L-6-v2 is not the path to a directory containing a file named config.json.
Checkout your internet connection or see how to run the library in offline mode at 'https://huggingface.co/docs/transformers/installation#offline-mode'.
2025-08-09 09:15:57 - rag_system.services.model_manager - ERROR - model_manager.py:410 - _load_embedding_model - 加载embedding模型失败: default_embedding, 错误: 1 validation error for EmbeddingConfig
  Value error, 提供商 openai 需要API密钥 [type=value_error, input_value={'provider': 'openai', 'm...s': 8192, 'timeout': 30}, input_type=dict]
    For further information visit https://errors.pydantic.dev/2.11/v/value_error
2025-08-09 09:15:57 - rag_system.services.model_manager - ERROR - model_manager.py:375 - load_model - 模型加载失败: default_embedding
2025-08-09 09:15:57 - rag_system.services.reranking_service - ERROR - reranking_service.py:161 - _load_model - 模型加载失败: We couldn't connect to 'https://huggingface.co' to load this file, couldn't find it in the cached files and it looks like cross-encoder/ms-marco-MiniLM-L-6-v2 is not the path to a directory containing a file named config.json.
Checkout your internet connection or see how to run the library in offline mode at 'https://huggingface.co/docs/transformers/installation#offline-mode'.
2025-08-09 09:15:57 - rag_system.services.reranking_service - ERROR - reranking_service.py:125 - initialize - 重排序模型加载失败: We couldn't connect to 'https://huggingface.co' to load this file, couldn't find it in the cached files and it looks like cross-encoder/ms-marco-MiniLM-L-6-v2 is not the path to a directory containing a file named config.json.
Checkout your internet connection or see how to run the library in offline mode at 'https://huggingface.co/docs/transformers/installation#offline-mode'.
2025-08-09 09:15:59 - rag_system.services.model_manager - ERROR - model_manager.py:410 - _load_embedding_model - 加载embedding模型失败: default_embedding, 错误: 1 validation error for EmbeddingConfig
  Value error, 提供商 openai 需要API密钥 [type=value_error, input_value={'provider': 'openai', 'm...s': 8192, 'timeout': 30}, input_type=dict]
    For further information visit https://errors.pydantic.dev/2.11/v/value_error
2025-08-09 09:15:59 - rag_system.services.model_manager - ERROR - model_manager.py:375 - load_model - 模型加载失败: default_embedding
2025-08-09 09:16:00 - rag_system.services.reranking_service - ERROR - reranking_service.py:161 - _load_model - 模型加载失败: We couldn't connect to 'https://huggingface.co' to load this file, couldn't find it in the cached files and it looks like cross-encoder/ms-marco-MiniLM-L-6-v2 is not the path to a directory containing a file named config.json.
Checkout your internet connection or see how to run the library in offline mode at 'https://huggingface.co/docs/transformers/installation#offline-mode'.
2025-08-09 09:16:00 - rag_system.services.reranking_service - ERROR - reranking_service.py:125 - initialize - 重排序模型加载失败: We couldn't connect to 'https://huggingface.co' to load this file, couldn't find it in the cached files and it looks like cross-encoder/ms-marco-MiniLM-L-6-v2 is not the path to a directory containing a file named config.json.
Checkout your internet connection or see how to run the library in offline mode at 'https://huggingface.co/docs/transformers/installation#offline-mode'.
2025-08-09 09:16:02 - rag_system.services.model_manager - ERROR - model_manager.py:410 - _load_embedding_model - 加载embedding模型失败: default_embedding, 错误: 1 validation error for EmbeddingConfig
  Value error, 提供商 openai 需要API密钥 [type=value_error, input_value={'provider': 'openai', 'm...s': 8192, 'timeout': 30}, input_type=dict]
    For further information visit https://errors.pydantic.dev/2.11/v/value_error
2025-08-09 09:16:02 - rag_system.services.model_manager - ERROR - model_manager.py:375 - load_model - 模型加载失败: default_embedding
2025-08-09 09:16:02 - rag_system.services.reranking_service - ERROR - reranking_service.py:161 - _load_model - 模型加载失败: We couldn't connect to 'https://huggingface.co' to load this file, couldn't find it in the cached files and it looks like cross-encoder/ms-marco-MiniLM-L-6-v2 is not the path to a directory containing a file named config.json.
Checkout your internet connection or see how to run the library in offline mode at 'https://huggingface.co/docs/transformers/installation#offline-mode'.
2025-08-09 09:16:02 - rag_system.services.reranking_service - ERROR - reranking_service.py:125 - initialize - 重排序模型加载失败: We couldn't connect to 'https://huggingface.co' to load this file, couldn't find it in the cached files and it looks like cross-encoder/ms-marco-MiniLM-L-6-v2 is not the path to a directory containing a file named config.json.
Checkout your internet connection or see how to run the library in offline mode at 'https://huggingface.co/docs/transformers/installation#offline-mode'.
2025-08-09 09:16:04 - rag_system.services.model_manager - ERROR - model_manager.py:410 - _load_embedding_model - 加载embedding模型失败: default_embedding, 错误: 1 validation error for EmbeddingConfig
  Value error, 提供商 openai 需要API密钥 [type=value_error, input_value={'provider': 'openai', 'm...s': 8192, 'timeout': 30}, input_type=dict]
    For further information visit https://errors.pydantic.dev/2.11/v/value_error
2025-08-09 09:16:04 - rag_system.services.model_manager - ERROR - model_manager.py:375 - load_model - 模型加载失败: default_embedding
2025-08-09 09:16:05 - rag_system.services.reranking_service - ERROR - reranking_service.py:161 - _load_model - 模型加载失败: We couldn't connect to 'https://huggingface.co' to load this file, couldn't find it in the cached files and it looks like cross-encoder/ms-marco-MiniLM-L-6-v2 is not the path to a directory containing a file named config.json.
Checkout your internet connection or see how to run the library in offline mode at 'https://huggingface.co/docs/transformers/installation#offline-mode'.
2025-08-09 09:16:05 - rag_system.services.reranking_service - ERROR - reranking_service.py:125 - initialize - 重排序模型加载失败: We couldn't connect to 'https://huggingface.co' to load this file, couldn't find it in the cached files and it looks like cross-encoder/ms-marco-MiniLM-L-6-v2 is not the path to a directory containing a file named config.json.
Checkout your internet connection or see how to run the library in offline mode at 'https://huggingface.co/docs/transformers/installation#offline-mode'.
2025-08-09 09:16:05 - asyncio - ERROR - base_events.py:1833 - default_exception_handler - Unclosed client session
client_session: <aiohttp.client.ClientSession object at 0x000001E180AD2B40>
2025-08-09 09:16:08 - rag_system.services.model_manager - ERROR - model_manager.py:410 - _load_embedding_model - 加载embedding模型失败: default_embedding, 错误: 1 validation error for EmbeddingConfig
  Value error, 提供商 openai 需要API密钥 [type=value_error, input_value={'provider': 'openai', 'm...s': 8192, 'timeout': 30}, input_type=dict]
    For further information visit https://errors.pydantic.dev/2.11/v/value_error
2025-08-09 09:16:08 - rag_system.services.model_manager - ERROR - model_manager.py:375 - load_model - 模型加载失败: default_embedding
2025-08-09 09:16:12 - rag_system.services.reranking_service - ERROR - reranking_service.py:161 - _load_model - 模型加载失败: We couldn't connect to 'https://huggingface.co' to load this file, couldn't find it in the cached files and it looks like cross-encoder/ms-marco-MiniLM-L-6-v2 is not the path to a directory containing a file named config.json.
Checkout your internet connection or see how to run the library in offline mode at 'https://huggingface.co/docs/transformers/installation#offline-mode'.
2025-08-09 09:16:12 - rag_system.services.reranking_service - ERROR - reranking_service.py:125 - initialize - 重排序模型加载失败: We couldn't connect to 'https://huggingface.co' to load this file, couldn't find it in the cached files and it looks like cross-encoder/ms-marco-MiniLM-L-6-v2 is not the path to a directory containing a file named config.json.
Checkout your internet connection or see how to run the library in offline mode at 'https://huggingface.co/docs/transformers/installation#offline-mode'.
2025-08-09 09:18:25 - rag_system.services.model_manager - ERROR - model_manager.py:410 - _load_embedding_model - 加载embedding模型失败: default_embedding, 错误: 1 validation error for EmbeddingConfig
  Value error, 提供商 openai 需要API密钥 [type=value_error, input_value={'provider': 'openai', 'm...s': 8192, 'timeout': 30}, input_type=dict]
    For further information visit https://errors.pydantic.dev/2.11/v/value_error
2025-08-09 09:18:25 - rag_system.services.model_manager - ERROR - model_manager.py:375 - load_model - 模型加载失败: default_embedding
2025-08-09 09:18:25 - rag_system.services.reranking_service - ERROR - reranking_service.py:161 - _load_model - 模型加载失败: We couldn't connect to 'https://huggingface.co' to load this file, couldn't find it in the cached files and it looks like cross-encoder/ms-marco-MiniLM-L-6-v2 is not the path to a directory containing a file named config.json.
Checkout your internet connection or see how to run the library in offline mode at 'https://huggingface.co/docs/transformers/installation#offline-mode'.
2025-08-09 09:18:25 - rag_system.services.reranking_service - ERROR - reranking_service.py:125 - initialize - 重排序模型加载失败: We couldn't connect to 'https://huggingface.co' to load this file, couldn't find it in the cached files and it looks like cross-encoder/ms-marco-MiniLM-L-6-v2 is not the path to a directory containing a file named config.json.
Checkout your internet connection or see how to run the library in offline mode at 'https://huggingface.co/docs/transformers/installation#offline-mode'.
2025-08-09 09:18:25 - rag_system.services.model_manager - ERROR - model_manager.py:410 - _load_embedding_model - 加载embedding模型失败: my_custom_embedding, 错误: rag_system.embeddings.base.EmbeddingConfig() got multiple values for keyword argument 'provider'
2025-08-09 09:18:25 - rag_system.services.model_manager - ERROR - model_manager.py:375 - load_model - 模型加载失败: my_custom_embedding
2025-08-09 09:18:27 - rag_system.services.model_manager - ERROR - model_manager.py:410 - _load_embedding_model - 加载embedding模型失败: default_embedding, 错误: 1 validation error for EmbeddingConfig
  Value error, 提供商 openai 需要API密钥 [type=value_error, input_value={'provider': 'openai', 'm...s': 8192, 'timeout': 30}, input_type=dict]
    For further information visit https://errors.pydantic.dev/2.11/v/value_error
2025-08-09 09:18:27 - rag_system.services.model_manager - ERROR - model_manager.py:375 - load_model - 模型加载失败: default_embedding
2025-08-09 09:18:27 - rag_system.services.reranking_service - ERROR - reranking_service.py:161 - _load_model - 模型加载失败: We couldn't connect to 'https://huggingface.co' to load this file, couldn't find it in the cached files and it looks like cross-encoder/ms-marco-MiniLM-L-6-v2 is not the path to a directory containing a file named config.json.
Checkout your internet connection or see how to run the library in offline mode at 'https://huggingface.co/docs/transformers/installation#offline-mode'.
2025-08-09 09:18:27 - rag_system.services.reranking_service - ERROR - reranking_service.py:125 - initialize - 重排序模型加载失败: We couldn't connect to 'https://huggingface.co' to load this file, couldn't find it in the cached files and it looks like cross-encoder/ms-marco-MiniLM-L-6-v2 is not the path to a directory containing a file named config.json.
Checkout your internet connection or see how to run the library in offline mode at 'https://huggingface.co/docs/transformers/installation#offline-mode'.
2025-08-09 09:18:30 - rag_system.services.model_manager - ERROR - model_manager.py:410 - _load_embedding_model - 加载embedding模型失败: default_embedding, 错误: 1 validation error for EmbeddingConfig
  Value error, 提供商 openai 需要API密钥 [type=value_error, input_value={'provider': 'openai', 'm...s': 8192, 'timeout': 30}, input_type=dict]
    For further information visit https://errors.pydantic.dev/2.11/v/value_error
2025-08-09 09:18:30 - rag_system.services.model_manager - ERROR - model_manager.py:375 - load_model - 模型加载失败: default_embedding
2025-08-09 09:18:30 - rag_system.services.reranking_service - ERROR - reranking_service.py:161 - _load_model - 模型加载失败: We couldn't connect to 'https://huggingface.co' to load this file, couldn't find it in the cached files and it looks like cross-encoder/ms-marco-MiniLM-L-6-v2 is not the path to a directory containing a file named config.json.
Checkout your internet connection or see how to run the library in offline mode at 'https://huggingface.co/docs/transformers/installation#offline-mode'.
2025-08-09 09:18:30 - rag_system.services.reranking_service - ERROR - reranking_service.py:125 - initialize - 重排序模型加载失败: We couldn't connect to 'https://huggingface.co' to load this file, couldn't find it in the cached files and it looks like cross-encoder/ms-marco-MiniLM-L-6-v2 is not the path to a directory containing a file named config.json.
Checkout your internet connection or see how to run the library in offline mode at 'https://huggingface.co/docs/transformers/installation#offline-mode'.
2025-08-09 09:18:32 - rag_system.services.model_manager - ERROR - model_manager.py:410 - _load_embedding_model - 加载embedding模型失败: default_embedding, 错误: 1 validation error for EmbeddingConfig
  Value error, 提供商 openai 需要API密钥 [type=value_error, input_value={'provider': 'openai', 'm...s': 8192, 'timeout': 30}, input_type=dict]
    For further information visit https://errors.pydantic.dev/2.11/v/value_error
2025-08-09 09:18:32 - rag_system.services.model_manager - ERROR - model_manager.py:375 - load_model - 模型加载失败: default_embedding
2025-08-09 09:18:33 - rag_system.services.reranking_service - ERROR - reranking_service.py:161 - _load_model - 模型加载失败: We couldn't connect to 'https://huggingface.co' to load this file, couldn't find it in the cached files and it looks like cross-encoder/ms-marco-MiniLM-L-6-v2 is not the path to a directory containing a file named config.json.
Checkout your internet connection or see how to run the library in offline mode at 'https://huggingface.co/docs/transformers/installation#offline-mode'.
2025-08-09 09:18:33 - rag_system.services.reranking_service - ERROR - reranking_service.py:125 - initialize - 重排序模型加载失败: We couldn't connect to 'https://huggingface.co' to load this file, couldn't find it in the cached files and it looks like cross-encoder/ms-marco-MiniLM-L-6-v2 is not the path to a directory containing a file named config.json.
Checkout your internet connection or see how to run the library in offline mode at 'https://huggingface.co/docs/transformers/installation#offline-mode'.
2025-08-09 09:18:35 - rag_system.services.model_manager - ERROR - model_manager.py:410 - _load_embedding_model - 加载embedding模型失败: default_embedding, 错误: 1 validation error for EmbeddingConfig
  Value error, 提供商 openai 需要API密钥 [type=value_error, input_value={'provider': 'openai', 'm...s': 8192, 'timeout': 30}, input_type=dict]
    For further information visit https://errors.pydantic.dev/2.11/v/value_error
2025-08-09 09:18:35 - rag_system.services.model_manager - ERROR - model_manager.py:375 - load_model - 模型加载失败: default_embedding
2025-08-09 09:18:35 - rag_system.services.reranking_service - ERROR - reranking_service.py:161 - _load_model - 模型加载失败: We couldn't connect to 'https://huggingface.co' to load this file, couldn't find it in the cached files and it looks like cross-encoder/ms-marco-MiniLM-L-6-v2 is not the path to a directory containing a file named config.json.
Checkout your internet connection or see how to run the library in offline mode at 'https://huggingface.co/docs/transformers/installation#offline-mode'.
2025-08-09 09:18:35 - rag_system.services.reranking_service - ERROR - reranking_service.py:125 - initialize - 重排序模型加载失败: We couldn't connect to 'https://huggingface.co' to load this file, couldn't find it in the cached files and it looks like cross-encoder/ms-marco-MiniLM-L-6-v2 is not the path to a directory containing a file named config.json.
Checkout your internet connection or see how to run the library in offline mode at 'https://huggingface.co/docs/transformers/installation#offline-mode'.
2025-08-09 09:20:29 - asyncio - ERROR - base_events.py:1833 - default_exception_handler - Unclosed client session
client_session: <aiohttp.client.ClientSession object at 0x0000027D3560C650>
2025-08-09 09:21:19 - rag_system.services.model_manager - ERROR - model_manager.py:410 - _load_embedding_model - 加载embedding模型失败: default_embedding, 错误: 1 validation error for EmbeddingConfig
  Value error, 提供商 openai 需要API密钥 [type=value_error, input_value={'provider': 'openai', 'm...s': 8192, 'timeout': 30}, input_type=dict]
    For further information visit https://errors.pydantic.dev/2.11/v/value_error
2025-08-09 09:21:19 - rag_system.services.model_manager - ERROR - model_manager.py:375 - load_model - 模型加载失败: default_embedding
2025-08-09 09:21:22 - rag_system.services.reranking_service - ERROR - reranking_service.py:161 - _load_model - 模型加载失败: We couldn't connect to 'https://huggingface.co' to load this file, couldn't find it in the cached files and it looks like cross-encoder/ms-marco-MiniLM-L-6-v2 is not the path to a directory containing a file named config.json.
Checkout your internet connection or see how to run the library in offline mode at 'https://huggingface.co/docs/transformers/installation#offline-mode'.
2025-08-09 09:21:22 - rag_system.services.reranking_service - ERROR - reranking_service.py:125 - initialize - 重排序模型加载失败: We couldn't connect to 'https://huggingface.co' to load this file, couldn't find it in the cached files and it looks like cross-encoder/ms-marco-MiniLM-L-6-v2 is not the path to a directory containing a file named config.json.
Checkout your internet connection or see how to run the library in offline mode at 'https://huggingface.co/docs/transformers/installation#offline-mode'.
2025-08-09 09:21:22 - rag_system.services.model_manager - ERROR - model_manager.py:410 - _load_embedding_model - 加载embedding模型失败: debug_embedding, 错误: rag_system.embeddings.base.EmbeddingConfig() got multiple values for keyword argument 'provider'
2025-08-09 09:21:22 - rag_system.services.model_manager - ERROR - model_manager.py:375 - load_model - 模型加载失败: debug_embedding
2025-08-09 09:21:24 - rag_system.services.model_manager - ERROR - model_manager.py:410 - _load_embedding_model - 加载embedding模型失败: default_embedding, 错误: 1 validation error for EmbeddingConfig
  Value error, 提供商 openai 需要API密钥 [type=value_error, input_value={'provider': 'openai', 'm...s': 8192, 'timeout': 30}, input_type=dict]
    For further information visit https://errors.pydantic.dev/2.11/v/value_error
2025-08-09 09:21:24 - rag_system.services.model_manager - ERROR - model_manager.py:375 - load_model - 模型加载失败: default_embedding
2025-08-09 09:21:25 - rag_system.services.reranking_service - ERROR - reranking_service.py:161 - _load_model - 模型加载失败: We couldn't connect to 'https://huggingface.co' to load this file, couldn't find it in the cached files and it looks like cross-encoder/ms-marco-MiniLM-L-6-v2 is not the path to a directory containing a file named config.json.
Checkout your internet connection or see how to run the library in offline mode at 'https://huggingface.co/docs/transformers/installation#offline-mode'.
2025-08-09 09:21:25 - rag_system.services.reranking_service - ERROR - reranking_service.py:125 - initialize - 重排序模型加载失败: We couldn't connect to 'https://huggingface.co' to load this file, couldn't find it in the cached files and it looks like cross-encoder/ms-marco-MiniLM-L-6-v2 is not the path to a directory containing a file named config.json.
Checkout your internet connection or see how to run the library in offline mode at 'https://huggingface.co/docs/transformers/installation#offline-mode'.
2025-08-09 09:21:27 - rag_system.services.model_manager - ERROR - model_manager.py:410 - _load_embedding_model - 加载embedding模型失败: default_embedding, 错误: 1 validation error for EmbeddingConfig
  Value error, 提供商 openai 需要API密钥 [type=value_error, input_value={'provider': 'openai', 'm...s': 8192, 'timeout': 30}, input_type=dict]
    For further information visit https://errors.pydantic.dev/2.11/v/value_error
2025-08-09 09:21:27 - rag_system.services.model_manager - ERROR - model_manager.py:375 - load_model - 模型加载失败: default_embedding
2025-08-09 09:21:27 - rag_system.services.reranking_service - ERROR - reranking_service.py:161 - _load_model - 模型加载失败: We couldn't connect to 'https://huggingface.co' to load this file, couldn't find it in the cached files and it looks like cross-encoder/ms-marco-MiniLM-L-6-v2 is not the path to a directory containing a file named config.json.
Checkout your internet connection or see how to run the library in offline mode at 'https://huggingface.co/docs/transformers/installation#offline-mode'.
2025-08-09 09:21:27 - rag_system.services.reranking_service - ERROR - reranking_service.py:125 - initialize - 重排序模型加载失败: We couldn't connect to 'https://huggingface.co' to load this file, couldn't find it in the cached files and it looks like cross-encoder/ms-marco-MiniLM-L-6-v2 is not the path to a directory containing a file named config.json.
Checkout your internet connection or see how to run the library in offline mode at 'https://huggingface.co/docs/transformers/installation#offline-mode'.
2025-08-09 09:21:29 - rag_system.services.model_manager - ERROR - model_manager.py:410 - _load_embedding_model - 加载embedding模型失败: default_embedding, 错误: 1 validation error for EmbeddingConfig
  Value error, 提供商 openai 需要API密钥 [type=value_error, input_value={'provider': 'openai', 'm...s': 8192, 'timeout': 30}, input_type=dict]
    For further information visit https://errors.pydantic.dev/2.11/v/value_error
2025-08-09 09:21:29 - rag_system.services.model_manager - ERROR - model_manager.py:375 - load_model - 模型加载失败: default_embedding
2025-08-09 09:21:30 - rag_system.services.reranking_service - ERROR - reranking_service.py:161 - _load_model - 模型加载失败: We couldn't connect to 'https://huggingface.co' to load this file, couldn't find it in the cached files and it looks like cross-encoder/ms-marco-MiniLM-L-6-v2 is not the path to a directory containing a file named config.json.
Checkout your internet connection or see how to run the library in offline mode at 'https://huggingface.co/docs/transformers/installation#offline-mode'.
2025-08-09 09:21:30 - rag_system.services.reranking_service - ERROR - reranking_service.py:125 - initialize - 重排序模型加载失败: We couldn't connect to 'https://huggingface.co' to load this file, couldn't find it in the cached files and it looks like cross-encoder/ms-marco-MiniLM-L-6-v2 is not the path to a directory containing a file named config.json.
Checkout your internet connection or see how to run the library in offline mode at 'https://huggingface.co/docs/transformers/installation#offline-mode'.
2025-08-09 09:21:30 - rag_system.services.reranking_service - ERROR - reranking_service.py:161 - _load_model - 模型加载失败: We couldn't connect to 'https://huggingface.co' to load this file, couldn't find it in the cached files and it looks like mock-reranking-model is not the path to a directory containing a file named config.json.
Checkout your internet connection or see how to run the library in offline mode at 'https://huggingface.co/docs/transformers/installation#offline-mode'.
2025-08-09 09:21:30 - rag_system.services.reranking_service - ERROR - reranking_service.py:125 - initialize - 重排序模型加载失败: We couldn't connect to 'https://huggingface.co' to load this file, couldn't find it in the cached files and it looks like mock-reranking-model is not the path to a directory containing a file named config.json.
Checkout your internet connection or see how to run the library in offline mode at 'https://huggingface.co/docs/transformers/installation#offline-mode'.
2025-08-09 09:21:32 - rag_system.services.model_manager - ERROR - model_manager.py:410 - _load_embedding_model - 加载embedding模型失败: default_embedding, 错误: 1 validation error for EmbeddingConfig
  Value error, 提供商 openai 需要API密钥 [type=value_error, input_value={'provider': 'openai', 'm...s': 8192, 'timeout': 30}, input_type=dict]
    For further information visit https://errors.pydantic.dev/2.11/v/value_error
2025-08-09 09:21:32 - rag_system.services.model_manager - ERROR - model_manager.py:375 - load_model - 模型加载失败: default_embedding
2025-08-09 09:21:33 - rag_system.services.reranking_service - ERROR - reranking_service.py:161 - _load_model - 模型加载失败: We couldn't connect to 'https://huggingface.co' to load this file, couldn't find it in the cached files and it looks like cross-encoder/ms-marco-MiniLM-L-6-v2 is not the path to a directory containing a file named config.json.
Checkout your internet connection or see how to run the library in offline mode at 'https://huggingface.co/docs/transformers/installation#offline-mode'.
2025-08-09 09:21:33 - rag_system.services.reranking_service - ERROR - reranking_service.py:125 - initialize - 重排序模型加载失败: We couldn't connect to 'https://huggingface.co' to load this file, couldn't find it in the cached files and it looks like cross-encoder/ms-marco-MiniLM-L-6-v2 is not the path to a directory containing a file named config.json.
Checkout your internet connection or see how to run the library in offline mode at 'https://huggingface.co/docs/transformers/installation#offline-mode'.
2025-08-09 09:21:35 - rag_system.services.model_manager - ERROR - model_manager.py:410 - _load_embedding_model - 加载embedding模型失败: default_embedding, 错误: 1 validation error for EmbeddingConfig
  Value error, 提供商 openai 需要API密钥 [type=value_error, input_value={'provider': 'openai', 'm...s': 8192, 'timeout': 30}, input_type=dict]
    For further information visit https://errors.pydantic.dev/2.11/v/value_error
2025-08-09 09:21:35 - rag_system.services.model_manager - ERROR - model_manager.py:375 - load_model - 模型加载失败: default_embedding
2025-08-09 09:21:35 - rag_system.services.reranking_service - ERROR - reranking_service.py:161 - _load_model - 模型加载失败: We couldn't connect to 'https://huggingface.co' to load this file, couldn't find it in the cached files and it looks like cross-encoder/ms-marco-MiniLM-L-6-v2 is not the path to a directory containing a file named config.json.
Checkout your internet connection or see how to run the library in offline mode at 'https://huggingface.co/docs/transformers/installation#offline-mode'.
2025-08-09 09:21:35 - rag_system.services.reranking_service - ERROR - reranking_service.py:125 - initialize - 重排序模型加载失败: We couldn't connect to 'https://huggingface.co' to load this file, couldn't find it in the cached files and it looks like cross-encoder/ms-marco-MiniLM-L-6-v2 is not the path to a directory containing a file named config.json.
Checkout your internet connection or see how to run the library in offline mode at 'https://huggingface.co/docs/transformers/installation#offline-mode'.
2025-08-09 09:21:35 - rag_system.services.model_manager - ERROR - model_manager.py:410 - _load_embedding_model - 加载embedding模型失败: default_embedding, 错误: 1 validation error for EmbeddingConfig
  Value error, 提供商 openai 需要API密钥 [type=value_error, input_value={'provider': 'openai', 'm...s': 8192, 'timeout': 30}, input_type=dict]
    For further information visit https://errors.pydantic.dev/2.11/v/value_error
2025-08-09 09:21:35 - rag_system.services.model_manager - ERROR - model_manager.py:375 - load_model - 模型加载失败: default_embedding
2025-08-09 09:21:36 - rag_system.services.reranking_service - ERROR - reranking_service.py:161 - _load_model - 模型加载失败: We couldn't connect to 'https://huggingface.co' to load this file, couldn't find it in the cached files and it looks like cross-encoder/ms-marco-MiniLM-L-6-v2 is not the path to a directory containing a file named config.json.
Checkout your internet connection or see how to run the library in offline mode at 'https://huggingface.co/docs/transformers/installation#offline-mode'.
2025-08-09 09:21:36 - rag_system.services.reranking_service - ERROR - reranking_service.py:125 - initialize - 重排序模型加载失败: We couldn't connect to 'https://huggingface.co' to load this file, couldn't find it in the cached files and it looks like cross-encoder/ms-marco-MiniLM-L-6-v2 is not the path to a directory containing a file named config.json.
Checkout your internet connection or see how to run the library in offline mode at 'https://huggingface.co/docs/transformers/installation#offline-mode'.
2025-08-09 09:22:29 - rag_system.services.model_manager - ERROR - model_manager.py:410 - _load_embedding_model - 加载embedding模型失败: default_embedding, 错误: 1 validation error for EmbeddingConfig
  Value error, 提供商 openai 需要API密钥 [type=value_error, input_value={'provider': 'openai', 'm...s': 8192, 'timeout': 30}, input_type=dict]
    For further information visit https://errors.pydantic.dev/2.11/v/value_error
2025-08-09 09:22:29 - rag_system.services.model_manager - ERROR - model_manager.py:375 - load_model - 模型加载失败: default_embedding
2025-08-09 09:22:29 - rag_system.services.reranking_service - ERROR - reranking_service.py:161 - _load_model - 模型加载失败: We couldn't connect to 'https://huggingface.co' to load this file, couldn't find it in the cached files and it looks like cross-encoder/ms-marco-MiniLM-L-6-v2 is not the path to a directory containing a file named config.json.
Checkout your internet connection or see how to run the library in offline mode at 'https://huggingface.co/docs/transformers/installation#offline-mode'.
2025-08-09 09:22:29 - rag_system.services.reranking_service - ERROR - reranking_service.py:125 - initialize - 重排序模型加载失败: We couldn't connect to 'https://huggingface.co' to load this file, couldn't find it in the cached files and it looks like cross-encoder/ms-marco-MiniLM-L-6-v2 is not the path to a directory containing a file named config.json.
Checkout your internet connection or see how to run the library in offline mode at 'https://huggingface.co/docs/transformers/installation#offline-mode'.
2025-08-09 09:22:29 - rag_system.services.model_manager - ERROR - model_manager.py:410 - _load_embedding_model - 加载embedding模型失败: debug_embedding, 错误: rag_system.embeddings.base.EmbeddingConfig() got multiple values for keyword argument 'provider'
2025-08-09 09:22:29 - rag_system.services.model_manager - ERROR - model_manager.py:375 - load_model - 模型加载失败: debug_embedding
2025-08-09 09:22:31 - rag_system.services.model_manager - ERROR - model_manager.py:410 - _load_embedding_model - 加载embedding模型失败: default_embedding, 错误: 1 validation error for EmbeddingConfig
  Value error, 提供商 openai 需要API密钥 [type=value_error, input_value={'provider': 'openai', 'm...s': 8192, 'timeout': 30}, input_type=dict]
    For further information visit https://errors.pydantic.dev/2.11/v/value_error
2025-08-09 09:22:31 - rag_system.services.model_manager - ERROR - model_manager.py:375 - load_model - 模型加载失败: default_embedding
2025-08-09 09:22:36 - rag_system.services.reranking_service - ERROR - reranking_service.py:161 - _load_model - 模型加载失败: We couldn't connect to 'https://huggingface.co' to load this file, couldn't find it in the cached files and it looks like cross-encoder/ms-marco-MiniLM-L-6-v2 is not the path to a directory containing a file named config.json.
Checkout your internet connection or see how to run the library in offline mode at 'https://huggingface.co/docs/transformers/installation#offline-mode'.
2025-08-09 09:22:36 - rag_system.services.reranking_service - ERROR - reranking_service.py:125 - initialize - 重排序模型加载失败: We couldn't connect to 'https://huggingface.co' to load this file, couldn't find it in the cached files and it looks like cross-encoder/ms-marco-MiniLM-L-6-v2 is not the path to a directory containing a file named config.json.
Checkout your internet connection or see how to run the library in offline mode at 'https://huggingface.co/docs/transformers/installation#offline-mode'.
2025-08-09 09:22:41 - rag_system.services.reranking_service - ERROR - reranking_service.py:161 - _load_model - 模型加载失败: We couldn't connect to 'https://huggingface.co' to load this file, couldn't find it in the cached files and it looks like mock-reranking-model is not the path to a directory containing a file named config.json.
Checkout your internet connection or see how to run the library in offline mode at 'https://huggingface.co/docs/transformers/installation#offline-mode'.
2025-08-09 09:22:41 - rag_system.services.reranking_service - ERROR - reranking_service.py:125 - initialize - 重排序模型加载失败: We couldn't connect to 'https://huggingface.co' to load this file, couldn't find it in the cached files and it looks like mock-reranking-model is not the path to a directory containing a file named config.json.
Checkout your internet connection or see how to run the library in offline mode at 'https://huggingface.co/docs/transformers/installation#offline-mode'.
2025-08-09 09:25:01 - rag_system.services.model_manager - ERROR - model_manager.py:410 - _load_embedding_model - 加载embedding模型失败: debug_embedding, 错误: rag_system.embeddings.base.EmbeddingConfig() got multiple values for keyword argument 'provider'
2025-08-09 09:25:01 - rag_system.services.model_manager - ERROR - model_manager.py:375 - load_model - 模型加载失败: debug_embedding
2025-08-09 09:25:04 - rag_system.services.model_manager - ERROR - model_manager.py:410 - _load_embedding_model - 加载embedding模型失败: default_embedding, 错误: 1 validation error for EmbeddingConfig
  Value error, 提供商 openai 需要API密钥 [type=value_error, input_value={'provider': 'openai', 'm...s': 8192, 'timeout': 30}, input_type=dict]
    For further information visit https://errors.pydantic.dev/2.11/v/value_error
2025-08-09 09:25:04 - rag_system.services.model_manager - ERROR - model_manager.py:375 - load_model - 模型加载失败: default_embedding
2025-08-09 09:25:07 - rag_system.reranking.local_reranking - ERROR - local_reranking.py:77 - _load_model - 本地模型加载失败: We couldn't connect to 'https://huggingface.co' to load this file, couldn't find it in the cached files and it looks like cross-encoder/ms-marco-MiniLM-L-6-v2 is not the path to a directory containing a file named config.json.
Checkout your internet connection or see how to run the library in offline mode at 'https://huggingface.co/docs/transformers/installation#offline-mode'.
2025-08-09 09:25:07 - rag_system.reranking.local_reranking - ERROR - local_reranking.py:48 - initialize - 本地重排序模型加载失败: We couldn't connect to 'https://huggingface.co' to load this file, couldn't find it in the cached files and it looks like cross-encoder/ms-marco-MiniLM-L-6-v2 is not the path to a directory containing a file named config.json.
Checkout your internet connection or see how to run the library in offline mode at 'https://huggingface.co/docs/transformers/installation#offline-mode'.
2025-08-09 09:25:07 - rag_system.services.model_manager - ERROR - model_manager.py:477 - _load_reranking_model - 加载重排序模型失败: default_reranking, 错误: 本地重排序模型加载失败: We couldn't connect to 'https://huggingface.co' to load this file, couldn't find it in the cached files and it looks like cross-encoder/ms-marco-MiniLM-L-6-v2 is not the path to a directory containing a file named config.json.
Checkout your internet connection or see how to run the library in offline mode at 'https://huggingface.co/docs/transformers/installation#offline-mode'.
2025-08-09 09:25:07 - rag_system.services.model_manager - ERROR - model_manager.py:375 - load_model - 模型加载失败: default_reranking
2025-08-09 09:25:11 - rag_system.services.model_manager - ERROR - model_manager.py:477 - _load_reranking_model - 加载重排序模型失败: debug_reranking, 错误: rag_system.reranking.base.RerankingConfig() got multiple values for keyword argument 'provider'
2025-08-09 09:25:11 - rag_system.services.model_manager - ERROR - model_manager.py:375 - load_model - 模型加载失败: debug_reranking
2025-08-09 09:27:03 - rag_system.vector_store.chroma_store - ERROR - chroma_store.py:85 - initialize - Chroma向量数据库初始化失败: Could not connect to tenant default_tenant. Are you sure it exists?
2025-08-09 09:27:03 - rag_system.services.vector_service - ERROR - vector_service.py:42 - initialize - 向量存储服务初始化失败: [VECTOR_STORE_OPERATION_ERROR] Chroma初始化失败: Could not connect to tenant default_tenant. Are you sure it exists?
2025-08-09 09:27:03 - rag_system.services.document_service - ERROR - document_service.py:91 - initialize - 文档管理服务初始化失败: [VECTOR_STORE_OPERATION_ERROR] 向量存储服务初始化失败: [VECTOR_STORE_OPERATION_ERROR] Chroma初始化失败: Could not connect to tenant default_tenant. Are you sure it exists?
2025-08-09 09:28:57 - rag_system.services.model_manager - ERROR - model_manager.py:410 - _load_embedding_model - 加载embedding模型失败: siliconflow_BAAI_bge_large_zh_v1_5_, 错误: 2 validation errors for EmbeddingConfig
chunk_size
  Extra inputs are not permitted [type=extra_forbidden, input_value=1000, input_type=int]
    For further information visit https://errors.pydantic.dev/2.11/v/extra_forbidden
chunk_overlap
  Extra inputs are not permitted [type=extra_forbidden, input_value=100, input_type=int]
    For further information visit https://errors.pydantic.dev/2.11/v/extra_forbidden
2025-08-09 09:28:57 - rag_system.services.model_manager - ERROR - model_manager.py:375 - load_model - 模型加载失败: siliconflow_BAAI_bge_large_zh_v1_5_
2025-08-09 09:29:44 - rag_system.reranking.factory - ERROR - factory.py:58 - create_reranking - 创建重排序模型实例失败: siliconflow - SiliconFlow重排序需要API密钥
2025-08-09 09:29:44 - rag_system.services.model_manager - ERROR - model_manager.py:477 - _load_reranking_model - 加载重排序模型失败: siliconflow_BAAI_bge_reranker_v2_m3, 错误: [UNKNOWN_ERROR] 创建重排序模型实例失败: SiliconFlow重排序需要API密钥
2025-08-09 09:29:44 - rag_system.services.model_manager - ERROR - model_manager.py:375 - load_model - 模型加载失败: siliconflow_BAAI_bge_reranker_v2_m3
2025-08-09 09:30:00 - rag_system.reranking.factory - ERROR - factory.py:58 - create_reranking - 创建重排序模型实例失败: siliconflow - SiliconFlow重排序需要API密钥
2025-08-09 09:30:00 - rag_system.services.model_manager - ERROR - model_manager.py:477 - _load_reranking_model - 加载重排序模型失败: siliconflow_BAAI_bge_reranker_v2_m3, 错误: [UNKNOWN_ERROR] 创建重排序模型实例失败: SiliconFlow重排序需要API密钥
2025-08-09 09:30:00 - rag_system.services.model_manager - ERROR - model_manager.py:375 - load_model - 模型加载失败: siliconflow_BAAI_bge_reranker_v2_m3
2025-08-09 09:33:13 - rag_system.embeddings.siliconflow_embedding - ERROR - siliconflow_embedding.py:72 - initialize - SiliconFlow嵌入模型初始化失败: [siliconflow:BAAI/bge-large-zh-v1.5'] SiliconFlow嵌入API连接测试失败: [siliconflow:BAAI/bge-large-zh-v1.5'] API请求失败: 400 - {"code":20012,"message":"Model does not exist. Please check it carefully.","data":null} (错误码: 6000) (错误码: 3000)
2025-08-09 09:33:13 - rag_system.services.embedding_service - ERROR - embedding_service.py:72 - _create_embedding_instance - 嵌入模型实例创建失败: siliconflow - [UNKNOWN_ERROR] SiliconFlow嵌入模型初始化失败: [siliconflow:BAAI/bge-large-zh-v1.5'] SiliconFlow嵌入API连接测试失败: [siliconflow:BAAI/bge-large-zh-v1.5'] API请求失败: 400 - {"code":20012,"message":"Model does not exist. Please check it carefully.","data":null} (错误码: 6000) (错误码: 3000)
2025-08-09 09:33:13 - rag_system.services.embedding_service - ERROR - embedding_service.py:242 - initialize - 嵌入服务初始化失败: [CONFIG_VALIDATION_ERROR] 无法创建主要嵌入模型实例: siliconflow
2025-08-09 09:33:13 - rag_system.services.document_service - ERROR - document_service.py:91 - initialize - 文档管理服务初始化失败: [CONFIG_VALIDATION_ERROR] 嵌入服务初始化失败: [CONFIG_VALIDATION_ERROR] 无法创建主要嵌入模型实例: siliconflow
2025-08-09 09:33:13 - rag_system.embeddings.siliconflow_embedding - ERROR - siliconflow_embedding.py:72 - initialize - SiliconFlow嵌入模型初始化失败: [siliconflow:BAAI/bge-large-zh-v1.5'] SiliconFlow嵌入API连接测试失败: [siliconflow:BAAI/bge-large-zh-v1.5'] API请求失败: 400 - {"code":20012,"message":"Model does not exist. Please check it carefully.","data":null} (错误码: 6000) (错误码: 3000)
2025-08-09 09:33:13 - rag_system.services.embedding_service - ERROR - embedding_service.py:72 - _create_embedding_instance - 嵌入模型实例创建失败: siliconflow - [UNKNOWN_ERROR] SiliconFlow嵌入模型初始化失败: [siliconflow:BAAI/bge-large-zh-v1.5'] SiliconFlow嵌入API连接测试失败: [siliconflow:BAAI/bge-large-zh-v1.5'] API请求失败: 400 - {"code":20012,"message":"Model does not exist. Please check it carefully.","data":null} (错误码: 6000) (错误码: 3000)
2025-08-09 09:33:13 - rag_system.services.embedding_service - ERROR - embedding_service.py:242 - initialize - 嵌入服务初始化失败: [CONFIG_VALIDATION_ERROR] 无法创建主要嵌入模型实例: siliconflow
2025-08-09 09:33:13 - rag_system.services.document_service - ERROR - document_service.py:91 - initialize - 文档管理服务初始化失败: [CONFIG_VALIDATION_ERROR] 嵌入服务初始化失败: [CONFIG_VALIDATION_ERROR] 无法创建主要嵌入模型实例: siliconflow
2025-08-09 09:33:18 - rag_system.embeddings.siliconflow_embedding - ERROR - siliconflow_embedding.py:72 - initialize - SiliconFlow嵌入模型初始化失败: [siliconflow:BAAI/bge-large-zh-v1.5'] SiliconFlow嵌入API连接测试失败: [siliconflow:BAAI/bge-large-zh-v1.5'] API请求失败: 400 - {"code":20012,"message":"Model does not exist. Please check it carefully.","data":null} (错误码: 6000) (错误码: 3000)
2025-08-09 09:33:18 - rag_system.services.embedding_service - ERROR - embedding_service.py:72 - _create_embedding_instance - 嵌入模型实例创建失败: siliconflow - [UNKNOWN_ERROR] SiliconFlow嵌入模型初始化失败: [siliconflow:BAAI/bge-large-zh-v1.5'] SiliconFlow嵌入API连接测试失败: [siliconflow:BAAI/bge-large-zh-v1.5'] API请求失败: 400 - {"code":20012,"message":"Model does not exist. Please check it carefully.","data":null} (错误码: 6000) (错误码: 3000)
2025-08-09 09:33:18 - rag_system.services.embedding_service - ERROR - embedding_service.py:242 - initialize - 嵌入服务初始化失败: [CONFIG_VALIDATION_ERROR] 无法创建主要嵌入模型实例: siliconflow
2025-08-09 09:33:18 - rag_system.services.document_service - ERROR - document_service.py:91 - initialize - 文档管理服务初始化失败: [CONFIG_VALIDATION_ERROR] 嵌入服务初始化失败: [CONFIG_VALIDATION_ERROR] 无法创建主要嵌入模型实例: siliconflow
2025-08-09 09:33:18 - rag_system.embeddings.siliconflow_embedding - ERROR - siliconflow_embedding.py:72 - initialize - SiliconFlow嵌入模型初始化失败: [siliconflow:BAAI/bge-large-zh-v1.5'] SiliconFlow嵌入API连接测试失败: [siliconflow:BAAI/bge-large-zh-v1.5'] API请求失败: 400 - {"code":20012,"message":"Model does not exist. Please check it carefully.","data":null} (错误码: 6000) (错误码: 3000)
2025-08-09 09:33:18 - rag_system.services.embedding_service - ERROR - embedding_service.py:72 - _create_embedding_instance - 嵌入模型实例创建失败: siliconflow - [UNKNOWN_ERROR] SiliconFlow嵌入模型初始化失败: [siliconflow:BAAI/bge-large-zh-v1.5'] SiliconFlow嵌入API连接测试失败: [siliconflow:BAAI/bge-large-zh-v1.5'] API请求失败: 400 - {"code":20012,"message":"Model does not exist. Please check it carefully.","data":null} (错误码: 6000) (错误码: 3000)
2025-08-09 09:33:18 - rag_system.services.embedding_service - ERROR - embedding_service.py:242 - initialize - 嵌入服务初始化失败: [CONFIG_VALIDATION_ERROR] 无法创建主要嵌入模型实例: siliconflow
2025-08-09 09:33:18 - rag_system.services.document_service - ERROR - document_service.py:91 - initialize - 文档管理服务初始化失败: [CONFIG_VALIDATION_ERROR] 嵌入服务初始化失败: [CONFIG_VALIDATION_ERROR] 无法创建主要嵌入模型实例: siliconflow
2025-08-09 09:33:22 - rag_system.embeddings.siliconflow_embedding - ERROR - siliconflow_embedding.py:72 - initialize - SiliconFlow嵌入模型初始化失败: [siliconflow:BAAI/bge-large-zh-v1.5'] SiliconFlow嵌入API连接测试失败: [siliconflow:BAAI/bge-large-zh-v1.5'] API请求失败: 400 - {"code":20012,"message":"Model does not exist. Please check it carefully.","data":null} (错误码: 6000) (错误码: 3000)
2025-08-09 09:33:22 - rag_system.services.embedding_service - ERROR - embedding_service.py:72 - _create_embedding_instance - 嵌入模型实例创建失败: siliconflow - [UNKNOWN_ERROR] SiliconFlow嵌入模型初始化失败: [siliconflow:BAAI/bge-large-zh-v1.5'] SiliconFlow嵌入API连接测试失败: [siliconflow:BAAI/bge-large-zh-v1.5'] API请求失败: 400 - {"code":20012,"message":"Model does not exist. Please check it carefully.","data":null} (错误码: 6000) (错误码: 3000)
2025-08-09 09:33:22 - rag_system.services.embedding_service - ERROR - embedding_service.py:242 - initialize - 嵌入服务初始化失败: [CONFIG_VALIDATION_ERROR] 无法创建主要嵌入模型实例: siliconflow
2025-08-09 09:33:22 - rag_system.services.document_service - ERROR - document_service.py:91 - initialize - 文档管理服务初始化失败: [CONFIG_VALIDATION_ERROR] 嵌入服务初始化失败: [CONFIG_VALIDATION_ERROR] 无法创建主要嵌入模型实例: siliconflow
2025-08-09 09:33:22 - rag_system.embeddings.siliconflow_embedding - ERROR - siliconflow_embedding.py:72 - initialize - SiliconFlow嵌入模型初始化失败: [siliconflow:BAAI/bge-large-zh-v1.5'] SiliconFlow嵌入API连接测试失败: [siliconflow:BAAI/bge-large-zh-v1.5'] API请求失败: 400 - {"code":20012,"message":"Model does not exist. Please check it carefully.","data":null} (错误码: 6000) (错误码: 3000)
2025-08-09 09:33:22 - rag_system.services.embedding_service - ERROR - embedding_service.py:72 - _create_embedding_instance - 嵌入模型实例创建失败: siliconflow - [UNKNOWN_ERROR] SiliconFlow嵌入模型初始化失败: [siliconflow:BAAI/bge-large-zh-v1.5'] SiliconFlow嵌入API连接测试失败: [siliconflow:BAAI/bge-large-zh-v1.5'] API请求失败: 400 - {"code":20012,"message":"Model does not exist. Please check it carefully.","data":null} (错误码: 6000) (错误码: 3000)
2025-08-09 09:33:22 - rag_system.services.embedding_service - ERROR - embedding_service.py:242 - initialize - 嵌入服务初始化失败: [CONFIG_VALIDATION_ERROR] 无法创建主要嵌入模型实例: siliconflow
2025-08-09 09:33:22 - rag_system.services.document_service - ERROR - document_service.py:91 - initialize - 文档管理服务初始化失败: [CONFIG_VALIDATION_ERROR] 嵌入服务初始化失败: [CONFIG_VALIDATION_ERROR] 无法创建主要嵌入模型实例: siliconflow
2025-08-09 09:33:49 - rag_system.embeddings.siliconflow_embedding - ERROR - siliconflow_embedding.py:72 - initialize - SiliconFlow嵌入模型初始化失败: [siliconflow:BAAI/bge-large-zh-v1.5'] SiliconFlow嵌入API连接测试失败: [siliconflow:BAAI/bge-large-zh-v1.5'] API请求失败: 400 - {"code":20012,"message":"Model does not exist. Please check it carefully.","data":null} (错误码: 6000) (错误码: 3000)
2025-08-09 09:33:49 - rag_system.services.embedding_service - ERROR - embedding_service.py:72 - _create_embedding_instance - 嵌入模型实例创建失败: siliconflow - [UNKNOWN_ERROR] SiliconFlow嵌入模型初始化失败: [siliconflow:BAAI/bge-large-zh-v1.5'] SiliconFlow嵌入API连接测试失败: [siliconflow:BAAI/bge-large-zh-v1.5'] API请求失败: 400 - {"code":20012,"message":"Model does not exist. Please check it carefully.","data":null} (错误码: 6000) (错误码: 3000)
2025-08-09 09:33:49 - rag_system.services.embedding_service - ERROR - embedding_service.py:242 - initialize - 嵌入服务初始化失败: [CONFIG_VALIDATION_ERROR] 无法创建主要嵌入模型实例: siliconflow
2025-08-09 09:33:49 - rag_system.services.document_service - ERROR - document_service.py:91 - initialize - 文档管理服务初始化失败: [CONFIG_VALIDATION_ERROR] 嵌入服务初始化失败: [CONFIG_VALIDATION_ERROR] 无法创建主要嵌入模型实例: siliconflow
2025-08-09 09:33:53 - rag_system.embeddings.siliconflow_embedding - ERROR - siliconflow_embedding.py:72 - initialize - SiliconFlow嵌入模型初始化失败: [siliconflow:BAAI/bge-large-zh-v1.5'] SiliconFlow嵌入API连接测试失败: [siliconflow:BAAI/bge-large-zh-v1.5'] API请求失败: 400 - {"code":20012,"message":"Model does not exist. Please check it carefully.","data":null} (错误码: 6000) (错误码: 3000)
2025-08-09 09:33:53 - rag_system.services.embedding_service - ERROR - embedding_service.py:72 - _create_embedding_instance - 嵌入模型实例创建失败: siliconflow - [UNKNOWN_ERROR] SiliconFlow嵌入模型初始化失败: [siliconflow:BAAI/bge-large-zh-v1.5'] SiliconFlow嵌入API连接测试失败: [siliconflow:BAAI/bge-large-zh-v1.5'] API请求失败: 400 - {"code":20012,"message":"Model does not exist. Please check it carefully.","data":null} (错误码: 6000) (错误码: 3000)
2025-08-09 09:33:53 - rag_system.services.embedding_service - ERROR - embedding_service.py:242 - initialize - 嵌入服务初始化失败: [CONFIG_VALIDATION_ERROR] 无法创建主要嵌入模型实例: siliconflow
2025-08-09 09:33:53 - rag_system.services.document_service - ERROR - document_service.py:91 - initialize - 文档管理服务初始化失败: [CONFIG_VALIDATION_ERROR] 嵌入服务初始化失败: [CONFIG_VALIDATION_ERROR] 无法创建主要嵌入模型实例: siliconflow
2025-08-09 09:33:53 - rag_system.embeddings.siliconflow_embedding - ERROR - siliconflow_embedding.py:72 - initialize - SiliconFlow嵌入模型初始化失败: [siliconflow:BAAI/bge-large-zh-v1.5'] SiliconFlow嵌入API连接测试失败: [siliconflow:BAAI/bge-large-zh-v1.5'] API请求失败: 400 - {"code":20012,"message":"Model does not exist. Please check it carefully.","data":null} (错误码: 6000) (错误码: 3000)
2025-08-09 09:33:53 - rag_system.services.embedding_service - ERROR - embedding_service.py:72 - _create_embedding_instance - 嵌入模型实例创建失败: siliconflow - [UNKNOWN_ERROR] SiliconFlow嵌入模型初始化失败: [siliconflow:BAAI/bge-large-zh-v1.5'] SiliconFlow嵌入API连接测试失败: [siliconflow:BAAI/bge-large-zh-v1.5'] API请求失败: 400 - {"code":20012,"message":"Model does not exist. Please check it carefully.","data":null} (错误码: 6000) (错误码: 3000)
2025-08-09 09:33:53 - rag_system.services.embedding_service - ERROR - embedding_service.py:242 - initialize - 嵌入服务初始化失败: [CONFIG_VALIDATION_ERROR] 无法创建主要嵌入模型实例: siliconflow
2025-08-09 09:33:53 - rag_system.services.document_service - ERROR - document_service.py:91 - initialize - 文档管理服务初始化失败: [CONFIG_VALIDATION_ERROR] 嵌入服务初始化失败: [CONFIG_VALIDATION_ERROR] 无法创建主要嵌入模型实例: siliconflow
2025-08-09 09:39:48 - rag_system.vector_store.chroma_store - ERROR - chroma_store.py:85 - initialize - Chroma向量数据库初始化失败: Could not connect to tenant default_tenant. Are you sure it exists?
2025-08-09 09:39:48 - rag_system.services.vector_service - ERROR - vector_service.py:42 - initialize - 向量存储服务初始化失败: [VECTOR_STORE_OPERATION_ERROR] Chroma初始化失败: Could not connect to tenant default_tenant. Are you sure it exists?
2025-08-09 09:39:48 - rag_system.services.document_service - ERROR - document_service.py:91 - initialize - 文档管理服务初始化失败: [VECTOR_STORE_OPERATION_ERROR] 向量存储服务初始化失败: [VECTOR_STORE_OPERATION_ERROR] Chroma初始化失败: Could not connect to tenant default_tenant. Are you sure it exists?
2025-08-09 09:41:40 - rag_system.services.reranking_service - ERROR - reranking_service.py:161 - _load_model - 模型加载失败: We couldn't connect to 'https://huggingface.co' to load this file, couldn't find it in the cached files and it looks like cross-encoder/ms-marco-MiniLM-L-6-v2 is not the path to a directory containing a file named config.json.
Checkout your internet connection or see how to run the library in offline mode at 'https://huggingface.co/docs/transformers/installation#offline-mode'.
2025-08-09 09:41:40 - rag_system.services.reranking_service - ERROR - reranking_service.py:125 - initialize - 重排序模型加载失败: We couldn't connect to 'https://huggingface.co' to load this file, couldn't find it in the cached files and it looks like cross-encoder/ms-marco-MiniLM-L-6-v2 is not the path to a directory containing a file named config.json.
Checkout your internet connection or see how to run the library in offline mode at 'https://huggingface.co/docs/transformers/installation#offline-mode'.
2025-08-09 09:43:39 - rag_system.services.reranking_service - ERROR - reranking_service.py:161 - _load_model - 模型加载失败: We couldn't connect to 'https://huggingface.co' to load this file, couldn't find it in the cached files and it looks like cross-encoder/ms-marco-MiniLM-L-6-v2 is not the path to a directory containing a file named config.json.
Checkout your internet connection or see how to run the library in offline mode at 'https://huggingface.co/docs/transformers/installation#offline-mode'.
2025-08-09 09:43:39 - rag_system.services.reranking_service - ERROR - reranking_service.py:125 - initialize - 重排序模型加载失败: We couldn't connect to 'https://huggingface.co' to load this file, couldn't find it in the cached files and it looks like cross-encoder/ms-marco-MiniLM-L-6-v2 is not the path to a directory containing a file named config.json.
Checkout your internet connection or see how to run the library in offline mode at 'https://huggingface.co/docs/transformers/installation#offline-mode'.
2025-08-10 18:00:10 - rag_system.vector_store.chroma_store - ERROR - chroma_store.py:85 - initialize - Chroma向量数据库初始化失败: Could not connect to tenant default_tenant. Are you sure it exists?
2025-08-10 18:00:10 - rag_system.services.vector_service - ERROR - vector_service.py:42 - initialize - 向量存储服务初始化失败: [VECTOR_STORE_OPERATION_ERROR] Chroma初始化失败: Could not connect to tenant default_tenant. Are you sure it exists?
2025-08-10 18:00:10 - rag_system.services.document_service - ERROR - document_service.py:91 - initialize - 文档管理服务初始化失败: [VECTOR_STORE_OPERATION_ERROR] 向量存储服务初始化失败: [VECTOR_STORE_OPERATION_ERROR] Chroma初始化失败: Could not connect to tenant default_tenant. Are you sure it exists?
2025-08-10 18:00:57 - rag_system.services.reranking_service - ERROR - reranking_service.py:161 - _load_model - 模型加载失败: We couldn't connect to 'https://huggingface.co' to load this file, couldn't find it in the cached files and it looks like cross-encoder/ms-marco-MiniLM-L-6-v2 is not the path to a directory containing a file named config.json.
Checkout your internet connection or see how to run the library in offline mode at 'https://huggingface.co/docs/transformers/installation#offline-mode'.
2025-08-10 18:00:57 - rag_system.services.reranking_service - ERROR - reranking_service.py:125 - initialize - 重排序模型加载失败: We couldn't connect to 'https://huggingface.co' to load this file, couldn't find it in the cached files and it looks like cross-encoder/ms-marco-MiniLM-L-6-v2 is not the path to a directory containing a file named config.json.
Checkout your internet connection or see how to run the library in offline mode at 'https://huggingface.co/docs/transformers/installation#offline-mode'.
